[32m2025-08-03 12:03:03.590[0m | [32m[1mSUCCESS [0m | [36mutils.agent_observability[0m:[36m_initialize_integrations[0m:[36m109[0m - [32m[1mâœ… W&B initialized for agent analytics.[0m
[32m2025-08-03 12:03:10.259[0m | [32m[1mSUCCESS [0m | [36mutils.sentry_integration[0m:[36m_initialize_sentry[0m:[36m78[0m - [32m[1mSentry integration initialized successfully[0m
[32m2025-08-03 12:03:10.277[0m | [1mINFO    [0m | [36msrc.core.cognitive_forge_engine[0m:[36m__init__[0m:[36m111[0m - [1mGoogle Generative AI initialized with model: gemini-1.5-pro[0m
[32m2025-08-03 12:03:10.282[0m | [1mINFO    [0m | [36mutils.crewai_bypass[0m:[36m__init__[0m:[36m21[0m - [1mCreating DirectAIAgent with role: Learning Analysis Specialist, LLM type: <class 'utils.google_ai_wrapper.GoogleGenerativeAIWrapper'>[0m
[32m2025-08-03 12:03:10.284[0m | [1mINFO    [0m | [36mutils.crewai_bypass[0m:[36m__init__[0m:[36m21[0m - [1mCreating DirectAIAgent with role: Improvement Generation Specialist, LLM type: <class 'utils.google_ai_wrapper.GoogleGenerativeAIWrapper'>[0m
[32m2025-08-03 12:03:10.286[0m | [1mINFO    [0m | [36mutils.self_learning_module[0m:[36m__init__[0m:[36m26[0m - [1mSelf-Learning Module initialized - Continuous improvement active[0m
[32m2025-08-03 12:03:10.341[0m | [1mINFO    [0m | [36msrc.models.advanced_database[0m:[36m__init__[0m:[36m179[0m - [1mâœ… ChromaDB memory system initialized successfully[0m
[32m2025-08-03 12:03:10.345[0m | [1mINFO    [0m | [36msrc.models.advanced_database[0m:[36m__init__[0m:[36m184[0m - [1mâœ… Database system initialized successfully[0m
[32mINFO[0m:     Started server process [[36m18208[0m]
[32mINFO[0m:     Waiting for application startup.
[32mINFO[0m:     Application startup complete.
[31mERROR[0m:    Traceback (most recent call last):
  File "C:\Users\AMD\AppData\Local\Programs\Python\Python311\Lib\asyncio\runners.py", line 190, in run
    return runner.run(main)
           ^^^^^^^^^^^^^^^^
  File "C:\Users\AMD\AppData\Local\Programs\Python\Python311\Lib\asyncio\runners.py", line 118, in run
    return self._loop.run_until_complete(task)
           ^^^^^^^^^^^^^^^^^^^^^^^^^^^^^^^^^^^
  File "C:\Users\AMD\AppData\Local\Programs\Python\Python311\Lib\asyncio\base_events.py", line 641, in run_until_complete
    self.run_forever()
  File "C:\Users\AMD\AppData\Local\Programs\Python\Python311\Lib\asyncio\base_events.py", line 608, in run_forever
    self._run_once()
  File "C:\Users\AMD\AppData\Local\Programs\Python\Python311\Lib\asyncio\base_events.py", line 1936, in _run_once
    handle._run()
  File "C:\Users\AMD\AppData\Local\Programs\Python\Python311\Lib\asyncio\events.py", line 84, in _run
    self._context.run(self._callback, *self._args)
  File "C:\Users\AMD\AppData\Local\Programs\Python\Python311\Lib\site-packages\uvicorn\server.py", line 70, in serve
    with self.capture_signals():
  File "C:\Users\AMD\AppData\Local\Programs\Python\Python311\Lib\contextlib.py", line 144, in __exit__
    next(self.gen)
  File "C:\Users\AMD\AppData\Local\Programs\Python\Python311\Lib\site-packages\uvicorn\server.py", line 331, in capture_signals
    signal.raise_signal(captured_signal)
  File "C:\Users\AMD\AppData\Local\Programs\Python\Python311\Lib\asyncio\runners.py", line 157, in _on_sigint
    raise KeyboardInterrupt()
KeyboardInterrupt

During handling of the above exception, another exception occurred:

Traceback (most recent call last):
  File "C:\Users\AMD\AppData\Local\Programs\Python\Python311\Lib\site-packages\starlette\routing.py", line 686, in lifespan
    await receive()
  File "C:\Users\AMD\AppData\Local\Programs\Python\Python311\Lib\site-packages\sentry_sdk\integrations\starlette.py", line 179, in _sentry_receive
    return await receive(*args, **kwargs)
           ^^^^^^^^^^^^^^^^^^^^^^^^^^^^^^
  File "C:\Users\AMD\AppData\Local\Programs\Python\Python311\Lib\site-packages\uvicorn\lifespan\on.py", line 137, in receive
    return await self.receive_queue.get()
           ^^^^^^^^^^^^^^^^^^^^^^^^^^^^^^
  File "C:\Users\AMD\AppData\Local\Programs\Python\Python311\Lib\asyncio\queues.py", line 158, in get
    await getter
asyncio.exceptions.CancelledError

Sentry is attempting to send 3 pending events
Waiting up to 2 seconds
Press Ctrl-Break to quit
