2025-07-30 04:17:09 | ERROR | __main__:run_test:180 | Test Database Connection failed: Database test failed: The onnxruntime python package is not installed. Please install it with `pip install onnxruntime`
Traceback (most recent call last):
  File "C:\Users\AMD\AppData\Local\Programs\Python\Python311\Lib\site-packages\chromadb\utils\embedding_functions.py", line 395, in __init__
    self.ort = importlib.import_module("onnxruntime")
               ^^^^^^^^^^^^^^^^^^^^^^^^^^^^^^^^^^^^^^
  File "C:\Users\AMD\AppData\Local\Programs\Python\Python311\Lib\importlib\__init__.py", line 126, in import_module
    return _bootstrap._gcd_import(name[level:], package, level)
           ^^^^^^^^^^^^^^^^^^^^^^^^^^^^^^^^^^^^^^^^^^^^^^^^^^^^
  File "<frozen importlib._bootstrap>", line 1204, in _gcd_import
  File "<frozen importlib._bootstrap>", line 1176, in _find_and_load
  File "<frozen importlib._bootstrap>", line 1147, in _find_and_load_unlocked
  File "<frozen importlib._bootstrap>", line 690, in _load_unlocked
  File "<frozen importlib._bootstrap_external>", line 940, in exec_module
  File "<frozen importlib._bootstrap>", line 241, in _call_with_frames_removed
  File "C:\Users\AMD\AppData\Local\Programs\Python\Python311\Lib\site-packages\onnxruntime\__init__.py", line 61, in <module>
    raise import_capi_exception
  File "C:\Users\AMD\AppData\Local\Programs\Python\Python311\Lib\site-packages\onnxruntime\__init__.py", line 24, in <module>
    from onnxruntime.capi._pybind_state import (
  File "C:\Users\AMD\AppData\Local\Programs\Python\Python311\Lib\site-packages\onnxruntime\capi\_pybind_state.py", line 32, in <module>
    from .onnxruntime_pybind11_state import *  # noqa
    ^^^^^^^^^^^^^^^^^^^^^^^^^^^^^^^^^^^^^^^^^
ImportError: DLL load failed while importing onnxruntime_pybind11_state: A dynamic link library (DLL) initialization routine failed.

During handling of the above exception, another exception occurred:

Traceback (most recent call last):
  File "C:\Users\AMD\sentinel\desktop-app\comprehensive_test_suite.py", line 243, in test_database_connection
    from src.models.advanced_database import db_manager
  File "C:\Users\AMD\sentinel\desktop-app\src\models\advanced_database.py", line 16, in <module>
    import chromadb
  File "C:\Users\AMD\AppData\Local\Programs\Python\Python311\Lib\site-packages\chromadb\__init__.py", line 3, in <module>
    from chromadb.api.client import Client as ClientCreator
  File "C:\Users\AMD\AppData\Local\Programs\Python\Python311\Lib\site-packages\chromadb\api\__init__.py", line 7, in <module>
    from chromadb.api.models.Collection import Collection
  File "C:\Users\AMD\AppData\Local\Programs\Python\Python311\Lib\site-packages\chromadb\api\models\Collection.py", line 57, in <module>
    class Collection(BaseModel):
  File "C:\Users\AMD\AppData\Local\Programs\Python\Python311\Lib\site-packages\chromadb\api\models\Collection.py", line 74, in Collection
    ] = ef.DefaultEmbeddingFunction(),  # type: ignore
        ^^^^^^^^^^^^^^^^^^^^^^^^^^^^^
  File "C:\Users\AMD\AppData\Local\Programs\Python\Python311\Lib\site-packages\chromadb\utils\embedding_functions.py", line 566, in DefaultEmbeddingFunction
    return ONNXMiniLM_L6_V2()
           ^^^^^^^^^^^^^^^^^^
  File "C:\Users\AMD\AppData\Local\Programs\Python\Python311\Lib\site-packages\chromadb\utils\embedding_functions.py", line 397, in __init__
    raise ValueError(
ValueError: The onnxruntime python package is not installed. Please install it with `pip install onnxruntime`

During handling of the above exception, another exception occurred:

Traceback (most recent call last):
  File "C:\Users\AMD\sentinel\desktop-app\comprehensive_test_suite.py", line 141, in run_test
    result = test_func()
             ^^^^^^^^^^^
  File "C:\Users\AMD\sentinel\desktop-app\comprehensive_test_suite.py", line 268, in test_database_connection
    raise Exception(f"Database test failed: {e}")
Exception: Database test failed: The onnxruntime python package is not installed. Please install it with `pip install onnxruntime`

2025-07-30 04:17:09 | ERROR | __main__:log_test_result:126 | Error in Database Connection: Database test failed: The onnxruntime python package is not installed. Please install it with `pip install onnxruntime`
Traceback (most recent call last):
  File "C:\Users\AMD\AppData\Local\Programs\Python\Python311\Lib\site-packages\chromadb\utils\embedding_functions.py", line 395, in __init__
    self.ort = importlib.import_module("onnxruntime")
               ^^^^^^^^^^^^^^^^^^^^^^^^^^^^^^^^^^^^^^
  File "C:\Users\AMD\AppData\Local\Programs\Python\Python311\Lib\importlib\__init__.py", line 126, in import_module
    return _bootstrap._gcd_import(name[level:], package, level)
           ^^^^^^^^^^^^^^^^^^^^^^^^^^^^^^^^^^^^^^^^^^^^^^^^^^^^
  File "<frozen importlib._bootstrap>", line 1204, in _gcd_import
  File "<frozen importlib._bootstrap>", line 1176, in _find_and_load
  File "<frozen importlib._bootstrap>", line 1147, in _find_and_load_unlocked
  File "<frozen importlib._bootstrap>", line 690, in _load_unlocked
  File "<frozen importlib._bootstrap_external>", line 940, in exec_module
  File "<frozen importlib._bootstrap>", line 241, in _call_with_frames_removed
  File "C:\Users\AMD\AppData\Local\Programs\Python\Python311\Lib\site-packages\onnxruntime\__init__.py", line 61, in <module>
    raise import_capi_exception
  File "C:\Users\AMD\AppData\Local\Programs\Python\Python311\Lib\site-packages\onnxruntime\__init__.py", line 24, in <module>
    from onnxruntime.capi._pybind_state import (
  File "C:\Users\AMD\AppData\Local\Programs\Python\Python311\Lib\site-packages\onnxruntime\capi\_pybind_state.py", line 32, in <module>
    from .onnxruntime_pybind11_state import *  # noqa
    ^^^^^^^^^^^^^^^^^^^^^^^^^^^^^^^^^^^^^^^^^
ImportError: DLL load failed while importing onnxruntime_pybind11_state: A dynamic link library (DLL) initialization routine failed.

During handling of the above exception, another exception occurred:

Traceback (most recent call last):
  File "C:\Users\AMD\sentinel\desktop-app\comprehensive_test_suite.py", line 243, in test_database_connection
    from src.models.advanced_database import db_manager
  File "C:\Users\AMD\sentinel\desktop-app\src\models\advanced_database.py", line 16, in <module>
    import chromadb
  File "C:\Users\AMD\AppData\Local\Programs\Python\Python311\Lib\site-packages\chromadb\__init__.py", line 3, in <module>
    from chromadb.api.client import Client as ClientCreator
  File "C:\Users\AMD\AppData\Local\Programs\Python\Python311\Lib\site-packages\chromadb\api\__init__.py", line 7, in <module>
    from chromadb.api.models.Collection import Collection
  File "C:\Users\AMD\AppData\Local\Programs\Python\Python311\Lib\site-packages\chromadb\api\models\Collection.py", line 57, in <module>
    class Collection(BaseModel):
  File "C:\Users\AMD\AppData\Local\Programs\Python\Python311\Lib\site-packages\chromadb\api\models\Collection.py", line 74, in Collection
    ] = ef.DefaultEmbeddingFunction(),  # type: ignore
        ^^^^^^^^^^^^^^^^^^^^^^^^^^^^^
  File "C:\Users\AMD\AppData\Local\Programs\Python\Python311\Lib\site-packages\chromadb\utils\embedding_functions.py", line 566, in DefaultEmbeddingFunction
    return ONNXMiniLM_L6_V2()
           ^^^^^^^^^^^^^^^^^^
  File "C:\Users\AMD\AppData\Local\Programs\Python\Python311\Lib\site-packages\chromadb\utils\embedding_functions.py", line 397, in __init__
    raise ValueError(
ValueError: The onnxruntime python package is not installed. Please install it with `pip install onnxruntime`

During handling of the above exception, another exception occurred:

Traceback (most recent call last):
  File "C:\Users\AMD\sentinel\desktop-app\comprehensive_test_suite.py", line 141, in run_test
    result = test_func()
             ^^^^^^^^^^^
  File "C:\Users\AMD\sentinel\desktop-app\comprehensive_test_suite.py", line 268, in test_database_connection
    raise Exception(f"Database test failed: {e}")
Exception: Database test failed: The onnxruntime python package is not installed. Please install it with `pip install onnxruntime`

2025-07-30 04:17:15 | ERROR | __main__:run_test:180 | Test Service Health failed: Cognitive Engine health check failed: HTTPConnectionPool(host='localhost', port=8002): Max retries exceeded with url: /health (Caused by NewConnectionError('<urllib3.connection.HTTPConnection object at 0x00000194E95F8D90>: Failed to establish a new connection: [WinError 10061] No connection could be made because the target machine actively refused it'))
Traceback (most recent call last):
  File "C:\Users\AMD\AppData\Local\Programs\Python\Python311\Lib\site-packages\urllib3\connection.py", line 198, in _new_conn
    sock = connection.create_connection(
           ^^^^^^^^^^^^^^^^^^^^^^^^^^^^^
  File "C:\Users\AMD\AppData\Local\Programs\Python\Python311\Lib\site-packages\urllib3\util\connection.py", line 85, in create_connection
    raise err
  File "C:\Users\AMD\AppData\Local\Programs\Python\Python311\Lib\site-packages\urllib3\util\connection.py", line 73, in create_connection
    sock.connect(sa)
ConnectionRefusedError: [WinError 10061] No connection could be made because the target machine actively refused it

The above exception was the direct cause of the following exception:

Traceback (most recent call last):
  File "C:\Users\AMD\AppData\Local\Programs\Python\Python311\Lib\site-packages\urllib3\connectionpool.py", line 787, in urlopen
    response = self._make_request(
               ^^^^^^^^^^^^^^^^^^^
  File "C:\Users\AMD\AppData\Local\Programs\Python\Python311\Lib\site-packages\urllib3\connectionpool.py", line 493, in _make_request
    conn.request(
  File "C:\Users\AMD\AppData\Local\Programs\Python\Python311\Lib\site-packages\urllib3\connection.py", line 494, in request
    self.endheaders()
  File "C:\Users\AMD\AppData\Local\Programs\Python\Python311\Lib\http\client.py", line 1298, in endheaders
    self._send_output(message_body, encode_chunked=encode_chunked)
  File "C:\Users\AMD\AppData\Local\Programs\Python\Python311\Lib\http\client.py", line 1058, in _send_output
    self.send(msg)
  File "C:\Users\AMD\AppData\Local\Programs\Python\Python311\Lib\http\client.py", line 996, in send
    self.connect()
  File "C:\Users\AMD\AppData\Local\Programs\Python\Python311\Lib\site-packages\urllib3\connection.py", line 325, in connect
    self.sock = self._new_conn()
                ^^^^^^^^^^^^^^^^
  File "C:\Users\AMD\AppData\Local\Programs\Python\Python311\Lib\site-packages\urllib3\connection.py", line 213, in _new_conn
    raise NewConnectionError(
urllib3.exceptions.NewConnectionError: <urllib3.connection.HTTPConnection object at 0x00000194E95F8D90>: Failed to establish a new connection: [WinError 10061] No connection could be made because the target machine actively refused it

The above exception was the direct cause of the following exception:

Traceback (most recent call last):
  File "C:\Users\AMD\AppData\Local\Programs\Python\Python311\Lib\site-packages\requests\adapters.py", line 486, in send
    resp = conn.urlopen(
           ^^^^^^^^^^^^^
  File "C:\Users\AMD\AppData\Local\Programs\Python\Python311\Lib\site-packages\urllib3\connectionpool.py", line 841, in urlopen
    retries = retries.increment(
              ^^^^^^^^^^^^^^^^^^
  File "C:\Users\AMD\AppData\Local\Programs\Python\Python311\Lib\site-packages\urllib3\util\retry.py", line 519, in increment
    raise MaxRetryError(_pool, url, reason) from reason  # type: ignore[arg-type]
    ^^^^^^^^^^^^^^^^^^^^^^^^^^^^^^^^^^^^^^^^^^^^^^^^^^^
urllib3.exceptions.MaxRetryError: HTTPConnectionPool(host='localhost', port=8002): Max retries exceeded with url: /health (Caused by NewConnectionError('<urllib3.connection.HTTPConnection object at 0x00000194E95F8D90>: Failed to establish a new connection: [WinError 10061] No connection could be made because the target machine actively refused it'))

During handling of the above exception, another exception occurred:

Traceback (most recent call last):
  File "C:\Users\AMD\sentinel\desktop-app\comprehensive_test_suite.py", line 281, in test_service_health
    response = requests.get(url, timeout=10)
               ^^^^^^^^^^^^^^^^^^^^^^^^^^^^^
  File "C:\Users\AMD\AppData\Local\Programs\Python\Python311\Lib\site-packages\requests\api.py", line 73, in get
    return request("get", url, params=params, **kwargs)
           ^^^^^^^^^^^^^^^^^^^^^^^^^^^^^^^^^^^^^^^^^^^^
  File "C:\Users\AMD\AppData\Local\Programs\Python\Python311\Lib\site-packages\requests\api.py", line 59, in request
    return session.request(method=method, url=url, **kwargs)
           ^^^^^^^^^^^^^^^^^^^^^^^^^^^^^^^^^^^^^^^^^^^^^^^^^
  File "C:\Users\AMD\AppData\Local\Programs\Python\Python311\Lib\site-packages\requests\sessions.py", line 589, in request
    resp = self.send(prep, **send_kwargs)
           ^^^^^^^^^^^^^^^^^^^^^^^^^^^^^^
  File "C:\Users\AMD\AppData\Local\Programs\Python\Python311\Lib\site-packages\requests\sessions.py", line 703, in send
    r = adapter.send(request, **kwargs)
        ^^^^^^^^^^^^^^^^^^^^^^^^^^^^^^^
  File "C:\Users\AMD\AppData\Local\Programs\Python\Python311\Lib\site-packages\requests\adapters.py", line 519, in send
    raise ConnectionError(e, request=request)
requests.exceptions.ConnectionError: HTTPConnectionPool(host='localhost', port=8002): Max retries exceeded with url: /health (Caused by NewConnectionError('<urllib3.connection.HTTPConnection object at 0x00000194E95F8D90>: Failed to establish a new connection: [WinError 10061] No connection could be made because the target machine actively refused it'))

During handling of the above exception, another exception occurred:

Traceback (most recent call last):
  File "C:\Users\AMD\sentinel\desktop-app\comprehensive_test_suite.py", line 141, in run_test
    result = test_func()
             ^^^^^^^^^^^
  File "C:\Users\AMD\sentinel\desktop-app\comprehensive_test_suite.py", line 287, in test_service_health
    raise Exception(f"{service_name} health check failed: {e}")
Exception: Cognitive Engine health check failed: HTTPConnectionPool(host='localhost', port=8002): Max retries exceeded with url: /health (Caused by NewConnectionError('<urllib3.connection.HTTPConnection object at 0x00000194E95F8D90>: Failed to establish a new connection: [WinError 10061] No connection could be made because the target machine actively refused it'))

2025-07-30 04:17:15 | ERROR | __main__:log_test_result:126 | Error in Service Health: Cognitive Engine health check failed: HTTPConnectionPool(host='localhost', port=8002): Max retries exceeded with url: /health (Caused by NewConnectionError('<urllib3.connection.HTTPConnection object at 0x00000194E95F8D90>: Failed to establish a new connection: [WinError 10061] No connection could be made because the target machine actively refused it'))
Traceback (most recent call last):
  File "C:\Users\AMD\AppData\Local\Programs\Python\Python311\Lib\site-packages\urllib3\connection.py", line 198, in _new_conn
    sock = connection.create_connection(
           ^^^^^^^^^^^^^^^^^^^^^^^^^^^^^
  File "C:\Users\AMD\AppData\Local\Programs\Python\Python311\Lib\site-packages\urllib3\util\connection.py", line 85, in create_connection
    raise err
  File "C:\Users\AMD\AppData\Local\Programs\Python\Python311\Lib\site-packages\urllib3\util\connection.py", line 73, in create_connection
    sock.connect(sa)
ConnectionRefusedError: [WinError 10061] No connection could be made because the target machine actively refused it

The above exception was the direct cause of the following exception:

Traceback (most recent call last):
  File "C:\Users\AMD\AppData\Local\Programs\Python\Python311\Lib\site-packages\urllib3\connectionpool.py", line 787, in urlopen
    response = self._make_request(
               ^^^^^^^^^^^^^^^^^^^
  File "C:\Users\AMD\AppData\Local\Programs\Python\Python311\Lib\site-packages\urllib3\connectionpool.py", line 493, in _make_request
    conn.request(
  File "C:\Users\AMD\AppData\Local\Programs\Python\Python311\Lib\site-packages\urllib3\connection.py", line 494, in request
    self.endheaders()
  File "C:\Users\AMD\AppData\Local\Programs\Python\Python311\Lib\http\client.py", line 1298, in endheaders
    self._send_output(message_body, encode_chunked=encode_chunked)
  File "C:\Users\AMD\AppData\Local\Programs\Python\Python311\Lib\http\client.py", line 1058, in _send_output
    self.send(msg)
  File "C:\Users\AMD\AppData\Local\Programs\Python\Python311\Lib\http\client.py", line 996, in send
    self.connect()
  File "C:\Users\AMD\AppData\Local\Programs\Python\Python311\Lib\site-packages\urllib3\connection.py", line 325, in connect
    self.sock = self._new_conn()
                ^^^^^^^^^^^^^^^^
  File "C:\Users\AMD\AppData\Local\Programs\Python\Python311\Lib\site-packages\urllib3\connection.py", line 213, in _new_conn
    raise NewConnectionError(
urllib3.exceptions.NewConnectionError: <urllib3.connection.HTTPConnection object at 0x00000194E95F8D90>: Failed to establish a new connection: [WinError 10061] No connection could be made because the target machine actively refused it

The above exception was the direct cause of the following exception:

Traceback (most recent call last):
  File "C:\Users\AMD\AppData\Local\Programs\Python\Python311\Lib\site-packages\requests\adapters.py", line 486, in send
    resp = conn.urlopen(
           ^^^^^^^^^^^^^
  File "C:\Users\AMD\AppData\Local\Programs\Python\Python311\Lib\site-packages\urllib3\connectionpool.py", line 841, in urlopen
    retries = retries.increment(
              ^^^^^^^^^^^^^^^^^^
  File "C:\Users\AMD\AppData\Local\Programs\Python\Python311\Lib\site-packages\urllib3\util\retry.py", line 519, in increment
    raise MaxRetryError(_pool, url, reason) from reason  # type: ignore[arg-type]
    ^^^^^^^^^^^^^^^^^^^^^^^^^^^^^^^^^^^^^^^^^^^^^^^^^^^
urllib3.exceptions.MaxRetryError: HTTPConnectionPool(host='localhost', port=8002): Max retries exceeded with url: /health (Caused by NewConnectionError('<urllib3.connection.HTTPConnection object at 0x00000194E95F8D90>: Failed to establish a new connection: [WinError 10061] No connection could be made because the target machine actively refused it'))

During handling of the above exception, another exception occurred:

Traceback (most recent call last):
  File "C:\Users\AMD\sentinel\desktop-app\comprehensive_test_suite.py", line 281, in test_service_health
    response = requests.get(url, timeout=10)
               ^^^^^^^^^^^^^^^^^^^^^^^^^^^^^
  File "C:\Users\AMD\AppData\Local\Programs\Python\Python311\Lib\site-packages\requests\api.py", line 73, in get
    return request("get", url, params=params, **kwargs)
           ^^^^^^^^^^^^^^^^^^^^^^^^^^^^^^^^^^^^^^^^^^^^
  File "C:\Users\AMD\AppData\Local\Programs\Python\Python311\Lib\site-packages\requests\api.py", line 59, in request
    return session.request(method=method, url=url, **kwargs)
           ^^^^^^^^^^^^^^^^^^^^^^^^^^^^^^^^^^^^^^^^^^^^^^^^^
  File "C:\Users\AMD\AppData\Local\Programs\Python\Python311\Lib\site-packages\requests\sessions.py", line 589, in request
    resp = self.send(prep, **send_kwargs)
           ^^^^^^^^^^^^^^^^^^^^^^^^^^^^^^
  File "C:\Users\AMD\AppData\Local\Programs\Python\Python311\Lib\site-packages\requests\sessions.py", line 703, in send
    r = adapter.send(request, **kwargs)
        ^^^^^^^^^^^^^^^^^^^^^^^^^^^^^^^
  File "C:\Users\AMD\AppData\Local\Programs\Python\Python311\Lib\site-packages\requests\adapters.py", line 519, in send
    raise ConnectionError(e, request=request)
requests.exceptions.ConnectionError: HTTPConnectionPool(host='localhost', port=8002): Max retries exceeded with url: /health (Caused by NewConnectionError('<urllib3.connection.HTTPConnection object at 0x00000194E95F8D90>: Failed to establish a new connection: [WinError 10061] No connection could be made because the target machine actively refused it'))

During handling of the above exception, another exception occurred:

Traceback (most recent call last):
  File "C:\Users\AMD\sentinel\desktop-app\comprehensive_test_suite.py", line 141, in run_test
    result = test_func()
             ^^^^^^^^^^^
  File "C:\Users\AMD\sentinel\desktop-app\comprehensive_test_suite.py", line 287, in test_service_health
    raise Exception(f"{service_name} health check failed: {e}")
Exception: Cognitive Engine health check failed: HTTPConnectionPool(host='localhost', port=8002): Max retries exceeded with url: /health (Caused by NewConnectionError('<urllib3.connection.HTTPConnection object at 0x00000194E95F8D90>: Failed to establish a new connection: [WinError 10061] No connection could be made because the target machine actively refused it'))

2025-07-30 04:17:35 | ERROR | __main__:test_api_endpoints:339 | [ERROR] Memory search failed: HTTPConnectionPool(host='localhost', port=8001): Read timed out. (read timeout=10)
2025-07-30 04:17:41 | ERROR | __main__:run_test:180 | Test AI Cognitive Engine failed: AI cognitive engine test failed: HTTPConnectionPool(host='localhost', port=8002): Max retries exceeded with url: /generate (Caused by NewConnectionError('<urllib3.connection.HTTPConnection object at 0x00000194E967C910>: Failed to establish a new connection: [WinError 10061] No connection could be made because the target machine actively refused it'))
Traceback (most recent call last):
  File "C:\Users\AMD\AppData\Local\Programs\Python\Python311\Lib\site-packages\urllib3\connection.py", line 198, in _new_conn
    sock = connection.create_connection(
           ^^^^^^^^^^^^^^^^^^^^^^^^^^^^^
  File "C:\Users\AMD\AppData\Local\Programs\Python\Python311\Lib\site-packages\urllib3\util\connection.py", line 85, in create_connection
    raise err
  File "C:\Users\AMD\AppData\Local\Programs\Python\Python311\Lib\site-packages\urllib3\util\connection.py", line 73, in create_connection
    sock.connect(sa)
ConnectionRefusedError: [WinError 10061] No connection could be made because the target machine actively refused it

The above exception was the direct cause of the following exception:

Traceback (most recent call last):
  File "C:\Users\AMD\AppData\Local\Programs\Python\Python311\Lib\site-packages\urllib3\connectionpool.py", line 787, in urlopen
    response = self._make_request(
               ^^^^^^^^^^^^^^^^^^^
  File "C:\Users\AMD\AppData\Local\Programs\Python\Python311\Lib\site-packages\urllib3\connectionpool.py", line 493, in _make_request
    conn.request(
  File "C:\Users\AMD\AppData\Local\Programs\Python\Python311\Lib\site-packages\urllib3\connection.py", line 494, in request
    self.endheaders()
  File "C:\Users\AMD\AppData\Local\Programs\Python\Python311\Lib\http\client.py", line 1298, in endheaders
    self._send_output(message_body, encode_chunked=encode_chunked)
  File "C:\Users\AMD\AppData\Local\Programs\Python\Python311\Lib\http\client.py", line 1058, in _send_output
    self.send(msg)
  File "C:\Users\AMD\AppData\Local\Programs\Python\Python311\Lib\http\client.py", line 996, in send
    self.connect()
  File "C:\Users\AMD\AppData\Local\Programs\Python\Python311\Lib\site-packages\urllib3\connection.py", line 325, in connect
    self.sock = self._new_conn()
                ^^^^^^^^^^^^^^^^
  File "C:\Users\AMD\AppData\Local\Programs\Python\Python311\Lib\site-packages\urllib3\connection.py", line 213, in _new_conn
    raise NewConnectionError(
urllib3.exceptions.NewConnectionError: <urllib3.connection.HTTPConnection object at 0x00000194E967C910>: Failed to establish a new connection: [WinError 10061] No connection could be made because the target machine actively refused it

The above exception was the direct cause of the following exception:

Traceback (most recent call last):
  File "C:\Users\AMD\AppData\Local\Programs\Python\Python311\Lib\site-packages\requests\adapters.py", line 486, in send
    resp = conn.urlopen(
           ^^^^^^^^^^^^^
  File "C:\Users\AMD\AppData\Local\Programs\Python\Python311\Lib\site-packages\urllib3\connectionpool.py", line 841, in urlopen
    retries = retries.increment(
              ^^^^^^^^^^^^^^^^^^
  File "C:\Users\AMD\AppData\Local\Programs\Python\Python311\Lib\site-packages\urllib3\util\retry.py", line 519, in increment
    raise MaxRetryError(_pool, url, reason) from reason  # type: ignore[arg-type]
    ^^^^^^^^^^^^^^^^^^^^^^^^^^^^^^^^^^^^^^^^^^^^^^^^^^^
urllib3.exceptions.MaxRetryError: HTTPConnectionPool(host='localhost', port=8002): Max retries exceeded with url: /generate (Caused by NewConnectionError('<urllib3.connection.HTTPConnection object at 0x00000194E967C910>: Failed to establish a new connection: [WinError 10061] No connection could be made because the target machine actively refused it'))

During handling of the above exception, another exception occurred:

Traceback (most recent call last):
  File "C:\Users\AMD\sentinel\desktop-app\comprehensive_test_suite.py", line 355, in test_ai_cognitive_engine
    response = requests.post(
               ^^^^^^^^^^^^^^
  File "C:\Users\AMD\AppData\Local\Programs\Python\Python311\Lib\site-packages\requests\api.py", line 115, in post
    return request("post", url, data=data, json=json, **kwargs)
           ^^^^^^^^^^^^^^^^^^^^^^^^^^^^^^^^^^^^^^^^^^^^^^^^^^^^
  File "C:\Users\AMD\AppData\Local\Programs\Python\Python311\Lib\site-packages\requests\api.py", line 59, in request
    return session.request(method=method, url=url, **kwargs)
           ^^^^^^^^^^^^^^^^^^^^^^^^^^^^^^^^^^^^^^^^^^^^^^^^^
  File "C:\Users\AMD\AppData\Local\Programs\Python\Python311\Lib\site-packages\requests\sessions.py", line 589, in request
    resp = self.send(prep, **send_kwargs)
           ^^^^^^^^^^^^^^^^^^^^^^^^^^^^^^
  File "C:\Users\AMD\AppData\Local\Programs\Python\Python311\Lib\site-packages\requests\sessions.py", line 703, in send
    r = adapter.send(request, **kwargs)
        ^^^^^^^^^^^^^^^^^^^^^^^^^^^^^^^
  File "C:\Users\AMD\AppData\Local\Programs\Python\Python311\Lib\site-packages\requests\adapters.py", line 519, in send
    raise ConnectionError(e, request=request)
requests.exceptions.ConnectionError: HTTPConnectionPool(host='localhost', port=8002): Max retries exceeded with url: /generate (Caused by NewConnectionError('<urllib3.connection.HTTPConnection object at 0x00000194E967C910>: Failed to establish a new connection: [WinError 10061] No connection could be made because the target machine actively refused it'))

During handling of the above exception, another exception occurred:

Traceback (most recent call last):
  File "C:\Users\AMD\sentinel\desktop-app\comprehensive_test_suite.py", line 141, in run_test
    result = test_func()
             ^^^^^^^^^^^
  File "C:\Users\AMD\sentinel\desktop-app\comprehensive_test_suite.py", line 394, in test_ai_cognitive_engine
    raise Exception(f"AI cognitive engine test failed: {e}")
Exception: AI cognitive engine test failed: HTTPConnectionPool(host='localhost', port=8002): Max retries exceeded with url: /generate (Caused by NewConnectionError('<urllib3.connection.HTTPConnection object at 0x00000194E967C910>: Failed to establish a new connection: [WinError 10061] No connection could be made because the target machine actively refused it'))

2025-07-30 04:17:41 | ERROR | __main__:log_test_result:126 | Error in AI Cognitive Engine: AI cognitive engine test failed: HTTPConnectionPool(host='localhost', port=8002): Max retries exceeded with url: /generate (Caused by NewConnectionError('<urllib3.connection.HTTPConnection object at 0x00000194E967C910>: Failed to establish a new connection: [WinError 10061] No connection could be made because the target machine actively refused it'))
Traceback (most recent call last):
  File "C:\Users\AMD\AppData\Local\Programs\Python\Python311\Lib\site-packages\urllib3\connection.py", line 198, in _new_conn
    sock = connection.create_connection(
           ^^^^^^^^^^^^^^^^^^^^^^^^^^^^^
  File "C:\Users\AMD\AppData\Local\Programs\Python\Python311\Lib\site-packages\urllib3\util\connection.py", line 85, in create_connection
    raise err
  File "C:\Users\AMD\AppData\Local\Programs\Python\Python311\Lib\site-packages\urllib3\util\connection.py", line 73, in create_connection
    sock.connect(sa)
ConnectionRefusedError: [WinError 10061] No connection could be made because the target machine actively refused it

The above exception was the direct cause of the following exception:

Traceback (most recent call last):
  File "C:\Users\AMD\AppData\Local\Programs\Python\Python311\Lib\site-packages\urllib3\connectionpool.py", line 787, in urlopen
    response = self._make_request(
               ^^^^^^^^^^^^^^^^^^^
  File "C:\Users\AMD\AppData\Local\Programs\Python\Python311\Lib\site-packages\urllib3\connectionpool.py", line 493, in _make_request
    conn.request(
  File "C:\Users\AMD\AppData\Local\Programs\Python\Python311\Lib\site-packages\urllib3\connection.py", line 494, in request
    self.endheaders()
  File "C:\Users\AMD\AppData\Local\Programs\Python\Python311\Lib\http\client.py", line 1298, in endheaders
    self._send_output(message_body, encode_chunked=encode_chunked)
  File "C:\Users\AMD\AppData\Local\Programs\Python\Python311\Lib\http\client.py", line 1058, in _send_output
    self.send(msg)
  File "C:\Users\AMD\AppData\Local\Programs\Python\Python311\Lib\http\client.py", line 996, in send
    self.connect()
  File "C:\Users\AMD\AppData\Local\Programs\Python\Python311\Lib\site-packages\urllib3\connection.py", line 325, in connect
    self.sock = self._new_conn()
                ^^^^^^^^^^^^^^^^
  File "C:\Users\AMD\AppData\Local\Programs\Python\Python311\Lib\site-packages\urllib3\connection.py", line 213, in _new_conn
    raise NewConnectionError(
urllib3.exceptions.NewConnectionError: <urllib3.connection.HTTPConnection object at 0x00000194E967C910>: Failed to establish a new connection: [WinError 10061] No connection could be made because the target machine actively refused it

The above exception was the direct cause of the following exception:

Traceback (most recent call last):
  File "C:\Users\AMD\AppData\Local\Programs\Python\Python311\Lib\site-packages\requests\adapters.py", line 486, in send
    resp = conn.urlopen(
           ^^^^^^^^^^^^^
  File "C:\Users\AMD\AppData\Local\Programs\Python\Python311\Lib\site-packages\urllib3\connectionpool.py", line 841, in urlopen
    retries = retries.increment(
              ^^^^^^^^^^^^^^^^^^
  File "C:\Users\AMD\AppData\Local\Programs\Python\Python311\Lib\site-packages\urllib3\util\retry.py", line 519, in increment
    raise MaxRetryError(_pool, url, reason) from reason  # type: ignore[arg-type]
    ^^^^^^^^^^^^^^^^^^^^^^^^^^^^^^^^^^^^^^^^^^^^^^^^^^^
urllib3.exceptions.MaxRetryError: HTTPConnectionPool(host='localhost', port=8002): Max retries exceeded with url: /generate (Caused by NewConnectionError('<urllib3.connection.HTTPConnection object at 0x00000194E967C910>: Failed to establish a new connection: [WinError 10061] No connection could be made because the target machine actively refused it'))

During handling of the above exception, another exception occurred:

Traceback (most recent call last):
  File "C:\Users\AMD\sentinel\desktop-app\comprehensive_test_suite.py", line 355, in test_ai_cognitive_engine
    response = requests.post(
               ^^^^^^^^^^^^^^
  File "C:\Users\AMD\AppData\Local\Programs\Python\Python311\Lib\site-packages\requests\api.py", line 115, in post
    return request("post", url, data=data, json=json, **kwargs)
           ^^^^^^^^^^^^^^^^^^^^^^^^^^^^^^^^^^^^^^^^^^^^^^^^^^^^
  File "C:\Users\AMD\AppData\Local\Programs\Python\Python311\Lib\site-packages\requests\api.py", line 59, in request
    return session.request(method=method, url=url, **kwargs)
           ^^^^^^^^^^^^^^^^^^^^^^^^^^^^^^^^^^^^^^^^^^^^^^^^^
  File "C:\Users\AMD\AppData\Local\Programs\Python\Python311\Lib\site-packages\requests\sessions.py", line 589, in request
    resp = self.send(prep, **send_kwargs)
           ^^^^^^^^^^^^^^^^^^^^^^^^^^^^^^
  File "C:\Users\AMD\AppData\Local\Programs\Python\Python311\Lib\site-packages\requests\sessions.py", line 703, in send
    r = adapter.send(request, **kwargs)
        ^^^^^^^^^^^^^^^^^^^^^^^^^^^^^^^
  File "C:\Users\AMD\AppData\Local\Programs\Python\Python311\Lib\site-packages\requests\adapters.py", line 519, in send
    raise ConnectionError(e, request=request)
requests.exceptions.ConnectionError: HTTPConnectionPool(host='localhost', port=8002): Max retries exceeded with url: /generate (Caused by NewConnectionError('<urllib3.connection.HTTPConnection object at 0x00000194E967C910>: Failed to establish a new connection: [WinError 10061] No connection could be made because the target machine actively refused it'))

During handling of the above exception, another exception occurred:

Traceback (most recent call last):
  File "C:\Users\AMD\sentinel\desktop-app\comprehensive_test_suite.py", line 141, in run_test
    result = test_func()
             ^^^^^^^^^^^
  File "C:\Users\AMD\sentinel\desktop-app\comprehensive_test_suite.py", line 394, in test_ai_cognitive_engine
    raise Exception(f"AI cognitive engine test failed: {e}")
Exception: AI cognitive engine test failed: HTTPConnectionPool(host='localhost', port=8002): Max retries exceeded with url: /generate (Caused by NewConnectionError('<urllib3.connection.HTTPConnection object at 0x00000194E967C910>: Failed to establish a new connection: [WinError 10061] No connection could be made because the target machine actively refused it'))

2025-07-30 04:18:00 | ERROR | __main__:run_test:180 | Test Error Handling failed: Error handling test failed: The onnxruntime python package is not installed. Please install it with `pip install onnxruntime`
Traceback (most recent call last):
  File "C:\Users\AMD\AppData\Local\Programs\Python\Python311\Lib\site-packages\chromadb\utils\embedding_functions.py", line 395, in __init__
    self.ort = importlib.import_module("onnxruntime")
               ^^^^^^^^^^^^^^^^^^^^^^^^^^^^^^^^^^^^^^
  File "C:\Users\AMD\AppData\Local\Programs\Python\Python311\Lib\importlib\__init__.py", line 126, in import_module
    return _bootstrap._gcd_import(name[level:], package, level)
           ^^^^^^^^^^^^^^^^^^^^^^^^^^^^^^^^^^^^^^^^^^^^^^^^^^^^
  File "<frozen importlib._bootstrap>", line 1204, in _gcd_import
  File "<frozen importlib._bootstrap>", line 1176, in _find_and_load
  File "<frozen importlib._bootstrap>", line 1147, in _find_and_load_unlocked
  File "<frozen importlib._bootstrap>", line 690, in _load_unlocked
  File "<frozen importlib._bootstrap_external>", line 940, in exec_module
  File "<frozen importlib._bootstrap>", line 241, in _call_with_frames_removed
  File "C:\Users\AMD\AppData\Local\Programs\Python\Python311\Lib\site-packages\onnxruntime\__init__.py", line 61, in <module>
    raise import_capi_exception
  File "C:\Users\AMD\AppData\Local\Programs\Python\Python311\Lib\site-packages\onnxruntime\__init__.py", line 24, in <module>
    from onnxruntime.capi._pybind_state import (
  File "C:\Users\AMD\AppData\Local\Programs\Python\Python311\Lib\site-packages\onnxruntime\capi\_pybind_state.py", line 32, in <module>
    from .onnxruntime_pybind11_state import *  # noqa
    ^^^^^^^^^^^^^^^^^^^^^^^^^^^^^^^^^^^^^^^^^
ImportError: DLL load failed while importing onnxruntime_pybind11_state: A dynamic link library (DLL) initialization routine failed.

During handling of the above exception, another exception occurred:

Traceback (most recent call last):
  File "C:\Users\AMD\sentinel\desktop-app\comprehensive_test_suite.py", line 483, in test_error_handling
    from src.models.advanced_database import db_manager
  File "C:\Users\AMD\sentinel\desktop-app\src\models\advanced_database.py", line 16, in <module>
    import chromadb
  File "C:\Users\AMD\AppData\Local\Programs\Python\Python311\Lib\site-packages\chromadb\__init__.py", line 3, in <module>
    from chromadb.api.client import Client as ClientCreator
  File "C:\Users\AMD\AppData\Local\Programs\Python\Python311\Lib\site-packages\chromadb\api\__init__.py", line 7, in <module>
    from chromadb.api.models.Collection import Collection
  File "C:\Users\AMD\AppData\Local\Programs\Python\Python311\Lib\site-packages\chromadb\api\models\Collection.py", line 57, in <module>
    class Collection(BaseModel):
  File "C:\Users\AMD\AppData\Local\Programs\Python\Python311\Lib\site-packages\chromadb\api\models\Collection.py", line 74, in Collection
    ] = ef.DefaultEmbeddingFunction(),  # type: ignore
        ^^^^^^^^^^^^^^^^^^^^^^^^^^^^^
  File "C:\Users\AMD\AppData\Local\Programs\Python\Python311\Lib\site-packages\chromadb\utils\embedding_functions.py", line 566, in DefaultEmbeddingFunction
    return ONNXMiniLM_L6_V2()
           ^^^^^^^^^^^^^^^^^^
  File "C:\Users\AMD\AppData\Local\Programs\Python\Python311\Lib\site-packages\chromadb\utils\embedding_functions.py", line 397, in __init__
    raise ValueError(
ValueError: The onnxruntime python package is not installed. Please install it with `pip install onnxruntime`

During handling of the above exception, another exception occurred:

Traceback (most recent call last):
  File "C:\Users\AMD\sentinel\desktop-app\comprehensive_test_suite.py", line 141, in run_test
    result = test_func()
             ^^^^^^^^^^^
  File "C:\Users\AMD\sentinel\desktop-app\comprehensive_test_suite.py", line 494, in test_error_handling
    raise Exception(f"Error handling test failed: {e}")
Exception: Error handling test failed: The onnxruntime python package is not installed. Please install it with `pip install onnxruntime`

2025-07-30 04:18:00 | ERROR | __main__:log_test_result:126 | Error in Error Handling: Error handling test failed: The onnxruntime python package is not installed. Please install it with `pip install onnxruntime`
Traceback (most recent call last):
  File "C:\Users\AMD\AppData\Local\Programs\Python\Python311\Lib\site-packages\chromadb\utils\embedding_functions.py", line 395, in __init__
    self.ort = importlib.import_module("onnxruntime")
               ^^^^^^^^^^^^^^^^^^^^^^^^^^^^^^^^^^^^^^
  File "C:\Users\AMD\AppData\Local\Programs\Python\Python311\Lib\importlib\__init__.py", line 126, in import_module
    return _bootstrap._gcd_import(name[level:], package, level)
           ^^^^^^^^^^^^^^^^^^^^^^^^^^^^^^^^^^^^^^^^^^^^^^^^^^^^
  File "<frozen importlib._bootstrap>", line 1204, in _gcd_import
  File "<frozen importlib._bootstrap>", line 1176, in _find_and_load
  File "<frozen importlib._bootstrap>", line 1147, in _find_and_load_unlocked
  File "<frozen importlib._bootstrap>", line 690, in _load_unlocked
  File "<frozen importlib._bootstrap_external>", line 940, in exec_module
  File "<frozen importlib._bootstrap>", line 241, in _call_with_frames_removed
  File "C:\Users\AMD\AppData\Local\Programs\Python\Python311\Lib\site-packages\onnxruntime\__init__.py", line 61, in <module>
    raise import_capi_exception
  File "C:\Users\AMD\AppData\Local\Programs\Python\Python311\Lib\site-packages\onnxruntime\__init__.py", line 24, in <module>
    from onnxruntime.capi._pybind_state import (
  File "C:\Users\AMD\AppData\Local\Programs\Python\Python311\Lib\site-packages\onnxruntime\capi\_pybind_state.py", line 32, in <module>
    from .onnxruntime_pybind11_state import *  # noqa
    ^^^^^^^^^^^^^^^^^^^^^^^^^^^^^^^^^^^^^^^^^
ImportError: DLL load failed while importing onnxruntime_pybind11_state: A dynamic link library (DLL) initialization routine failed.

During handling of the above exception, another exception occurred:

Traceback (most recent call last):
  File "C:\Users\AMD\sentinel\desktop-app\comprehensive_test_suite.py", line 483, in test_error_handling
    from src.models.advanced_database import db_manager
  File "C:\Users\AMD\sentinel\desktop-app\src\models\advanced_database.py", line 16, in <module>
    import chromadb
  File "C:\Users\AMD\AppData\Local\Programs\Python\Python311\Lib\site-packages\chromadb\__init__.py", line 3, in <module>
    from chromadb.api.client import Client as ClientCreator
  File "C:\Users\AMD\AppData\Local\Programs\Python\Python311\Lib\site-packages\chromadb\api\__init__.py", line 7, in <module>
    from chromadb.api.models.Collection import Collection
  File "C:\Users\AMD\AppData\Local\Programs\Python\Python311\Lib\site-packages\chromadb\api\models\Collection.py", line 57, in <module>
    class Collection(BaseModel):
  File "C:\Users\AMD\AppData\Local\Programs\Python\Python311\Lib\site-packages\chromadb\api\models\Collection.py", line 74, in Collection
    ] = ef.DefaultEmbeddingFunction(),  # type: ignore
        ^^^^^^^^^^^^^^^^^^^^^^^^^^^^^
  File "C:\Users\AMD\AppData\Local\Programs\Python\Python311\Lib\site-packages\chromadb\utils\embedding_functions.py", line 566, in DefaultEmbeddingFunction
    return ONNXMiniLM_L6_V2()
           ^^^^^^^^^^^^^^^^^^
  File "C:\Users\AMD\AppData\Local\Programs\Python\Python311\Lib\site-packages\chromadb\utils\embedding_functions.py", line 397, in __init__
    raise ValueError(
ValueError: The onnxruntime python package is not installed. Please install it with `pip install onnxruntime`

During handling of the above exception, another exception occurred:

Traceback (most recent call last):
  File "C:\Users\AMD\sentinel\desktop-app\comprehensive_test_suite.py", line 141, in run_test
    result = test_func()
             ^^^^^^^^^^^
  File "C:\Users\AMD\sentinel\desktop-app\comprehensive_test_suite.py", line 494, in test_error_handling
    raise Exception(f"Error handling test failed: {e}")
Exception: Error handling test failed: The onnxruntime python package is not installed. Please install it with `pip install onnxruntime`

2025-07-30 04:18:09 | ERROR | __main__:main:677 | Test suite failed: 'charmap' codec can't encode character '\U0001f4a1' in position 2: character maps to <undefined>
