{
  "summary": {
    "total_issues_identified": 25,
    "issues_attempted": 25,
    "issues_fixed": 0,
    "issues_failed": 25,
    "remaining_issues_after_fix": 0,
    "sentry_errors_processed": 25
  },
  "details": [
    {
      "file_path": "unknown",
      "line": 0,
      "type": "SentryError",
      "message": "default: Cognitive Forge Engine initialized successfully",
      "frequency": "325",
      "suggested_fix": "Review the error context and apply appropriate fix",
      "source": "sentry",
      "proposed_action": "Fix the SentryError.",
      "status": "FAILED",
      "final_error": "Validation after fix failed: [Errno 2] No such file or directory: 'unknown'"
    },
    {
      "file_path": "unknown",
      "line": 0,
      "type": "SentryError",
      "message": "default: LLM initialized successfully",
      "frequency": "346",
      "suggested_fix": "Review the error context and apply appropriate fix",
      "source": "sentry",
      "proposed_action": "Fix the SentryError.",
      "status": "FAILED",
      "final_error": "Validation after fix failed: [Errno 2] No such file or directory: 'unknown'"
    },
    {
      "file_path": "unknown",
      "line": 0,
      "type": "SentryError",
      "message": "default: 2025-07-31 18:11:21.290 | ERROR    | Fix_AI:run_execution_phase:372 - Could not fix default: 2025-07-31 18:08:03.039 | ERROR    | Fix_AI:run_execution_phase:372 - Could not fix default: Traceback (most recent call last): after 3 attempts. after 3 attempts.",
      "frequency": "1",
      "suggested_fix": "Review the error context and apply appropriate fix",
      "source": "sentry",
      "proposed_action": "Fix the SentryError.",
      "status": "FAILED",
      "final_error": "Validation after fix failed: [Errno 2] No such file or directory: 'unknown'"
    },
    {
      "file_path": "unknown",
      "line": 0,
      "type": "SentryError",
      "message": "default: 2025-07-31 18:11:21.233 | ERROR    | Fix_AI:run_execution_phase:372 - Could not fix default: 2025-07-31 18:08:03.054 | ERROR    | Fix_AI:run_execution_phase:372 - Could not fix error: ConnectionAbortedError: [WinError 10053] An established connection wa...",
      "frequency": "1",
      "suggested_fix": "Review the error context and apply appropriate fix",
      "source": "sentry",
      "proposed_action": "Fix the SentryError.",
      "status": "FAILED",
      "final_error": "Validation after fix failed: [Errno 2] No such file or directory: 'unknown'"
    },
    {
      "file_path": "unknown",
      "line": 0,
      "type": "SentryError",
      "message": "default: 2025-07-31 18:11:21.210 | ERROR    | Fix_AI:run_execution_phase:372 - Could not fix default: 2025-07-31 18:08:03.070 | ERROR    | Fix_AI:run_execution_phase:372 - Could not fix default: 2025-07-31 17:54:48.191 | ERROR    | src.utils.crewai_bypass:execut...",
      "frequency": "1",
      "suggested_fix": "Review the error context and apply appropriate fix",
      "source": "sentry",
      "proposed_action": "Fix the SentryError.",
      "status": "FAILED",
      "final_error": "Validation after fix failed: [Errno 2] No such file or directory: 'unknown'"
    },
    {
      "file_path": "unknown",
      "line": 0,
      "type": "SentryError",
      "message": "default: 2025-07-31 18:11:21.196 | ERROR    | Fix_AI:run_execution_phase:372 - Could not fix default: 2025-07-31 18:08:03.084 | ERROR    | Fix_AI:run_execution_phase:372 - Could not fix default: 2025-07-31 17:54:48.052 | ERROR    | src.core.cognitive_forge_engin...",
      "frequency": "1",
      "suggested_fix": "Review the error context and apply appropriate fix",
      "source": "sentry",
      "proposed_action": "Fix the SentryError.",
      "status": "FAILED",
      "final_error": "Validation after fix failed: [Errno 2] No such file or directory: 'unknown'"
    },
    {
      "file_path": "unknown",
      "line": 0,
      "type": "SentryError",
      "message": "default: 2025-07-31 18:11:21.172 | ERROR    | Fix_AI:run_execution_phase:372 - Could not fix default: 2025-07-31 18:08:03.103 | ERROR    | Fix_AI:run_execution_phase:372 - Could not fix default: 2025-07-31 17:54:48.039 | ERROR    | src.core.cognitive_forge_engin...",
      "frequency": "2",
      "suggested_fix": "Review the error context and apply appropriate fix",
      "source": "sentry",
      "proposed_action": "Fix the SentryError.",
      "status": "FAILED",
      "final_error": "Validation after fix failed: [Errno 2] No such file or directory: 'unknown'"
    },
    {
      "file_path": "unknown",
      "line": 0,
      "type": "SentryError",
      "message": "default: 2025-07-31 18:11:21.151 | ERROR    | Fix_AI:run_execution_phase:372 - Could not fix default: 2025-07-31 18:08:03.112 | ERROR    | Fix_AI:run_execution_phase:372 - Could not fix default: 2025-07-31 17:54:47.999 | ERROR    | src.utils.crewai_bypass:execut...",
      "frequency": "1",
      "suggested_fix": "Review the error context and apply appropriate fix",
      "source": "sentry",
      "proposed_action": "Fix the SentryError.",
      "status": "FAILED",
      "final_error": "Validation after fix failed: [Errno 2] No such file or directory: 'unknown'"
    },
    {
      "file_path": "unknown",
      "line": 0,
      "type": "SentryError",
      "message": "default: 2025-07-31 18:11:21.130 | ERROR    | Fix_AI:run_execution_phase:372 - Could not fix default: 2025-07-31 18:08:03.135 | ERROR    | Fix_AI:run_execution_phase:372 - Could not fix default: 2025-07-31 17:54:47.987 | ERROR    | src.utils.google_ai_wrapper:mo...",
      "frequency": "1",
      "suggested_fix": "Review the error context and apply appropriate fix",
      "source": "sentry",
      "proposed_action": "Fix the SentryError.",
      "status": "FAILED",
      "final_error": "Validation after fix failed: [Errno 2] No such file or directory: 'unknown'"
    },
    {
      "file_path": "unknown",
      "line": 0,
      "type": "SentryError",
      "message": "default: 2025-07-31 18:11:21.084 | ERROR    | Fix_AI:run_execution_phase:372 - Could not fix default: 2025-07-31 18:08:03.170 | ERROR    | Fix_AI:run_execution_phase:372 - Could not fix default: 2025-07-31 17:54:46.493 | ERROR    | src.core.cognitive_forge_engin...",
      "frequency": "1",
      "suggested_fix": "Review the error context and apply appropriate fix",
      "source": "sentry",
      "proposed_action": "Fix the SentryError.",
      "status": "FAILED",
      "final_error": "Validation after fix failed: [Errno 2] No such file or directory: 'unknown'"
    },
    {
      "file_path": "unknown",
      "line": 0,
      "type": "SentryError",
      "message": "default: 2025-07-31 18:11:21.063 | ERROR    | Fix_AI:run_execution_phase:372 - Could not fix default: 2025-07-31 18:08:03.184 | ERROR    | Fix_AI:run_execution_phase:372 - Could not fix default: 2025-07-31 17:45:54.716 | ERROR    | src.core.cognitive_forge_engin...",
      "frequency": "1",
      "suggested_fix": "Review the error context and apply appropriate fix",
      "source": "sentry",
      "proposed_action": "Fix the SentryError.",
      "status": "FAILED",
      "final_error": "Validation after fix failed: [Errno 2] No such file or directory: 'unknown'"
    },
    {
      "file_path": "unknown",
      "line": 0,
      "type": "SentryError",
      "message": "default: 2025-07-31 18:11:21.043 | ERROR    | Fix_AI:run_execution_phase:372 - Could not fix default: 2025-07-31 18:08:03.203 | ERROR    | Fix_AI:run_execution_phase:372 - Could not fix default: 2025-07-31 17:45:54.695 | ERROR    | src.utils.google_ai_wrapper:_g...",
      "frequency": "1",
      "suggested_fix": "Review the error context and apply appropriate fix",
      "source": "sentry",
      "proposed_action": "Fix the SentryError.",
      "status": "FAILED",
      "final_error": "Validation after fix failed: [Errno 2] No such file or directory: 'unknown'"
    },
    {
      "file_path": "unknown",
      "line": 0,
      "type": "SentryError",
      "message": "default: 2025-07-31 18:11:21.024 | ERROR    | Fix_AI:run_execution_phase:372 - Could not fix default: 2025-07-31 18:08:03.221 | ERROR    | Fix_AI:run_execution_phase:372 - Could not fix default: 2025-07-31 17:31:38.570 | ERROR    | src.core.advanced_intelligence...",
      "frequency": "1",
      "suggested_fix": "Review the error context and apply appropriate fix",
      "source": "sentry",
      "proposed_action": "Fix the SentryError.",
      "status": "FAILED",
      "final_error": "Validation after fix failed: [Errno 2] No such file or directory: 'unknown'"
    },
    {
      "file_path": "unknown",
      "line": 0,
      "type": "SentryError",
      "message": "default: 2025-07-31 18:11:21.003 | ERROR    | Fix_AI:run_execution_phase:372 - Could not fix default: 2025-07-31 18:08:03.239 | ERROR    | Fix_AI:run_execution_phase:372 - Could not fix default: 2025-07-31 17:26:05.503 | ERROR    | src.core.advanced_intelligence...",
      "frequency": "1",
      "suggested_fix": "Review the error context and apply appropriate fix",
      "source": "sentry",
      "proposed_action": "Fix the SentryError.",
      "status": "FAILED",
      "final_error": "Validation after fix failed: [Errno 2] No such file or directory: 'unknown'"
    },
    {
      "file_path": "unknown",
      "line": 0,
      "type": "SentryError",
      "message": "default: 2025-07-31 18:11:20.981 | ERROR    | Fix_AI:run_execution_phase:372 - Could not fix default: 2025-07-31 18:08:03.259 | ERROR    | Fix_AI:run_execution_phase:372 - Could not fix default: 2025-07-31 17:26:05.474 | ERROR    | src.utils.performance_optimize...",
      "frequency": "1",
      "suggested_fix": "Review the error context and apply appropriate fix",
      "source": "sentry",
      "proposed_action": "Fix the SentryError.",
      "status": "FAILED",
      "final_error": "Validation after fix failed: [Errno 2] No such file or directory: 'unknown'"
    },
    {
      "file_path": "unknown",
      "line": 0,
      "type": "SentryError",
      "message": "default: 2025-07-31 18:11:20.952 | ERROR    | Fix_AI:run_execution_phase:372 - Could not fix default: 2025-07-31 18:08:03.277 | ERROR    | Fix_AI:run_execution_phase:372 - Could not fix default: 2025-07-31 16:14:58.073 | ERROR    | src.core.cognitive_forge_engin...",
      "frequency": "1",
      "suggested_fix": "Review the error context and apply appropriate fix",
      "source": "sentry",
      "proposed_action": "Fix the SentryError.",
      "status": "FAILED",
      "final_error": "Validation after fix failed: [Errno 2] No such file or directory: 'unknown'"
    },
    {
      "file_path": "unknown",
      "line": 0,
      "type": "SentryError",
      "message": "default: 2025-07-31 18:11:20.932 | ERROR    | Fix_AI:run_execution_phase:372 - Could not fix default: 2025-07-31 18:08:03.295 | ERROR    | Fix_AI:run_execution_phase:372 - Could not fix error: ValueError: Invalid JSON format: Expecting value: line 1 column 1 (ch...",
      "frequency": "1",
      "suggested_fix": "Review the error context and apply appropriate fix",
      "source": "sentry",
      "proposed_action": "Fix the SentryError.",
      "status": "FAILED",
      "final_error": "Validation after fix failed: [Errno 2] No such file or directory: 'unknown'"
    },
    {
      "file_path": "unknown",
      "line": 0,
      "type": "SentryError",
      "message": "default: 2025-07-31 18:11:20.909 | ERROR    | Fix_AI:run_execution_phase:372 - Could not fix default: 2025-07-31 18:08:03.313 | ERROR    | Fix_AI:run_execution_phase:372 - Could not fix default: 2025-07-31 16:14:58.044 | ERROR    | src.core.cognitive_forge_engin...",
      "frequency": "1",
      "suggested_fix": "Review the error context and apply appropriate fix",
      "source": "sentry",
      "proposed_action": "Fix the SentryError.",
      "status": "FAILED",
      "final_error": "Validation after fix failed: [Errno 2] No such file or directory: 'unknown'"
    },
    {
      "file_path": "unknown",
      "line": 0,
      "type": "SentryError",
      "message": "default: 2025-07-31 18:11:20.888 | ERROR    | Fix_AI:run_execution_phase:372 - Could not fix default: 2025-07-31 18:08:03.333 | ERROR    | Fix_AI:run_execution_phase:372 - Could not fix default: 2025-07-31 16:14:58.030 | ERROR    | src.utils.google_ai_wrapper:_g...",
      "frequency": "1",
      "suggested_fix": "Review the error context and apply appropriate fix",
      "source": "sentry",
      "proposed_action": "Fix the SentryError.",
      "status": "FAILED",
      "final_error": "Validation after fix failed: [Errno 2] No such file or directory: 'unknown'"
    },
    {
      "file_path": "unknown",
      "line": 0,
      "type": "SentryError",
      "message": "default: 2025-07-31 18:11:20.871 | ERROR    | Fix_AI:run_execution_phase:372 - Could not fix default: 2025-07-31 18:08:03.348 | ERROR    | Fix_AI:run_execution_phase:372 - Could not fix default: Mission started: test_mission_20250731_161458 after 3 attempts. aft...",
      "frequency": "1",
      "suggested_fix": "Review the error context and apply appropriate fix",
      "source": "sentry",
      "proposed_action": "Fix the SentryError.",
      "status": "FAILED",
      "final_error": "Validation after fix failed: [Errno 2] No such file or directory: 'unknown'"
    },
    {
      "file_path": "unknown",
      "line": 0,
      "type": "SentryError",
      "message": "default: 2025-07-31 18:11:20.855 | ERROR    | Fix_AI:run_execution_phase:372 - Could not fix default: 2025-07-31 18:08:03.369 | ERROR    | Fix_AI:run_execution_phase:372 - Could not fix default: 2025-07-31 16:11:57.907 | ERROR    | src.core.cognitive_forge_engin...",
      "frequency": "1",
      "suggested_fix": "Review the error context and apply appropriate fix",
      "source": "sentry",
      "proposed_action": "Fix the SentryError.",
      "status": "FAILED",
      "final_error": "Validation after fix failed: [Errno 2] No such file or directory: 'unknown'"
    },
    {
      "file_path": "unknown",
      "line": 0,
      "type": "SentryError",
      "message": "default: 2025-07-31 18:11:20.834 | ERROR    | Fix_AI:run_execution_phase:372 - Could not fix default: 2025-07-31 18:08:03.387 | ERROR    | Fix_AI:run_execution_phase:372 - Could not fix default: Mission started: test_mission_20250731_161157 after 3 attempts. aft...",
      "frequency": "1",
      "suggested_fix": "Review the error context and apply appropriate fix",
      "source": "sentry",
      "proposed_action": "Fix the SentryError.",
      "status": "FAILED",
      "final_error": "Validation after fix failed: [Errno 2] No such file or directory: 'unknown'"
    },
    {
      "file_path": "unknown",
      "line": 0,
      "type": "SentryError",
      "message": "default: 2025-07-31 18:11:20.819 | ERROR    | Fix_AI:run_execution_phase:372 - Could not fix default: 2025-07-31 18:08:03.403 | ERROR    | Fix_AI:run_execution_phase:372 - Could not fix default: 2025-07-31 16:09:07.287 | ERROR    | src.core.cognitive_forge_engin...",
      "frequency": "1",
      "suggested_fix": "Review the error context and apply appropriate fix",
      "source": "sentry",
      "proposed_action": "Fix the SentryError.",
      "status": "FAILED",
      "final_error": "Validation after fix failed: [Errno 2] No such file or directory: 'unknown'"
    },
    {
      "file_path": "unknown",
      "line": 0,
      "type": "SentryError",
      "message": "default: 2025-07-31 18:11:20.804 | ERROR    | Fix_AI:run_execution_phase:372 - Could not fix default: Traceback (most recent call last): after 3 attempts.",
      "frequency": "2",
      "suggested_fix": "Review the error context and apply appropriate fix",
      "source": "sentry",
      "proposed_action": "Fix the SentryError.",
      "status": "FAILED",
      "final_error": "Validation after fix failed: [Errno 2] No such file or directory: 'unknown'"
    },
    {
      "file_path": "unknown",
      "line": 0,
      "type": "SentryError",
      "message": "default: 2025-07-31 18:11:20.788 | ERROR    | Fix_AI:run_execution_phase:372 - Could not fix default: LLM initialized successfully after 3 attempts.",
      "frequency": "2",
      "suggested_fix": "Review the error context and apply appropriate fix",
      "source": "sentry",
      "proposed_action": "Fix the SentryError.",
      "status": "FAILED",
      "final_error": "Validation after fix failed: [Errno 2] No such file or directory: 'unknown'"
    }
  ],
  "start_time": "2025-07-31T18:35:59.997547",
  "final_validation": {
    "initial_issues": 25,
    "remaining_issues": 0
  },
  "end_time": "2025-07-31T18:37:26.062554"
}