2025-08-01 21:10:39,242 INFO    MainThread:18476 [wandb_init.py:setup_run_log_directory():703] Logging user logs to C:\Users\AMD\sentinel\desktop-app\wandb\run-20250801_211039-n75sqa1t\logs\debug.log
2025-08-01 21:10:39,242 INFO    MainThread:18476 [wandb_init.py:setup_run_log_directory():704] Logging internal logs to C:\Users\AMD\sentinel\desktop-app\wandb\run-20250801_211039-n75sqa1t\logs\debug-internal.log
2025-08-01 21:10:39,242 INFO    MainThread:18476 [wandb_init.py:init():830] calling init triggers
2025-08-01 21:10:39,243 INFO    MainThread:18476 [wandb_init.py:init():835] wandb.init called with sweep_config: {}
config: {'_wandb': {}}
2025-08-01 21:28:43,465 INFO    MsgRouterThr:18476 [mailbox.py:close():129] [no run ID] Closing mailbox, abandoning 1 handles.
2025-08-01 21:28:45,646 ERROR   MainThread:18476 [redirect.py:_on_write():664] [all runs] error in stdout callback
Traceback (most recent call last):
  File "C:\Users\AMD\AppData\Local\Programs\Python\Python311\Lib\site-packages\wandb\sdk\lib\redirect.py", line 662, in _on_write
    cb(written_data)
  File "C:\Users\AMD\AppData\Local\Programs\Python\Python311\Lib\site-packages\wandb\sdk\wandb_run.py", line 2379, in <lambda>
    lambda data: self._console_raw_callback("stdout", data),
                 ^^^^^^^^^^^^^^^^^^^^^^^^^^^^^^^^^^^^^^^^^^
  File "C:\Users\AMD\AppData\Local\Programs\Python\Python311\Lib\site-packages\wandb\sdk\wandb_run.py", line 398, in wrapper
    return func(self, *args, **kwargs)
           ^^^^^^^^^^^^^^^^^^^^^^^^^^^
  File "C:\Users\AMD\AppData\Local\Programs\Python\Python311\Lib\site-packages\wandb\sdk\wandb_run.py", line 456, in wrapper_fn
    return func(self, *args, **kwargs)
           ^^^^^^^^^^^^^^^^^^^^^^^^^^^
  File "C:\Users\AMD\AppData\Local\Programs\Python\Python311\Lib\site-packages\wandb\sdk\wandb_run.py", line 1566, in _console_raw_callback
    self._backend.interface.publish_output_raw(name, data)
  File "C:\Users\AMD\AppData\Local\Programs\Python\Python311\Lib\site-packages\wandb\sdk\interface\interface.py", line 771, in publish_output_raw
    self._publish_output_raw(o)
  File "C:\Users\AMD\AppData\Local\Programs\Python\Python311\Lib\site-packages\wandb\sdk\interface\interface_shared.py", line 38, in _publish_output_raw
    self._publish(rec)
  File "C:\Users\AMD\AppData\Local\Programs\Python\Python311\Lib\site-packages\wandb\sdk\interface\interface_sock.py", line 39, in _publish
    self._sock_client.send_record_publish(record)
  File "C:\Users\AMD\AppData\Local\Programs\Python\Python311\Lib\site-packages\wandb\sdk\lib\sock_client.py", line 170, in send_record_publish
    self.send_server_request(server_req)
  File "C:\Users\AMD\AppData\Local\Programs\Python\Python311\Lib\site-packages\wandb\sdk\lib\sock_client.py", line 150, in send_server_request
    self._send_message(msg)
  File "C:\Users\AMD\AppData\Local\Programs\Python\Python311\Lib\site-packages\wandb\sdk\lib\sock_client.py", line 147, in _send_message
    self._sendall_with_error_handle(header + data)
  File "C:\Users\AMD\AppData\Local\Programs\Python\Python311\Lib\site-packages\wandb\sdk\lib\sock_client.py", line 126, in _sendall_with_error_handle
    sent = self._sock.send(data)
           ^^^^^^^^^^^^^^^^^^^^^
ConnectionAbortedError: [WinError 10053] An established connection was aborted by the software in your host machine
