2025-07-31 17:36:13,434 INFO    MainThread:12572 [wandb_setup.py:_flush():80] Current SDK version is 0.21.0
2025-07-31 17:36:13,434 INFO    MainThread:12572 [wandb_setup.py:_flush():80] Configure stats pid to 12572
2025-07-31 17:36:13,434 INFO    MainThread:12572 [wandb_setup.py:_flush():80] Loading settings from C:\Users\AMD\.config\wandb\settings
2025-07-31 17:36:13,434 INFO    MainThread:12572 [wandb_setup.py:_flush():80] Loading settings from C:\Users\AMD\sentinel\wandb\settings
2025-07-31 17:36:13,434 INFO    MainThread:12572 [wandb_setup.py:_flush():80] Loading settings from environment variables
2025-07-31 17:36:13,434 INFO    MainThread:12572 [wandb_init.py:setup_run_log_directory():703] Logging user logs to C:\Users\AMD\sentinel\wandb\run-20250731_173613-6qvl3c70\logs\debug.log
2025-07-31 17:36:13,434 INFO    MainThread:12572 [wandb_init.py:setup_run_log_directory():704] Logging internal logs to C:\Users\AMD\sentinel\wandb\run-20250731_173613-6qvl3c70\logs\debug-internal.log
2025-07-31 17:36:13,434 INFO    MainThread:12572 [wandb_init.py:init():830] calling init triggers
2025-07-31 17:36:13,434 INFO    MainThread:12572 [wandb_init.py:init():835] wandb.init called with sweep_config: {}
config: {'system_version': 'v5.0', 'observability_enabled': True, 'weave_integration': True, '_wandb': {}}
2025-07-31 17:36:13,434 INFO    MainThread:12572 [wandb_init.py:init():871] starting backend
2025-07-31 17:36:13,662 INFO    MainThread:12572 [wandb_init.py:init():874] sending inform_init request
2025-07-31 17:36:13,673 INFO    MainThread:12572 [wandb_init.py:init():882] backend started and connected
2025-07-31 17:36:13,675 INFO    MainThread:12572 [wandb_init.py:init():953] updated telemetry
2025-07-31 17:36:13,713 INFO    MainThread:12572 [wandb_init.py:init():977] communicating run to backend with 90.0 second timeout
2025-07-31 17:36:14,082 INFO    MainThread:12572 [wandb_init.py:init():1029] starting run threads in backend
2025-07-31 17:36:14,432 INFO    MainThread:12572 [wandb_run.py:_console_start():2458] atexit reg
2025-07-31 17:36:14,432 INFO    MainThread:12572 [wandb_run.py:_redirect():2306] redirect: wrap_raw
2025-07-31 17:36:14,432 INFO    MainThread:12572 [wandb_run.py:_redirect():2375] Wrapping output streams.
2025-07-31 17:36:14,432 INFO    MainThread:12572 [wandb_run.py:_redirect():2398] Redirects installed.
2025-07-31 17:36:14,435 INFO    MainThread:12572 [wandb_init.py:init():1075] run started, returning control to user process
2025-07-31 17:37:46,642 INFO    MsgRouterThr:12572 [mailbox.py:close():129] [no run ID] Closing mailbox, abandoning 1 handles.
2025-07-31 17:37:47,758 ERROR   sentry-sdk.BackgroundWorker:12572 [redirect.py:_on_write():664] [all runs] error in stdout callback
Traceback (most recent call last):
  File "C:\Users\AMD\AppData\Local\Programs\Python\Python311\Lib\site-packages\wandb\sdk\lib\redirect.py", line 662, in _on_write
    cb(written_data)
  File "C:\Users\AMD\AppData\Local\Programs\Python\Python311\Lib\site-packages\wandb\sdk\wandb_run.py", line 2379, in <lambda>
    lambda data: self._console_raw_callback("stdout", data),
                 ^^^^^^^^^^^^^^^^^^^^^^^^^^^^^^^^^^^^^^^^^^
  File "C:\Users\AMD\AppData\Local\Programs\Python\Python311\Lib\site-packages\wandb\sdk\wandb_run.py", line 398, in wrapper
    return func(self, *args, **kwargs)
           ^^^^^^^^^^^^^^^^^^^^^^^^^^^
  File "C:\Users\AMD\AppData\Local\Programs\Python\Python311\Lib\site-packages\wandb\sdk\wandb_run.py", line 456, in wrapper_fn
    return func(self, *args, **kwargs)
           ^^^^^^^^^^^^^^^^^^^^^^^^^^^
  File "C:\Users\AMD\AppData\Local\Programs\Python\Python311\Lib\site-packages\wandb\sdk\wandb_run.py", line 1566, in _console_raw_callback
    self._backend.interface.publish_output_raw(name, data)
  File "C:\Users\AMD\AppData\Local\Programs\Python\Python311\Lib\site-packages\wandb\sdk\interface\interface.py", line 771, in publish_output_raw
    self._publish_output_raw(o)
  File "C:\Users\AMD\AppData\Local\Programs\Python\Python311\Lib\site-packages\wandb\sdk\interface\interface_shared.py", line 38, in _publish_output_raw
    self._publish(rec)
  File "C:\Users\AMD\AppData\Local\Programs\Python\Python311\Lib\site-packages\wandb\sdk\interface\interface_sock.py", line 39, in _publish
    self._sock_client.send_record_publish(record)
  File "C:\Users\AMD\AppData\Local\Programs\Python\Python311\Lib\site-packages\wandb\sdk\lib\sock_client.py", line 170, in send_record_publish
    self.send_server_request(server_req)
  File "C:\Users\AMD\AppData\Local\Programs\Python\Python311\Lib\site-packages\wandb\sdk\lib\sock_client.py", line 150, in send_server_request
    self._send_message(msg)
  File "C:\Users\AMD\AppData\Local\Programs\Python\Python311\Lib\site-packages\wandb\sdk\lib\sock_client.py", line 147, in _send_message
    self._sendall_with_error_handle(header + data)
  File "C:\Users\AMD\AppData\Local\Programs\Python\Python311\Lib\site-packages\wandb\sdk\lib\sock_client.py", line 126, in _sendall_with_error_handle
    sent = self._sock.send(data)
           ^^^^^^^^^^^^^^^^^^^^^
ConnectionAbortedError: [WinError 10053] An established connection was aborted by the software in your host machine
2025-07-31 17:37:47,858 ERROR   sentry-sdk.BackgroundWorker:12572 [redirect.py:_on_write():664] [all runs] error in stdout callback
Traceback (most recent call last):
  File "C:\Users\AMD\AppData\Local\Programs\Python\Python311\Lib\site-packages\wandb\sdk\lib\redirect.py", line 662, in _on_write
    cb(written_data)
  File "C:\Users\AMD\AppData\Local\Programs\Python\Python311\Lib\site-packages\wandb\sdk\wandb_run.py", line 2379, in <lambda>
    lambda data: self._console_raw_callback("stdout", data),
                 ^^^^^^^^^^^^^^^^^^^^^^^^^^^^^^^^^^^^^^^^^^
  File "C:\Users\AMD\AppData\Local\Programs\Python\Python311\Lib\site-packages\wandb\sdk\wandb_run.py", line 398, in wrapper
    return func(self, *args, **kwargs)
           ^^^^^^^^^^^^^^^^^^^^^^^^^^^
  File "C:\Users\AMD\AppData\Local\Programs\Python\Python311\Lib\site-packages\wandb\sdk\wandb_run.py", line 456, in wrapper_fn
    return func(self, *args, **kwargs)
           ^^^^^^^^^^^^^^^^^^^^^^^^^^^
  File "C:\Users\AMD\AppData\Local\Programs\Python\Python311\Lib\site-packages\wandb\sdk\wandb_run.py", line 1566, in _console_raw_callback
    self._backend.interface.publish_output_raw(name, data)
  File "C:\Users\AMD\AppData\Local\Programs\Python\Python311\Lib\site-packages\wandb\sdk\interface\interface.py", line 771, in publish_output_raw
    self._publish_output_raw(o)
  File "C:\Users\AMD\AppData\Local\Programs\Python\Python311\Lib\site-packages\wandb\sdk\interface\interface_shared.py", line 38, in _publish_output_raw
    self._publish(rec)
  File "C:\Users\AMD\AppData\Local\Programs\Python\Python311\Lib\site-packages\wandb\sdk\interface\interface_sock.py", line 39, in _publish
    self._sock_client.send_record_publish(record)
  File "C:\Users\AMD\AppData\Local\Programs\Python\Python311\Lib\site-packages\wandb\sdk\lib\sock_client.py", line 170, in send_record_publish
    self.send_server_request(server_req)
  File "C:\Users\AMD\AppData\Local\Programs\Python\Python311\Lib\site-packages\wandb\sdk\lib\sock_client.py", line 150, in send_server_request
    self._send_message(msg)
  File "C:\Users\AMD\AppData\Local\Programs\Python\Python311\Lib\site-packages\wandb\sdk\lib\sock_client.py", line 147, in _send_message
    self._sendall_with_error_handle(header + data)
  File "C:\Users\AMD\AppData\Local\Programs\Python\Python311\Lib\site-packages\wandb\sdk\lib\sock_client.py", line 126, in _sendall_with_error_handle
    sent = self._sock.send(data)
           ^^^^^^^^^^^^^^^^^^^^^
ConnectionAbortedError: [WinError 10053] An established connection was aborted by the software in your host machine
2025-07-31 17:37:47,961 ERROR   sentry-sdk.BackgroundWorker:12572 [redirect.py:_on_write():664] [all runs] error in stdout callback
Traceback (most recent call last):
  File "C:\Users\AMD\AppData\Local\Programs\Python\Python311\Lib\site-packages\wandb\sdk\lib\redirect.py", line 662, in _on_write
    cb(written_data)
  File "C:\Users\AMD\AppData\Local\Programs\Python\Python311\Lib\site-packages\wandb\sdk\wandb_run.py", line 2379, in <lambda>
    lambda data: self._console_raw_callback("stdout", data),
                 ^^^^^^^^^^^^^^^^^^^^^^^^^^^^^^^^^^^^^^^^^^
  File "C:\Users\AMD\AppData\Local\Programs\Python\Python311\Lib\site-packages\wandb\sdk\wandb_run.py", line 398, in wrapper
    return func(self, *args, **kwargs)
           ^^^^^^^^^^^^^^^^^^^^^^^^^^^
  File "C:\Users\AMD\AppData\Local\Programs\Python\Python311\Lib\site-packages\wandb\sdk\wandb_run.py", line 456, in wrapper_fn
    return func(self, *args, **kwargs)
           ^^^^^^^^^^^^^^^^^^^^^^^^^^^
  File "C:\Users\AMD\AppData\Local\Programs\Python\Python311\Lib\site-packages\wandb\sdk\wandb_run.py", line 1566, in _console_raw_callback
    self._backend.interface.publish_output_raw(name, data)
  File "C:\Users\AMD\AppData\Local\Programs\Python\Python311\Lib\site-packages\wandb\sdk\interface\interface.py", line 771, in publish_output_raw
    self._publish_output_raw(o)
  File "C:\Users\AMD\AppData\Local\Programs\Python\Python311\Lib\site-packages\wandb\sdk\interface\interface_shared.py", line 38, in _publish_output_raw
    self._publish(rec)
  File "C:\Users\AMD\AppData\Local\Programs\Python\Python311\Lib\site-packages\wandb\sdk\interface\interface_sock.py", line 39, in _publish
    self._sock_client.send_record_publish(record)
  File "C:\Users\AMD\AppData\Local\Programs\Python\Python311\Lib\site-packages\wandb\sdk\lib\sock_client.py", line 170, in send_record_publish
    self.send_server_request(server_req)
  File "C:\Users\AMD\AppData\Local\Programs\Python\Python311\Lib\site-packages\wandb\sdk\lib\sock_client.py", line 150, in send_server_request
    self._send_message(msg)
  File "C:\Users\AMD\AppData\Local\Programs\Python\Python311\Lib\site-packages\wandb\sdk\lib\sock_client.py", line 147, in _send_message
    self._sendall_with_error_handle(header + data)
  File "C:\Users\AMD\AppData\Local\Programs\Python\Python311\Lib\site-packages\wandb\sdk\lib\sock_client.py", line 126, in _sendall_with_error_handle
    sent = self._sock.send(data)
           ^^^^^^^^^^^^^^^^^^^^^
ConnectionAbortedError: [WinError 10053] An established connection was aborted by the software in your host machine
2025-07-31 17:37:48,052 ERROR   sentry-sdk.BackgroundWorker:12572 [redirect.py:_on_write():664] [all runs] error in stdout callback
Traceback (most recent call last):
  File "C:\Users\AMD\AppData\Local\Programs\Python\Python311\Lib\site-packages\wandb\sdk\lib\redirect.py", line 662, in _on_write
    cb(written_data)
  File "C:\Users\AMD\AppData\Local\Programs\Python\Python311\Lib\site-packages\wandb\sdk\wandb_run.py", line 2379, in <lambda>
    lambda data: self._console_raw_callback("stdout", data),
                 ^^^^^^^^^^^^^^^^^^^^^^^^^^^^^^^^^^^^^^^^^^
  File "C:\Users\AMD\AppData\Local\Programs\Python\Python311\Lib\site-packages\wandb\sdk\wandb_run.py", line 398, in wrapper
    return func(self, *args, **kwargs)
           ^^^^^^^^^^^^^^^^^^^^^^^^^^^
  File "C:\Users\AMD\AppData\Local\Programs\Python\Python311\Lib\site-packages\wandb\sdk\wandb_run.py", line 456, in wrapper_fn
    return func(self, *args, **kwargs)
           ^^^^^^^^^^^^^^^^^^^^^^^^^^^
  File "C:\Users\AMD\AppData\Local\Programs\Python\Python311\Lib\site-packages\wandb\sdk\wandb_run.py", line 1566, in _console_raw_callback
    self._backend.interface.publish_output_raw(name, data)
  File "C:\Users\AMD\AppData\Local\Programs\Python\Python311\Lib\site-packages\wandb\sdk\interface\interface.py", line 771, in publish_output_raw
    self._publish_output_raw(o)
  File "C:\Users\AMD\AppData\Local\Programs\Python\Python311\Lib\site-packages\wandb\sdk\interface\interface_shared.py", line 38, in _publish_output_raw
    self._publish(rec)
  File "C:\Users\AMD\AppData\Local\Programs\Python\Python311\Lib\site-packages\wandb\sdk\interface\interface_sock.py", line 39, in _publish
    self._sock_client.send_record_publish(record)
  File "C:\Users\AMD\AppData\Local\Programs\Python\Python311\Lib\site-packages\wandb\sdk\lib\sock_client.py", line 170, in send_record_publish
    self.send_server_request(server_req)
  File "C:\Users\AMD\AppData\Local\Programs\Python\Python311\Lib\site-packages\wandb\sdk\lib\sock_client.py", line 150, in send_server_request
    self._send_message(msg)
  File "C:\Users\AMD\AppData\Local\Programs\Python\Python311\Lib\site-packages\wandb\sdk\lib\sock_client.py", line 147, in _send_message
    self._sendall_with_error_handle(header + data)
  File "C:\Users\AMD\AppData\Local\Programs\Python\Python311\Lib\site-packages\wandb\sdk\lib\sock_client.py", line 126, in _sendall_with_error_handle
    sent = self._sock.send(data)
           ^^^^^^^^^^^^^^^^^^^^^
ConnectionAbortedError: [WinError 10053] An established connection was aborted by the software in your host machine
2025-07-31 17:37:48,394 ERROR   sentry-sdk.BackgroundWorker:12572 [redirect.py:_on_write():664] [all runs] error in stdout callback
Traceback (most recent call last):
  File "C:\Users\AMD\AppData\Local\Programs\Python\Python311\Lib\site-packages\wandb\sdk\lib\redirect.py", line 662, in _on_write
    cb(written_data)
  File "C:\Users\AMD\AppData\Local\Programs\Python\Python311\Lib\site-packages\wandb\sdk\wandb_run.py", line 2379, in <lambda>
    lambda data: self._console_raw_callback("stdout", data),
                 ^^^^^^^^^^^^^^^^^^^^^^^^^^^^^^^^^^^^^^^^^^
  File "C:\Users\AMD\AppData\Local\Programs\Python\Python311\Lib\site-packages\wandb\sdk\wandb_run.py", line 398, in wrapper
    return func(self, *args, **kwargs)
           ^^^^^^^^^^^^^^^^^^^^^^^^^^^
  File "C:\Users\AMD\AppData\Local\Programs\Python\Python311\Lib\site-packages\wandb\sdk\wandb_run.py", line 456, in wrapper_fn
    return func(self, *args, **kwargs)
           ^^^^^^^^^^^^^^^^^^^^^^^^^^^
  File "C:\Users\AMD\AppData\Local\Programs\Python\Python311\Lib\site-packages\wandb\sdk\wandb_run.py", line 1566, in _console_raw_callback
    self._backend.interface.publish_output_raw(name, data)
  File "C:\Users\AMD\AppData\Local\Programs\Python\Python311\Lib\site-packages\wandb\sdk\interface\interface.py", line 771, in publish_output_raw
    self._publish_output_raw(o)
  File "C:\Users\AMD\AppData\Local\Programs\Python\Python311\Lib\site-packages\wandb\sdk\interface\interface_shared.py", line 38, in _publish_output_raw
    self._publish(rec)
  File "C:\Users\AMD\AppData\Local\Programs\Python\Python311\Lib\site-packages\wandb\sdk\interface\interface_sock.py", line 39, in _publish
    self._sock_client.send_record_publish(record)
  File "C:\Users\AMD\AppData\Local\Programs\Python\Python311\Lib\site-packages\wandb\sdk\lib\sock_client.py", line 170, in send_record_publish
    self.send_server_request(server_req)
  File "C:\Users\AMD\AppData\Local\Programs\Python\Python311\Lib\site-packages\wandb\sdk\lib\sock_client.py", line 150, in send_server_request
    self._send_message(msg)
  File "C:\Users\AMD\AppData\Local\Programs\Python\Python311\Lib\site-packages\wandb\sdk\lib\sock_client.py", line 147, in _send_message
    self._sendall_with_error_handle(header + data)
  File "C:\Users\AMD\AppData\Local\Programs\Python\Python311\Lib\site-packages\wandb\sdk\lib\sock_client.py", line 126, in _sendall_with_error_handle
    sent = self._sock.send(data)
           ^^^^^^^^^^^^^^^^^^^^^
ConnectionAbortedError: [WinError 10053] An established connection was aborted by the software in your host machine
2025-07-31 17:37:48,486 ERROR   sentry-sdk.BackgroundWorker:12572 [redirect.py:_on_write():664] [all runs] error in stdout callback
Traceback (most recent call last):
  File "C:\Users\AMD\AppData\Local\Programs\Python\Python311\Lib\site-packages\wandb\sdk\lib\redirect.py", line 662, in _on_write
    cb(written_data)
  File "C:\Users\AMD\AppData\Local\Programs\Python\Python311\Lib\site-packages\wandb\sdk\wandb_run.py", line 2379, in <lambda>
    lambda data: self._console_raw_callback("stdout", data),
                 ^^^^^^^^^^^^^^^^^^^^^^^^^^^^^^^^^^^^^^^^^^
  File "C:\Users\AMD\AppData\Local\Programs\Python\Python311\Lib\site-packages\wandb\sdk\wandb_run.py", line 398, in wrapper
    return func(self, *args, **kwargs)
           ^^^^^^^^^^^^^^^^^^^^^^^^^^^
  File "C:\Users\AMD\AppData\Local\Programs\Python\Python311\Lib\site-packages\wandb\sdk\wandb_run.py", line 456, in wrapper_fn
    return func(self, *args, **kwargs)
           ^^^^^^^^^^^^^^^^^^^^^^^^^^^
  File "C:\Users\AMD\AppData\Local\Programs\Python\Python311\Lib\site-packages\wandb\sdk\wandb_run.py", line 1566, in _console_raw_callback
    self._backend.interface.publish_output_raw(name, data)
  File "C:\Users\AMD\AppData\Local\Programs\Python\Python311\Lib\site-packages\wandb\sdk\interface\interface.py", line 771, in publish_output_raw
    self._publish_output_raw(o)
  File "C:\Users\AMD\AppData\Local\Programs\Python\Python311\Lib\site-packages\wandb\sdk\interface\interface_shared.py", line 38, in _publish_output_raw
    self._publish(rec)
  File "C:\Users\AMD\AppData\Local\Programs\Python\Python311\Lib\site-packages\wandb\sdk\interface\interface_sock.py", line 39, in _publish
    self._sock_client.send_record_publish(record)
  File "C:\Users\AMD\AppData\Local\Programs\Python\Python311\Lib\site-packages\wandb\sdk\lib\sock_client.py", line 170, in send_record_publish
    self.send_server_request(server_req)
  File "C:\Users\AMD\AppData\Local\Programs\Python\Python311\Lib\site-packages\wandb\sdk\lib\sock_client.py", line 150, in send_server_request
    self._send_message(msg)
  File "C:\Users\AMD\AppData\Local\Programs\Python\Python311\Lib\site-packages\wandb\sdk\lib\sock_client.py", line 147, in _send_message
    self._sendall_with_error_handle(header + data)
  File "C:\Users\AMD\AppData\Local\Programs\Python\Python311\Lib\site-packages\wandb\sdk\lib\sock_client.py", line 126, in _sendall_with_error_handle
    sent = self._sock.send(data)
           ^^^^^^^^^^^^^^^^^^^^^
ConnectionAbortedError: [WinError 10053] An established connection was aborted by the software in your host machine
2025-07-31 17:37:48,589 ERROR   sentry-sdk.BackgroundWorker:12572 [redirect.py:_on_write():664] [all runs] error in stdout callback
Traceback (most recent call last):
  File "C:\Users\AMD\AppData\Local\Programs\Python\Python311\Lib\site-packages\wandb\sdk\lib\redirect.py", line 662, in _on_write
    cb(written_data)
  File "C:\Users\AMD\AppData\Local\Programs\Python\Python311\Lib\site-packages\wandb\sdk\wandb_run.py", line 2379, in <lambda>
    lambda data: self._console_raw_callback("stdout", data),
                 ^^^^^^^^^^^^^^^^^^^^^^^^^^^^^^^^^^^^^^^^^^
  File "C:\Users\AMD\AppData\Local\Programs\Python\Python311\Lib\site-packages\wandb\sdk\wandb_run.py", line 398, in wrapper
    return func(self, *args, **kwargs)
           ^^^^^^^^^^^^^^^^^^^^^^^^^^^
  File "C:\Users\AMD\AppData\Local\Programs\Python\Python311\Lib\site-packages\wandb\sdk\wandb_run.py", line 456, in wrapper_fn
    return func(self, *args, **kwargs)
           ^^^^^^^^^^^^^^^^^^^^^^^^^^^
  File "C:\Users\AMD\AppData\Local\Programs\Python\Python311\Lib\site-packages\wandb\sdk\wandb_run.py", line 1566, in _console_raw_callback
    self._backend.interface.publish_output_raw(name, data)
  File "C:\Users\AMD\AppData\Local\Programs\Python\Python311\Lib\site-packages\wandb\sdk\interface\interface.py", line 771, in publish_output_raw
    self._publish_output_raw(o)
  File "C:\Users\AMD\AppData\Local\Programs\Python\Python311\Lib\site-packages\wandb\sdk\interface\interface_shared.py", line 38, in _publish_output_raw
    self._publish(rec)
  File "C:\Users\AMD\AppData\Local\Programs\Python\Python311\Lib\site-packages\wandb\sdk\interface\interface_sock.py", line 39, in _publish
    self._sock_client.send_record_publish(record)
  File "C:\Users\AMD\AppData\Local\Programs\Python\Python311\Lib\site-packages\wandb\sdk\lib\sock_client.py", line 170, in send_record_publish
    self.send_server_request(server_req)
  File "C:\Users\AMD\AppData\Local\Programs\Python\Python311\Lib\site-packages\wandb\sdk\lib\sock_client.py", line 150, in send_server_request
    self._send_message(msg)
  File "C:\Users\AMD\AppData\Local\Programs\Python\Python311\Lib\site-packages\wandb\sdk\lib\sock_client.py", line 147, in _send_message
    self._sendall_with_error_handle(header + data)
  File "C:\Users\AMD\AppData\Local\Programs\Python\Python311\Lib\site-packages\wandb\sdk\lib\sock_client.py", line 126, in _sendall_with_error_handle
    sent = self._sock.send(data)
           ^^^^^^^^^^^^^^^^^^^^^
ConnectionAbortedError: [WinError 10053] An established connection was aborted by the software in your host machine
2025-07-31 17:37:48,679 ERROR   sentry-sdk.BackgroundWorker:12572 [redirect.py:_on_write():664] [all runs] error in stdout callback
Traceback (most recent call last):
  File "C:\Users\AMD\AppData\Local\Programs\Python\Python311\Lib\site-packages\wandb\sdk\lib\redirect.py", line 662, in _on_write
    cb(written_data)
  File "C:\Users\AMD\AppData\Local\Programs\Python\Python311\Lib\site-packages\wandb\sdk\wandb_run.py", line 2379, in <lambda>
    lambda data: self._console_raw_callback("stdout", data),
                 ^^^^^^^^^^^^^^^^^^^^^^^^^^^^^^^^^^^^^^^^^^
  File "C:\Users\AMD\AppData\Local\Programs\Python\Python311\Lib\site-packages\wandb\sdk\wandb_run.py", line 398, in wrapper
    return func(self, *args, **kwargs)
           ^^^^^^^^^^^^^^^^^^^^^^^^^^^
  File "C:\Users\AMD\AppData\Local\Programs\Python\Python311\Lib\site-packages\wandb\sdk\wandb_run.py", line 456, in wrapper_fn
    return func(self, *args, **kwargs)
           ^^^^^^^^^^^^^^^^^^^^^^^^^^^
  File "C:\Users\AMD\AppData\Local\Programs\Python\Python311\Lib\site-packages\wandb\sdk\wandb_run.py", line 1566, in _console_raw_callback
    self._backend.interface.publish_output_raw(name, data)
  File "C:\Users\AMD\AppData\Local\Programs\Python\Python311\Lib\site-packages\wandb\sdk\interface\interface.py", line 771, in publish_output_raw
    self._publish_output_raw(o)
  File "C:\Users\AMD\AppData\Local\Programs\Python\Python311\Lib\site-packages\wandb\sdk\interface\interface_shared.py", line 38, in _publish_output_raw
    self._publish(rec)
  File "C:\Users\AMD\AppData\Local\Programs\Python\Python311\Lib\site-packages\wandb\sdk\interface\interface_sock.py", line 39, in _publish
    self._sock_client.send_record_publish(record)
  File "C:\Users\AMD\AppData\Local\Programs\Python\Python311\Lib\site-packages\wandb\sdk\lib\sock_client.py", line 170, in send_record_publish
    self.send_server_request(server_req)
  File "C:\Users\AMD\AppData\Local\Programs\Python\Python311\Lib\site-packages\wandb\sdk\lib\sock_client.py", line 150, in send_server_request
    self._send_message(msg)
  File "C:\Users\AMD\AppData\Local\Programs\Python\Python311\Lib\site-packages\wandb\sdk\lib\sock_client.py", line 147, in _send_message
    self._sendall_with_error_handle(header + data)
  File "C:\Users\AMD\AppData\Local\Programs\Python\Python311\Lib\site-packages\wandb\sdk\lib\sock_client.py", line 126, in _sendall_with_error_handle
    sent = self._sock.send(data)
           ^^^^^^^^^^^^^^^^^^^^^
ConnectionAbortedError: [WinError 10053] An established connection was aborted by the software in your host machine
2025-07-31 17:37:48,776 ERROR   sentry-sdk.BackgroundWorker:12572 [redirect.py:_on_write():664] [all runs] error in stdout callback
Traceback (most recent call last):
  File "C:\Users\AMD\AppData\Local\Programs\Python\Python311\Lib\site-packages\wandb\sdk\lib\redirect.py", line 662, in _on_write
    cb(written_data)
  File "C:\Users\AMD\AppData\Local\Programs\Python\Python311\Lib\site-packages\wandb\sdk\wandb_run.py", line 2379, in <lambda>
    lambda data: self._console_raw_callback("stdout", data),
                 ^^^^^^^^^^^^^^^^^^^^^^^^^^^^^^^^^^^^^^^^^^
  File "C:\Users\AMD\AppData\Local\Programs\Python\Python311\Lib\site-packages\wandb\sdk\wandb_run.py", line 398, in wrapper
    return func(self, *args, **kwargs)
           ^^^^^^^^^^^^^^^^^^^^^^^^^^^
  File "C:\Users\AMD\AppData\Local\Programs\Python\Python311\Lib\site-packages\wandb\sdk\wandb_run.py", line 456, in wrapper_fn
    return func(self, *args, **kwargs)
           ^^^^^^^^^^^^^^^^^^^^^^^^^^^
  File "C:\Users\AMD\AppData\Local\Programs\Python\Python311\Lib\site-packages\wandb\sdk\wandb_run.py", line 1566, in _console_raw_callback
    self._backend.interface.publish_output_raw(name, data)
  File "C:\Users\AMD\AppData\Local\Programs\Python\Python311\Lib\site-packages\wandb\sdk\interface\interface.py", line 771, in publish_output_raw
    self._publish_output_raw(o)
  File "C:\Users\AMD\AppData\Local\Programs\Python\Python311\Lib\site-packages\wandb\sdk\interface\interface_shared.py", line 38, in _publish_output_raw
    self._publish(rec)
  File "C:\Users\AMD\AppData\Local\Programs\Python\Python311\Lib\site-packages\wandb\sdk\interface\interface_sock.py", line 39, in _publish
    self._sock_client.send_record_publish(record)
  File "C:\Users\AMD\AppData\Local\Programs\Python\Python311\Lib\site-packages\wandb\sdk\lib\sock_client.py", line 170, in send_record_publish
    self.send_server_request(server_req)
  File "C:\Users\AMD\AppData\Local\Programs\Python\Python311\Lib\site-packages\wandb\sdk\lib\sock_client.py", line 150, in send_server_request
    self._send_message(msg)
  File "C:\Users\AMD\AppData\Local\Programs\Python\Python311\Lib\site-packages\wandb\sdk\lib\sock_client.py", line 147, in _send_message
    self._sendall_with_error_handle(header + data)
  File "C:\Users\AMD\AppData\Local\Programs\Python\Python311\Lib\site-packages\wandb\sdk\lib\sock_client.py", line 126, in _sendall_with_error_handle
    sent = self._sock.send(data)
           ^^^^^^^^^^^^^^^^^^^^^
ConnectionAbortedError: [WinError 10053] An established connection was aborted by the software in your host machine
2025-07-31 17:37:48,866 ERROR   sentry-sdk.BackgroundWorker:12572 [redirect.py:_on_write():664] [all runs] error in stdout callback
Traceback (most recent call last):
  File "C:\Users\AMD\AppData\Local\Programs\Python\Python311\Lib\site-packages\wandb\sdk\lib\redirect.py", line 662, in _on_write
    cb(written_data)
  File "C:\Users\AMD\AppData\Local\Programs\Python\Python311\Lib\site-packages\wandb\sdk\wandb_run.py", line 2379, in <lambda>
    lambda data: self._console_raw_callback("stdout", data),
                 ^^^^^^^^^^^^^^^^^^^^^^^^^^^^^^^^^^^^^^^^^^
  File "C:\Users\AMD\AppData\Local\Programs\Python\Python311\Lib\site-packages\wandb\sdk\wandb_run.py", line 398, in wrapper
    return func(self, *args, **kwargs)
           ^^^^^^^^^^^^^^^^^^^^^^^^^^^
  File "C:\Users\AMD\AppData\Local\Programs\Python\Python311\Lib\site-packages\wandb\sdk\wandb_run.py", line 456, in wrapper_fn
    return func(self, *args, **kwargs)
           ^^^^^^^^^^^^^^^^^^^^^^^^^^^
  File "C:\Users\AMD\AppData\Local\Programs\Python\Python311\Lib\site-packages\wandb\sdk\wandb_run.py", line 1566, in _console_raw_callback
    self._backend.interface.publish_output_raw(name, data)
  File "C:\Users\AMD\AppData\Local\Programs\Python\Python311\Lib\site-packages\wandb\sdk\interface\interface.py", line 771, in publish_output_raw
    self._publish_output_raw(o)
  File "C:\Users\AMD\AppData\Local\Programs\Python\Python311\Lib\site-packages\wandb\sdk\interface\interface_shared.py", line 38, in _publish_output_raw
    self._publish(rec)
  File "C:\Users\AMD\AppData\Local\Programs\Python\Python311\Lib\site-packages\wandb\sdk\interface\interface_sock.py", line 39, in _publish
    self._sock_client.send_record_publish(record)
  File "C:\Users\AMD\AppData\Local\Programs\Python\Python311\Lib\site-packages\wandb\sdk\lib\sock_client.py", line 170, in send_record_publish
    self.send_server_request(server_req)
  File "C:\Users\AMD\AppData\Local\Programs\Python\Python311\Lib\site-packages\wandb\sdk\lib\sock_client.py", line 150, in send_server_request
    self._send_message(msg)
  File "C:\Users\AMD\AppData\Local\Programs\Python\Python311\Lib\site-packages\wandb\sdk\lib\sock_client.py", line 147, in _send_message
    self._sendall_with_error_handle(header + data)
  File "C:\Users\AMD\AppData\Local\Programs\Python\Python311\Lib\site-packages\wandb\sdk\lib\sock_client.py", line 126, in _sendall_with_error_handle
    sent = self._sock.send(data)
           ^^^^^^^^^^^^^^^^^^^^^
ConnectionAbortedError: [WinError 10053] An established connection was aborted by the software in your host machine
2025-07-31 17:37:48,953 ERROR   sentry-sdk.BackgroundWorker:12572 [redirect.py:_on_write():664] [all runs] error in stdout callback
Traceback (most recent call last):
  File "C:\Users\AMD\AppData\Local\Programs\Python\Python311\Lib\site-packages\wandb\sdk\lib\redirect.py", line 662, in _on_write
    cb(written_data)
  File "C:\Users\AMD\AppData\Local\Programs\Python\Python311\Lib\site-packages\wandb\sdk\wandb_run.py", line 2379, in <lambda>
    lambda data: self._console_raw_callback("stdout", data),
                 ^^^^^^^^^^^^^^^^^^^^^^^^^^^^^^^^^^^^^^^^^^
  File "C:\Users\AMD\AppData\Local\Programs\Python\Python311\Lib\site-packages\wandb\sdk\wandb_run.py", line 398, in wrapper
    return func(self, *args, **kwargs)
           ^^^^^^^^^^^^^^^^^^^^^^^^^^^
  File "C:\Users\AMD\AppData\Local\Programs\Python\Python311\Lib\site-packages\wandb\sdk\wandb_run.py", line 456, in wrapper_fn
    return func(self, *args, **kwargs)
           ^^^^^^^^^^^^^^^^^^^^^^^^^^^
  File "C:\Users\AMD\AppData\Local\Programs\Python\Python311\Lib\site-packages\wandb\sdk\wandb_run.py", line 1566, in _console_raw_callback
    self._backend.interface.publish_output_raw(name, data)
  File "C:\Users\AMD\AppData\Local\Programs\Python\Python311\Lib\site-packages\wandb\sdk\interface\interface.py", line 771, in publish_output_raw
    self._publish_output_raw(o)
  File "C:\Users\AMD\AppData\Local\Programs\Python\Python311\Lib\site-packages\wandb\sdk\interface\interface_shared.py", line 38, in _publish_output_raw
    self._publish(rec)
  File "C:\Users\AMD\AppData\Local\Programs\Python\Python311\Lib\site-packages\wandb\sdk\interface\interface_sock.py", line 39, in _publish
    self._sock_client.send_record_publish(record)
  File "C:\Users\AMD\AppData\Local\Programs\Python\Python311\Lib\site-packages\wandb\sdk\lib\sock_client.py", line 170, in send_record_publish
    self.send_server_request(server_req)
  File "C:\Users\AMD\AppData\Local\Programs\Python\Python311\Lib\site-packages\wandb\sdk\lib\sock_client.py", line 150, in send_server_request
    self._send_message(msg)
  File "C:\Users\AMD\AppData\Local\Programs\Python\Python311\Lib\site-packages\wandb\sdk\lib\sock_client.py", line 147, in _send_message
    self._sendall_with_error_handle(header + data)
  File "C:\Users\AMD\AppData\Local\Programs\Python\Python311\Lib\site-packages\wandb\sdk\lib\sock_client.py", line 126, in _sendall_with_error_handle
    sent = self._sock.send(data)
           ^^^^^^^^^^^^^^^^^^^^^
ConnectionAbortedError: [WinError 10053] An established connection was aborted by the software in your host machine
2025-07-31 17:37:49,044 ERROR   sentry-sdk.BackgroundWorker:12572 [redirect.py:_on_write():664] [all runs] error in stdout callback
Traceback (most recent call last):
  File "C:\Users\AMD\AppData\Local\Programs\Python\Python311\Lib\site-packages\wandb\sdk\lib\redirect.py", line 662, in _on_write
    cb(written_data)
  File "C:\Users\AMD\AppData\Local\Programs\Python\Python311\Lib\site-packages\wandb\sdk\wandb_run.py", line 2379, in <lambda>
    lambda data: self._console_raw_callback("stdout", data),
                 ^^^^^^^^^^^^^^^^^^^^^^^^^^^^^^^^^^^^^^^^^^
  File "C:\Users\AMD\AppData\Local\Programs\Python\Python311\Lib\site-packages\wandb\sdk\wandb_run.py", line 398, in wrapper
    return func(self, *args, **kwargs)
           ^^^^^^^^^^^^^^^^^^^^^^^^^^^
  File "C:\Users\AMD\AppData\Local\Programs\Python\Python311\Lib\site-packages\wandb\sdk\wandb_run.py", line 456, in wrapper_fn
    return func(self, *args, **kwargs)
           ^^^^^^^^^^^^^^^^^^^^^^^^^^^
  File "C:\Users\AMD\AppData\Local\Programs\Python\Python311\Lib\site-packages\wandb\sdk\wandb_run.py", line 1566, in _console_raw_callback
    self._backend.interface.publish_output_raw(name, data)
  File "C:\Users\AMD\AppData\Local\Programs\Python\Python311\Lib\site-packages\wandb\sdk\interface\interface.py", line 771, in publish_output_raw
    self._publish_output_raw(o)
  File "C:\Users\AMD\AppData\Local\Programs\Python\Python311\Lib\site-packages\wandb\sdk\interface\interface_shared.py", line 38, in _publish_output_raw
    self._publish(rec)
  File "C:\Users\AMD\AppData\Local\Programs\Python\Python311\Lib\site-packages\wandb\sdk\interface\interface_sock.py", line 39, in _publish
    self._sock_client.send_record_publish(record)
  File "C:\Users\AMD\AppData\Local\Programs\Python\Python311\Lib\site-packages\wandb\sdk\lib\sock_client.py", line 170, in send_record_publish
    self.send_server_request(server_req)
  File "C:\Users\AMD\AppData\Local\Programs\Python\Python311\Lib\site-packages\wandb\sdk\lib\sock_client.py", line 150, in send_server_request
    self._send_message(msg)
  File "C:\Users\AMD\AppData\Local\Programs\Python\Python311\Lib\site-packages\wandb\sdk\lib\sock_client.py", line 147, in _send_message
    self._sendall_with_error_handle(header + data)
  File "C:\Users\AMD\AppData\Local\Programs\Python\Python311\Lib\site-packages\wandb\sdk\lib\sock_client.py", line 126, in _sendall_with_error_handle
    sent = self._sock.send(data)
           ^^^^^^^^^^^^^^^^^^^^^
ConnectionAbortedError: [WinError 10053] An established connection was aborted by the software in your host machine
2025-07-31 17:37:49,142 ERROR   sentry-sdk.BackgroundWorker:12572 [redirect.py:_on_write():664] [all runs] error in stdout callback
Traceback (most recent call last):
  File "C:\Users\AMD\AppData\Local\Programs\Python\Python311\Lib\site-packages\wandb\sdk\lib\redirect.py", line 662, in _on_write
    cb(written_data)
  File "C:\Users\AMD\AppData\Local\Programs\Python\Python311\Lib\site-packages\wandb\sdk\wandb_run.py", line 2379, in <lambda>
    lambda data: self._console_raw_callback("stdout", data),
                 ^^^^^^^^^^^^^^^^^^^^^^^^^^^^^^^^^^^^^^^^^^
  File "C:\Users\AMD\AppData\Local\Programs\Python\Python311\Lib\site-packages\wandb\sdk\wandb_run.py", line 398, in wrapper
    return func(self, *args, **kwargs)
           ^^^^^^^^^^^^^^^^^^^^^^^^^^^
  File "C:\Users\AMD\AppData\Local\Programs\Python\Python311\Lib\site-packages\wandb\sdk\wandb_run.py", line 456, in wrapper_fn
    return func(self, *args, **kwargs)
           ^^^^^^^^^^^^^^^^^^^^^^^^^^^
  File "C:\Users\AMD\AppData\Local\Programs\Python\Python311\Lib\site-packages\wandb\sdk\wandb_run.py", line 1566, in _console_raw_callback
    self._backend.interface.publish_output_raw(name, data)
  File "C:\Users\AMD\AppData\Local\Programs\Python\Python311\Lib\site-packages\wandb\sdk\interface\interface.py", line 771, in publish_output_raw
    self._publish_output_raw(o)
  File "C:\Users\AMD\AppData\Local\Programs\Python\Python311\Lib\site-packages\wandb\sdk\interface\interface_shared.py", line 38, in _publish_output_raw
    self._publish(rec)
  File "C:\Users\AMD\AppData\Local\Programs\Python\Python311\Lib\site-packages\wandb\sdk\interface\interface_sock.py", line 39, in _publish
    self._sock_client.send_record_publish(record)
  File "C:\Users\AMD\AppData\Local\Programs\Python\Python311\Lib\site-packages\wandb\sdk\lib\sock_client.py", line 170, in send_record_publish
    self.send_server_request(server_req)
  File "C:\Users\AMD\AppData\Local\Programs\Python\Python311\Lib\site-packages\wandb\sdk\lib\sock_client.py", line 150, in send_server_request
    self._send_message(msg)
  File "C:\Users\AMD\AppData\Local\Programs\Python\Python311\Lib\site-packages\wandb\sdk\lib\sock_client.py", line 147, in _send_message
    self._sendall_with_error_handle(header + data)
  File "C:\Users\AMD\AppData\Local\Programs\Python\Python311\Lib\site-packages\wandb\sdk\lib\sock_client.py", line 126, in _sendall_with_error_handle
    sent = self._sock.send(data)
           ^^^^^^^^^^^^^^^^^^^^^
ConnectionAbortedError: [WinError 10053] An established connection was aborted by the software in your host machine
2025-07-31 17:37:49,240 ERROR   sentry-sdk.BackgroundWorker:12572 [redirect.py:_on_write():664] [all runs] error in stdout callback
Traceback (most recent call last):
  File "C:\Users\AMD\AppData\Local\Programs\Python\Python311\Lib\site-packages\wandb\sdk\lib\redirect.py", line 662, in _on_write
    cb(written_data)
  File "C:\Users\AMD\AppData\Local\Programs\Python\Python311\Lib\site-packages\wandb\sdk\wandb_run.py", line 2379, in <lambda>
    lambda data: self._console_raw_callback("stdout", data),
                 ^^^^^^^^^^^^^^^^^^^^^^^^^^^^^^^^^^^^^^^^^^
  File "C:\Users\AMD\AppData\Local\Programs\Python\Python311\Lib\site-packages\wandb\sdk\wandb_run.py", line 398, in wrapper
    return func(self, *args, **kwargs)
           ^^^^^^^^^^^^^^^^^^^^^^^^^^^
  File "C:\Users\AMD\AppData\Local\Programs\Python\Python311\Lib\site-packages\wandb\sdk\wandb_run.py", line 456, in wrapper_fn
    return func(self, *args, **kwargs)
           ^^^^^^^^^^^^^^^^^^^^^^^^^^^
  File "C:\Users\AMD\AppData\Local\Programs\Python\Python311\Lib\site-packages\wandb\sdk\wandb_run.py", line 1566, in _console_raw_callback
    self._backend.interface.publish_output_raw(name, data)
  File "C:\Users\AMD\AppData\Local\Programs\Python\Python311\Lib\site-packages\wandb\sdk\interface\interface.py", line 771, in publish_output_raw
    self._publish_output_raw(o)
  File "C:\Users\AMD\AppData\Local\Programs\Python\Python311\Lib\site-packages\wandb\sdk\interface\interface_shared.py", line 38, in _publish_output_raw
    self._publish(rec)
  File "C:\Users\AMD\AppData\Local\Programs\Python\Python311\Lib\site-packages\wandb\sdk\interface\interface_sock.py", line 39, in _publish
    self._sock_client.send_record_publish(record)
  File "C:\Users\AMD\AppData\Local\Programs\Python\Python311\Lib\site-packages\wandb\sdk\lib\sock_client.py", line 170, in send_record_publish
    self.send_server_request(server_req)
  File "C:\Users\AMD\AppData\Local\Programs\Python\Python311\Lib\site-packages\wandb\sdk\lib\sock_client.py", line 150, in send_server_request
    self._send_message(msg)
  File "C:\Users\AMD\AppData\Local\Programs\Python\Python311\Lib\site-packages\wandb\sdk\lib\sock_client.py", line 147, in _send_message
    self._sendall_with_error_handle(header + data)
  File "C:\Users\AMD\AppData\Local\Programs\Python\Python311\Lib\site-packages\wandb\sdk\lib\sock_client.py", line 126, in _sendall_with_error_handle
    sent = self._sock.send(data)
           ^^^^^^^^^^^^^^^^^^^^^
ConnectionAbortedError: [WinError 10053] An established connection was aborted by the software in your host machine
2025-07-31 17:37:49,317 ERROR   MainThread:12572 [redirect.py:_on_write():664] [all runs] error in stderr callback
Traceback (most recent call last):
  File "C:\Users\AMD\AppData\Local\Programs\Python\Python311\Lib\site-packages\wandb\sdk\lib\redirect.py", line 662, in _on_write
    cb(written_data)
  File "C:\Users\AMD\AppData\Local\Programs\Python\Python311\Lib\site-packages\wandb\sdk\wandb_run.py", line 2385, in <lambda>
    lambda data: self._console_raw_callback("stderr", data),
                 ^^^^^^^^^^^^^^^^^^^^^^^^^^^^^^^^^^^^^^^^^^
  File "C:\Users\AMD\AppData\Local\Programs\Python\Python311\Lib\site-packages\wandb\sdk\wandb_run.py", line 398, in wrapper
    return func(self, *args, **kwargs)
           ^^^^^^^^^^^^^^^^^^^^^^^^^^^
  File "C:\Users\AMD\AppData\Local\Programs\Python\Python311\Lib\site-packages\wandb\sdk\wandb_run.py", line 456, in wrapper_fn
    return func(self, *args, **kwargs)
           ^^^^^^^^^^^^^^^^^^^^^^^^^^^
  File "C:\Users\AMD\AppData\Local\Programs\Python\Python311\Lib\site-packages\wandb\sdk\wandb_run.py", line 1566, in _console_raw_callback
    self._backend.interface.publish_output_raw(name, data)
  File "C:\Users\AMD\AppData\Local\Programs\Python\Python311\Lib\site-packages\wandb\sdk\interface\interface.py", line 771, in publish_output_raw
    self._publish_output_raw(o)
  File "C:\Users\AMD\AppData\Local\Programs\Python\Python311\Lib\site-packages\wandb\sdk\interface\interface_shared.py", line 38, in _publish_output_raw
    self._publish(rec)
  File "C:\Users\AMD\AppData\Local\Programs\Python\Python311\Lib\site-packages\wandb\sdk\interface\interface_sock.py", line 39, in _publish
    self._sock_client.send_record_publish(record)
  File "C:\Users\AMD\AppData\Local\Programs\Python\Python311\Lib\site-packages\wandb\sdk\lib\sock_client.py", line 170, in send_record_publish
    self.send_server_request(server_req)
  File "C:\Users\AMD\AppData\Local\Programs\Python\Python311\Lib\site-packages\wandb\sdk\lib\sock_client.py", line 150, in send_server_request
    self._send_message(msg)
  File "C:\Users\AMD\AppData\Local\Programs\Python\Python311\Lib\site-packages\wandb\sdk\lib\sock_client.py", line 147, in _send_message
    self._sendall_with_error_handle(header + data)
  File "C:\Users\AMD\AppData\Local\Programs\Python\Python311\Lib\site-packages\wandb\sdk\lib\sock_client.py", line 126, in _sendall_with_error_handle
    sent = self._sock.send(data)
           ^^^^^^^^^^^^^^^^^^^^^
ConnectionAbortedError: [WinError 10053] An established connection was aborted by the software in your host machine
2025-07-31 17:37:49,335 ERROR   MainThread:12572 [redirect.py:_on_write():664] [all runs] error in stderr callback
Traceback (most recent call last):
  File "C:\Users\AMD\AppData\Local\Programs\Python\Python311\Lib\site-packages\wandb\sdk\lib\redirect.py", line 662, in _on_write
    cb(written_data)
  File "C:\Users\AMD\AppData\Local\Programs\Python\Python311\Lib\site-packages\wandb\sdk\wandb_run.py", line 2385, in <lambda>
    lambda data: self._console_raw_callback("stderr", data),
                 ^^^^^^^^^^^^^^^^^^^^^^^^^^^^^^^^^^^^^^^^^^
  File "C:\Users\AMD\AppData\Local\Programs\Python\Python311\Lib\site-packages\wandb\sdk\wandb_run.py", line 398, in wrapper
    return func(self, *args, **kwargs)
           ^^^^^^^^^^^^^^^^^^^^^^^^^^^
  File "C:\Users\AMD\AppData\Local\Programs\Python\Python311\Lib\site-packages\wandb\sdk\wandb_run.py", line 456, in wrapper_fn
    return func(self, *args, **kwargs)
           ^^^^^^^^^^^^^^^^^^^^^^^^^^^
  File "C:\Users\AMD\AppData\Local\Programs\Python\Python311\Lib\site-packages\wandb\sdk\wandb_run.py", line 1566, in _console_raw_callback
    self._backend.interface.publish_output_raw(name, data)
  File "C:\Users\AMD\AppData\Local\Programs\Python\Python311\Lib\site-packages\wandb\sdk\interface\interface.py", line 771, in publish_output_raw
    self._publish_output_raw(o)
  File "C:\Users\AMD\AppData\Local\Programs\Python\Python311\Lib\site-packages\wandb\sdk\interface\interface_shared.py", line 38, in _publish_output_raw
    self._publish(rec)
  File "C:\Users\AMD\AppData\Local\Programs\Python\Python311\Lib\site-packages\wandb\sdk\interface\interface_sock.py", line 39, in _publish
    self._sock_client.send_record_publish(record)
  File "C:\Users\AMD\AppData\Local\Programs\Python\Python311\Lib\site-packages\wandb\sdk\lib\sock_client.py", line 170, in send_record_publish
    self.send_server_request(server_req)
  File "C:\Users\AMD\AppData\Local\Programs\Python\Python311\Lib\site-packages\wandb\sdk\lib\sock_client.py", line 150, in send_server_request
    self._send_message(msg)
  File "C:\Users\AMD\AppData\Local\Programs\Python\Python311\Lib\site-packages\wandb\sdk\lib\sock_client.py", line 147, in _send_message
    self._sendall_with_error_handle(header + data)
  File "C:\Users\AMD\AppData\Local\Programs\Python\Python311\Lib\site-packages\wandb\sdk\lib\sock_client.py", line 126, in _sendall_with_error_handle
    sent = self._sock.send(data)
           ^^^^^^^^^^^^^^^^^^^^^
ConnectionAbortedError: [WinError 10053] An established connection was aborted by the software in your host machine
2025-07-31 17:37:49,355 ERROR   sentry-sdk.BackgroundWorker:12572 [redirect.py:_on_write():664] [all runs] error in stdout callback
Traceback (most recent call last):
  File "C:\Users\AMD\AppData\Local\Programs\Python\Python311\Lib\site-packages\wandb\sdk\lib\redirect.py", line 662, in _on_write
    cb(written_data)
  File "C:\Users\AMD\AppData\Local\Programs\Python\Python311\Lib\site-packages\wandb\sdk\wandb_run.py", line 2379, in <lambda>
    lambda data: self._console_raw_callback("stdout", data),
                 ^^^^^^^^^^^^^^^^^^^^^^^^^^^^^^^^^^^^^^^^^^
  File "C:\Users\AMD\AppData\Local\Programs\Python\Python311\Lib\site-packages\wandb\sdk\wandb_run.py", line 398, in wrapper
    return func(self, *args, **kwargs)
           ^^^^^^^^^^^^^^^^^^^^^^^^^^^
  File "C:\Users\AMD\AppData\Local\Programs\Python\Python311\Lib\site-packages\wandb\sdk\wandb_run.py", line 456, in wrapper_fn
    return func(self, *args, **kwargs)
           ^^^^^^^^^^^^^^^^^^^^^^^^^^^
  File "C:\Users\AMD\AppData\Local\Programs\Python\Python311\Lib\site-packages\wandb\sdk\wandb_run.py", line 1566, in _console_raw_callback
    self._backend.interface.publish_output_raw(name, data)
  File "C:\Users\AMD\AppData\Local\Programs\Python\Python311\Lib\site-packages\wandb\sdk\interface\interface.py", line 771, in publish_output_raw
    self._publish_output_raw(o)
  File "C:\Users\AMD\AppData\Local\Programs\Python\Python311\Lib\site-packages\wandb\sdk\interface\interface_shared.py", line 38, in _publish_output_raw
    self._publish(rec)
  File "C:\Users\AMD\AppData\Local\Programs\Python\Python311\Lib\site-packages\wandb\sdk\interface\interface_sock.py", line 39, in _publish
    self._sock_client.send_record_publish(record)
  File "C:\Users\AMD\AppData\Local\Programs\Python\Python311\Lib\site-packages\wandb\sdk\lib\sock_client.py", line 170, in send_record_publish
    self.send_server_request(server_req)
  File "C:\Users\AMD\AppData\Local\Programs\Python\Python311\Lib\site-packages\wandb\sdk\lib\sock_client.py", line 150, in send_server_request
    self._send_message(msg)
  File "C:\Users\AMD\AppData\Local\Programs\Python\Python311\Lib\site-packages\wandb\sdk\lib\sock_client.py", line 147, in _send_message
    self._sendall_with_error_handle(header + data)
  File "C:\Users\AMD\AppData\Local\Programs\Python\Python311\Lib\site-packages\wandb\sdk\lib\sock_client.py", line 126, in _sendall_with_error_handle
    sent = self._sock.send(data)
           ^^^^^^^^^^^^^^^^^^^^^
ConnectionAbortedError: [WinError 10053] An established connection was aborted by the software in your host machine
2025-07-31 17:37:49,375 ERROR   MainThread:12572 [redirect.py:_on_write():664] [all runs] error in stderr callback
Traceback (most recent call last):
  File "C:\Users\AMD\AppData\Local\Programs\Python\Python311\Lib\site-packages\wandb\sdk\lib\redirect.py", line 662, in _on_write
    cb(written_data)
  File "C:\Users\AMD\AppData\Local\Programs\Python\Python311\Lib\site-packages\wandb\sdk\wandb_run.py", line 2385, in <lambda>
    lambda data: self._console_raw_callback("stderr", data),
                 ^^^^^^^^^^^^^^^^^^^^^^^^^^^^^^^^^^^^^^^^^^
  File "C:\Users\AMD\AppData\Local\Programs\Python\Python311\Lib\site-packages\wandb\sdk\wandb_run.py", line 398, in wrapper
    return func(self, *args, **kwargs)
           ^^^^^^^^^^^^^^^^^^^^^^^^^^^
  File "C:\Users\AMD\AppData\Local\Programs\Python\Python311\Lib\site-packages\wandb\sdk\wandb_run.py", line 456, in wrapper_fn
    return func(self, *args, **kwargs)
           ^^^^^^^^^^^^^^^^^^^^^^^^^^^
  File "C:\Users\AMD\AppData\Local\Programs\Python\Python311\Lib\site-packages\wandb\sdk\wandb_run.py", line 1566, in _console_raw_callback
    self._backend.interface.publish_output_raw(name, data)
  File "C:\Users\AMD\AppData\Local\Programs\Python\Python311\Lib\site-packages\wandb\sdk\interface\interface.py", line 771, in publish_output_raw
    self._publish_output_raw(o)
  File "C:\Users\AMD\AppData\Local\Programs\Python\Python311\Lib\site-packages\wandb\sdk\interface\interface_shared.py", line 38, in _publish_output_raw
    self._publish(rec)
  File "C:\Users\AMD\AppData\Local\Programs\Python\Python311\Lib\site-packages\wandb\sdk\interface\interface_sock.py", line 39, in _publish
    self._sock_client.send_record_publish(record)
  File "C:\Users\AMD\AppData\Local\Programs\Python\Python311\Lib\site-packages\wandb\sdk\lib\sock_client.py", line 170, in send_record_publish
    self.send_server_request(server_req)
  File "C:\Users\AMD\AppData\Local\Programs\Python\Python311\Lib\site-packages\wandb\sdk\lib\sock_client.py", line 150, in send_server_request
    self._send_message(msg)
  File "C:\Users\AMD\AppData\Local\Programs\Python\Python311\Lib\site-packages\wandb\sdk\lib\sock_client.py", line 147, in _send_message
    self._sendall_with_error_handle(header + data)
  File "C:\Users\AMD\AppData\Local\Programs\Python\Python311\Lib\site-packages\wandb\sdk\lib\sock_client.py", line 126, in _sendall_with_error_handle
    sent = self._sock.send(data)
           ^^^^^^^^^^^^^^^^^^^^^
ConnectionAbortedError: [WinError 10053] An established connection was aborted by the software in your host machine
2025-07-31 17:37:49,455 ERROR   sentry-sdk.BackgroundWorker:12572 [redirect.py:_on_write():664] [all runs] error in stdout callback
Traceback (most recent call last):
  File "C:\Users\AMD\AppData\Local\Programs\Python\Python311\Lib\site-packages\wandb\sdk\lib\redirect.py", line 662, in _on_write
    cb(written_data)
  File "C:\Users\AMD\AppData\Local\Programs\Python\Python311\Lib\site-packages\wandb\sdk\wandb_run.py", line 2379, in <lambda>
    lambda data: self._console_raw_callback("stdout", data),
                 ^^^^^^^^^^^^^^^^^^^^^^^^^^^^^^^^^^^^^^^^^^
  File "C:\Users\AMD\AppData\Local\Programs\Python\Python311\Lib\site-packages\wandb\sdk\wandb_run.py", line 398, in wrapper
    return func(self, *args, **kwargs)
           ^^^^^^^^^^^^^^^^^^^^^^^^^^^
  File "C:\Users\AMD\AppData\Local\Programs\Python\Python311\Lib\site-packages\wandb\sdk\wandb_run.py", line 456, in wrapper_fn
    return func(self, *args, **kwargs)
           ^^^^^^^^^^^^^^^^^^^^^^^^^^^
  File "C:\Users\AMD\AppData\Local\Programs\Python\Python311\Lib\site-packages\wandb\sdk\wandb_run.py", line 1566, in _console_raw_callback
    self._backend.interface.publish_output_raw(name, data)
  File "C:\Users\AMD\AppData\Local\Programs\Python\Python311\Lib\site-packages\wandb\sdk\interface\interface.py", line 771, in publish_output_raw
    self._publish_output_raw(o)
  File "C:\Users\AMD\AppData\Local\Programs\Python\Python311\Lib\site-packages\wandb\sdk\interface\interface_shared.py", line 38, in _publish_output_raw
    self._publish(rec)
  File "C:\Users\AMD\AppData\Local\Programs\Python\Python311\Lib\site-packages\wandb\sdk\interface\interface_sock.py", line 39, in _publish
    self._sock_client.send_record_publish(record)
  File "C:\Users\AMD\AppData\Local\Programs\Python\Python311\Lib\site-packages\wandb\sdk\lib\sock_client.py", line 170, in send_record_publish
    self.send_server_request(server_req)
  File "C:\Users\AMD\AppData\Local\Programs\Python\Python311\Lib\site-packages\wandb\sdk\lib\sock_client.py", line 150, in send_server_request
    self._send_message(msg)
  File "C:\Users\AMD\AppData\Local\Programs\Python\Python311\Lib\site-packages\wandb\sdk\lib\sock_client.py", line 147, in _send_message
    self._sendall_with_error_handle(header + data)
  File "C:\Users\AMD\AppData\Local\Programs\Python\Python311\Lib\site-packages\wandb\sdk\lib\sock_client.py", line 126, in _sendall_with_error_handle
    sent = self._sock.send(data)
           ^^^^^^^^^^^^^^^^^^^^^
ConnectionAbortedError: [WinError 10053] An established connection was aborted by the software in your host machine
2025-07-31 17:37:49,554 ERROR   sentry-sdk.BackgroundWorker:12572 [redirect.py:_on_write():664] [all runs] error in stdout callback
Traceback (most recent call last):
  File "C:\Users\AMD\AppData\Local\Programs\Python\Python311\Lib\site-packages\wandb\sdk\lib\redirect.py", line 662, in _on_write
    cb(written_data)
  File "C:\Users\AMD\AppData\Local\Programs\Python\Python311\Lib\site-packages\wandb\sdk\wandb_run.py", line 2379, in <lambda>
    lambda data: self._console_raw_callback("stdout", data),
                 ^^^^^^^^^^^^^^^^^^^^^^^^^^^^^^^^^^^^^^^^^^
  File "C:\Users\AMD\AppData\Local\Programs\Python\Python311\Lib\site-packages\wandb\sdk\wandb_run.py", line 398, in wrapper
    return func(self, *args, **kwargs)
           ^^^^^^^^^^^^^^^^^^^^^^^^^^^
  File "C:\Users\AMD\AppData\Local\Programs\Python\Python311\Lib\site-packages\wandb\sdk\wandb_run.py", line 456, in wrapper_fn
    return func(self, *args, **kwargs)
           ^^^^^^^^^^^^^^^^^^^^^^^^^^^
  File "C:\Users\AMD\AppData\Local\Programs\Python\Python311\Lib\site-packages\wandb\sdk\wandb_run.py", line 1566, in _console_raw_callback
    self._backend.interface.publish_output_raw(name, data)
  File "C:\Users\AMD\AppData\Local\Programs\Python\Python311\Lib\site-packages\wandb\sdk\interface\interface.py", line 771, in publish_output_raw
    self._publish_output_raw(o)
  File "C:\Users\AMD\AppData\Local\Programs\Python\Python311\Lib\site-packages\wandb\sdk\interface\interface_shared.py", line 38, in _publish_output_raw
    self._publish(rec)
  File "C:\Users\AMD\AppData\Local\Programs\Python\Python311\Lib\site-packages\wandb\sdk\interface\interface_sock.py", line 39, in _publish
    self._sock_client.send_record_publish(record)
  File "C:\Users\AMD\AppData\Local\Programs\Python\Python311\Lib\site-packages\wandb\sdk\lib\sock_client.py", line 170, in send_record_publish
    self.send_server_request(server_req)
  File "C:\Users\AMD\AppData\Local\Programs\Python\Python311\Lib\site-packages\wandb\sdk\lib\sock_client.py", line 150, in send_server_request
    self._send_message(msg)
  File "C:\Users\AMD\AppData\Local\Programs\Python\Python311\Lib\site-packages\wandb\sdk\lib\sock_client.py", line 147, in _send_message
    self._sendall_with_error_handle(header + data)
  File "C:\Users\AMD\AppData\Local\Programs\Python\Python311\Lib\site-packages\wandb\sdk\lib\sock_client.py", line 126, in _sendall_with_error_handle
    sent = self._sock.send(data)
           ^^^^^^^^^^^^^^^^^^^^^
ConnectionAbortedError: [WinError 10053] An established connection was aborted by the software in your host machine
2025-07-31 17:37:49,661 ERROR   sentry-sdk.BackgroundWorker:12572 [redirect.py:_on_write():664] [all runs] error in stdout callback
Traceback (most recent call last):
  File "C:\Users\AMD\AppData\Local\Programs\Python\Python311\Lib\site-packages\wandb\sdk\lib\redirect.py", line 662, in _on_write
    cb(written_data)
  File "C:\Users\AMD\AppData\Local\Programs\Python\Python311\Lib\site-packages\wandb\sdk\wandb_run.py", line 2379, in <lambda>
    lambda data: self._console_raw_callback("stdout", data),
                 ^^^^^^^^^^^^^^^^^^^^^^^^^^^^^^^^^^^^^^^^^^
  File "C:\Users\AMD\AppData\Local\Programs\Python\Python311\Lib\site-packages\wandb\sdk\wandb_run.py", line 398, in wrapper
    return func(self, *args, **kwargs)
           ^^^^^^^^^^^^^^^^^^^^^^^^^^^
  File "C:\Users\AMD\AppData\Local\Programs\Python\Python311\Lib\site-packages\wandb\sdk\wandb_run.py", line 456, in wrapper_fn
    return func(self, *args, **kwargs)
           ^^^^^^^^^^^^^^^^^^^^^^^^^^^
  File "C:\Users\AMD\AppData\Local\Programs\Python\Python311\Lib\site-packages\wandb\sdk\wandb_run.py", line 1566, in _console_raw_callback
    self._backend.interface.publish_output_raw(name, data)
  File "C:\Users\AMD\AppData\Local\Programs\Python\Python311\Lib\site-packages\wandb\sdk\interface\interface.py", line 771, in publish_output_raw
    self._publish_output_raw(o)
  File "C:\Users\AMD\AppData\Local\Programs\Python\Python311\Lib\site-packages\wandb\sdk\interface\interface_shared.py", line 38, in _publish_output_raw
    self._publish(rec)
  File "C:\Users\AMD\AppData\Local\Programs\Python\Python311\Lib\site-packages\wandb\sdk\interface\interface_sock.py", line 39, in _publish
    self._sock_client.send_record_publish(record)
  File "C:\Users\AMD\AppData\Local\Programs\Python\Python311\Lib\site-packages\wandb\sdk\lib\sock_client.py", line 170, in send_record_publish
    self.send_server_request(server_req)
  File "C:\Users\AMD\AppData\Local\Programs\Python\Python311\Lib\site-packages\wandb\sdk\lib\sock_client.py", line 150, in send_server_request
    self._send_message(msg)
  File "C:\Users\AMD\AppData\Local\Programs\Python\Python311\Lib\site-packages\wandb\sdk\lib\sock_client.py", line 147, in _send_message
    self._sendall_with_error_handle(header + data)
  File "C:\Users\AMD\AppData\Local\Programs\Python\Python311\Lib\site-packages\wandb\sdk\lib\sock_client.py", line 126, in _sendall_with_error_handle
    sent = self._sock.send(data)
           ^^^^^^^^^^^^^^^^^^^^^
ConnectionAbortedError: [WinError 10053] An established connection was aborted by the software in your host machine
2025-07-31 17:37:49,756 ERROR   sentry-sdk.BackgroundWorker:12572 [redirect.py:_on_write():664] [all runs] error in stdout callback
Traceback (most recent call last):
  File "C:\Users\AMD\AppData\Local\Programs\Python\Python311\Lib\site-packages\wandb\sdk\lib\redirect.py", line 662, in _on_write
    cb(written_data)
  File "C:\Users\AMD\AppData\Local\Programs\Python\Python311\Lib\site-packages\wandb\sdk\wandb_run.py", line 2379, in <lambda>
    lambda data: self._console_raw_callback("stdout", data),
                 ^^^^^^^^^^^^^^^^^^^^^^^^^^^^^^^^^^^^^^^^^^
  File "C:\Users\AMD\AppData\Local\Programs\Python\Python311\Lib\site-packages\wandb\sdk\wandb_run.py", line 398, in wrapper
    return func(self, *args, **kwargs)
           ^^^^^^^^^^^^^^^^^^^^^^^^^^^
  File "C:\Users\AMD\AppData\Local\Programs\Python\Python311\Lib\site-packages\wandb\sdk\wandb_run.py", line 456, in wrapper_fn
    return func(self, *args, **kwargs)
           ^^^^^^^^^^^^^^^^^^^^^^^^^^^
  File "C:\Users\AMD\AppData\Local\Programs\Python\Python311\Lib\site-packages\wandb\sdk\wandb_run.py", line 1566, in _console_raw_callback
    self._backend.interface.publish_output_raw(name, data)
  File "C:\Users\AMD\AppData\Local\Programs\Python\Python311\Lib\site-packages\wandb\sdk\interface\interface.py", line 771, in publish_output_raw
    self._publish_output_raw(o)
  File "C:\Users\AMD\AppData\Local\Programs\Python\Python311\Lib\site-packages\wandb\sdk\interface\interface_shared.py", line 38, in _publish_output_raw
    self._publish(rec)
  File "C:\Users\AMD\AppData\Local\Programs\Python\Python311\Lib\site-packages\wandb\sdk\interface\interface_sock.py", line 39, in _publish
    self._sock_client.send_record_publish(record)
  File "C:\Users\AMD\AppData\Local\Programs\Python\Python311\Lib\site-packages\wandb\sdk\lib\sock_client.py", line 170, in send_record_publish
    self.send_server_request(server_req)
  File "C:\Users\AMD\AppData\Local\Programs\Python\Python311\Lib\site-packages\wandb\sdk\lib\sock_client.py", line 150, in send_server_request
    self._send_message(msg)
  File "C:\Users\AMD\AppData\Local\Programs\Python\Python311\Lib\site-packages\wandb\sdk\lib\sock_client.py", line 147, in _send_message
    self._sendall_with_error_handle(header + data)
  File "C:\Users\AMD\AppData\Local\Programs\Python\Python311\Lib\site-packages\wandb\sdk\lib\sock_client.py", line 126, in _sendall_with_error_handle
    sent = self._sock.send(data)
           ^^^^^^^^^^^^^^^^^^^^^
ConnectionAbortedError: [WinError 10053] An established connection was aborted by the software in your host machine
2025-07-31 17:37:49,852 ERROR   sentry-sdk.BackgroundWorker:12572 [redirect.py:_on_write():664] [all runs] error in stdout callback
Traceback (most recent call last):
  File "C:\Users\AMD\AppData\Local\Programs\Python\Python311\Lib\site-packages\wandb\sdk\lib\redirect.py", line 662, in _on_write
    cb(written_data)
  File "C:\Users\AMD\AppData\Local\Programs\Python\Python311\Lib\site-packages\wandb\sdk\wandb_run.py", line 2379, in <lambda>
    lambda data: self._console_raw_callback("stdout", data),
                 ^^^^^^^^^^^^^^^^^^^^^^^^^^^^^^^^^^^^^^^^^^
  File "C:\Users\AMD\AppData\Local\Programs\Python\Python311\Lib\site-packages\wandb\sdk\wandb_run.py", line 398, in wrapper
    return func(self, *args, **kwargs)
           ^^^^^^^^^^^^^^^^^^^^^^^^^^^
  File "C:\Users\AMD\AppData\Local\Programs\Python\Python311\Lib\site-packages\wandb\sdk\wandb_run.py", line 456, in wrapper_fn
    return func(self, *args, **kwargs)
           ^^^^^^^^^^^^^^^^^^^^^^^^^^^
  File "C:\Users\AMD\AppData\Local\Programs\Python\Python311\Lib\site-packages\wandb\sdk\wandb_run.py", line 1566, in _console_raw_callback
    self._backend.interface.publish_output_raw(name, data)
  File "C:\Users\AMD\AppData\Local\Programs\Python\Python311\Lib\site-packages\wandb\sdk\interface\interface.py", line 771, in publish_output_raw
    self._publish_output_raw(o)
  File "C:\Users\AMD\AppData\Local\Programs\Python\Python311\Lib\site-packages\wandb\sdk\interface\interface_shared.py", line 38, in _publish_output_raw
    self._publish(rec)
  File "C:\Users\AMD\AppData\Local\Programs\Python\Python311\Lib\site-packages\wandb\sdk\interface\interface_sock.py", line 39, in _publish
    self._sock_client.send_record_publish(record)
  File "C:\Users\AMD\AppData\Local\Programs\Python\Python311\Lib\site-packages\wandb\sdk\lib\sock_client.py", line 170, in send_record_publish
    self.send_server_request(server_req)
  File "C:\Users\AMD\AppData\Local\Programs\Python\Python311\Lib\site-packages\wandb\sdk\lib\sock_client.py", line 150, in send_server_request
    self._send_message(msg)
  File "C:\Users\AMD\AppData\Local\Programs\Python\Python311\Lib\site-packages\wandb\sdk\lib\sock_client.py", line 147, in _send_message
    self._sendall_with_error_handle(header + data)
  File "C:\Users\AMD\AppData\Local\Programs\Python\Python311\Lib\site-packages\wandb\sdk\lib\sock_client.py", line 126, in _sendall_with_error_handle
    sent = self._sock.send(data)
           ^^^^^^^^^^^^^^^^^^^^^
ConnectionAbortedError: [WinError 10053] An established connection was aborted by the software in your host machine
2025-07-31 17:37:49,949 ERROR   sentry-sdk.BackgroundWorker:12572 [redirect.py:_on_write():664] [all runs] error in stdout callback
Traceback (most recent call last):
  File "C:\Users\AMD\AppData\Local\Programs\Python\Python311\Lib\site-packages\wandb\sdk\lib\redirect.py", line 662, in _on_write
    cb(written_data)
  File "C:\Users\AMD\AppData\Local\Programs\Python\Python311\Lib\site-packages\wandb\sdk\wandb_run.py", line 2379, in <lambda>
    lambda data: self._console_raw_callback("stdout", data),
                 ^^^^^^^^^^^^^^^^^^^^^^^^^^^^^^^^^^^^^^^^^^
  File "C:\Users\AMD\AppData\Local\Programs\Python\Python311\Lib\site-packages\wandb\sdk\wandb_run.py", line 398, in wrapper
    return func(self, *args, **kwargs)
           ^^^^^^^^^^^^^^^^^^^^^^^^^^^
  File "C:\Users\AMD\AppData\Local\Programs\Python\Python311\Lib\site-packages\wandb\sdk\wandb_run.py", line 456, in wrapper_fn
    return func(self, *args, **kwargs)
           ^^^^^^^^^^^^^^^^^^^^^^^^^^^
  File "C:\Users\AMD\AppData\Local\Programs\Python\Python311\Lib\site-packages\wandb\sdk\wandb_run.py", line 1566, in _console_raw_callback
    self._backend.interface.publish_output_raw(name, data)
  File "C:\Users\AMD\AppData\Local\Programs\Python\Python311\Lib\site-packages\wandb\sdk\interface\interface.py", line 771, in publish_output_raw
    self._publish_output_raw(o)
  File "C:\Users\AMD\AppData\Local\Programs\Python\Python311\Lib\site-packages\wandb\sdk\interface\interface_shared.py", line 38, in _publish_output_raw
    self._publish(rec)
  File "C:\Users\AMD\AppData\Local\Programs\Python\Python311\Lib\site-packages\wandb\sdk\interface\interface_sock.py", line 39, in _publish
    self._sock_client.send_record_publish(record)
  File "C:\Users\AMD\AppData\Local\Programs\Python\Python311\Lib\site-packages\wandb\sdk\lib\sock_client.py", line 170, in send_record_publish
    self.send_server_request(server_req)
  File "C:\Users\AMD\AppData\Local\Programs\Python\Python311\Lib\site-packages\wandb\sdk\lib\sock_client.py", line 150, in send_server_request
    self._send_message(msg)
  File "C:\Users\AMD\AppData\Local\Programs\Python\Python311\Lib\site-packages\wandb\sdk\lib\sock_client.py", line 147, in _send_message
    self._sendall_with_error_handle(header + data)
  File "C:\Users\AMD\AppData\Local\Programs\Python\Python311\Lib\site-packages\wandb\sdk\lib\sock_client.py", line 126, in _sendall_with_error_handle
    sent = self._sock.send(data)
           ^^^^^^^^^^^^^^^^^^^^^
ConnectionAbortedError: [WinError 10053] An established connection was aborted by the software in your host machine
2025-07-31 17:37:50,043 ERROR   sentry-sdk.BackgroundWorker:12572 [redirect.py:_on_write():664] [all runs] error in stdout callback
Traceback (most recent call last):
  File "C:\Users\AMD\AppData\Local\Programs\Python\Python311\Lib\site-packages\wandb\sdk\lib\redirect.py", line 662, in _on_write
    cb(written_data)
  File "C:\Users\AMD\AppData\Local\Programs\Python\Python311\Lib\site-packages\wandb\sdk\wandb_run.py", line 2379, in <lambda>
    lambda data: self._console_raw_callback("stdout", data),
                 ^^^^^^^^^^^^^^^^^^^^^^^^^^^^^^^^^^^^^^^^^^
  File "C:\Users\AMD\AppData\Local\Programs\Python\Python311\Lib\site-packages\wandb\sdk\wandb_run.py", line 398, in wrapper
    return func(self, *args, **kwargs)
           ^^^^^^^^^^^^^^^^^^^^^^^^^^^
  File "C:\Users\AMD\AppData\Local\Programs\Python\Python311\Lib\site-packages\wandb\sdk\wandb_run.py", line 456, in wrapper_fn
    return func(self, *args, **kwargs)
           ^^^^^^^^^^^^^^^^^^^^^^^^^^^
  File "C:\Users\AMD\AppData\Local\Programs\Python\Python311\Lib\site-packages\wandb\sdk\wandb_run.py", line 1566, in _console_raw_callback
    self._backend.interface.publish_output_raw(name, data)
  File "C:\Users\AMD\AppData\Local\Programs\Python\Python311\Lib\site-packages\wandb\sdk\interface\interface.py", line 771, in publish_output_raw
    self._publish_output_raw(o)
  File "C:\Users\AMD\AppData\Local\Programs\Python\Python311\Lib\site-packages\wandb\sdk\interface\interface_shared.py", line 38, in _publish_output_raw
    self._publish(rec)
  File "C:\Users\AMD\AppData\Local\Programs\Python\Python311\Lib\site-packages\wandb\sdk\interface\interface_sock.py", line 39, in _publish
    self._sock_client.send_record_publish(record)
  File "C:\Users\AMD\AppData\Local\Programs\Python\Python311\Lib\site-packages\wandb\sdk\lib\sock_client.py", line 170, in send_record_publish
    self.send_server_request(server_req)
  File "C:\Users\AMD\AppData\Local\Programs\Python\Python311\Lib\site-packages\wandb\sdk\lib\sock_client.py", line 150, in send_server_request
    self._send_message(msg)
  File "C:\Users\AMD\AppData\Local\Programs\Python\Python311\Lib\site-packages\wandb\sdk\lib\sock_client.py", line 147, in _send_message
    self._sendall_with_error_handle(header + data)
  File "C:\Users\AMD\AppData\Local\Programs\Python\Python311\Lib\site-packages\wandb\sdk\lib\sock_client.py", line 126, in _sendall_with_error_handle
    sent = self._sock.send(data)
           ^^^^^^^^^^^^^^^^^^^^^
ConnectionAbortedError: [WinError 10053] An established connection was aborted by the software in your host machine
2025-07-31 17:37:50,132 ERROR   sentry-sdk.BackgroundWorker:12572 [redirect.py:_on_write():664] [all runs] error in stdout callback
Traceback (most recent call last):
  File "C:\Users\AMD\AppData\Local\Programs\Python\Python311\Lib\site-packages\wandb\sdk\lib\redirect.py", line 662, in _on_write
    cb(written_data)
  File "C:\Users\AMD\AppData\Local\Programs\Python\Python311\Lib\site-packages\wandb\sdk\wandb_run.py", line 2379, in <lambda>
    lambda data: self._console_raw_callback("stdout", data),
                 ^^^^^^^^^^^^^^^^^^^^^^^^^^^^^^^^^^^^^^^^^^
  File "C:\Users\AMD\AppData\Local\Programs\Python\Python311\Lib\site-packages\wandb\sdk\wandb_run.py", line 398, in wrapper
    return func(self, *args, **kwargs)
           ^^^^^^^^^^^^^^^^^^^^^^^^^^^
  File "C:\Users\AMD\AppData\Local\Programs\Python\Python311\Lib\site-packages\wandb\sdk\wandb_run.py", line 456, in wrapper_fn
    return func(self, *args, **kwargs)
           ^^^^^^^^^^^^^^^^^^^^^^^^^^^
  File "C:\Users\AMD\AppData\Local\Programs\Python\Python311\Lib\site-packages\wandb\sdk\wandb_run.py", line 1566, in _console_raw_callback
    self._backend.interface.publish_output_raw(name, data)
  File "C:\Users\AMD\AppData\Local\Programs\Python\Python311\Lib\site-packages\wandb\sdk\interface\interface.py", line 771, in publish_output_raw
    self._publish_output_raw(o)
  File "C:\Users\AMD\AppData\Local\Programs\Python\Python311\Lib\site-packages\wandb\sdk\interface\interface_shared.py", line 38, in _publish_output_raw
    self._publish(rec)
  File "C:\Users\AMD\AppData\Local\Programs\Python\Python311\Lib\site-packages\wandb\sdk\interface\interface_sock.py", line 39, in _publish
    self._sock_client.send_record_publish(record)
  File "C:\Users\AMD\AppData\Local\Programs\Python\Python311\Lib\site-packages\wandb\sdk\lib\sock_client.py", line 170, in send_record_publish
    self.send_server_request(server_req)
  File "C:\Users\AMD\AppData\Local\Programs\Python\Python311\Lib\site-packages\wandb\sdk\lib\sock_client.py", line 150, in send_server_request
    self._send_message(msg)
  File "C:\Users\AMD\AppData\Local\Programs\Python\Python311\Lib\site-packages\wandb\sdk\lib\sock_client.py", line 147, in _send_message
    self._sendall_with_error_handle(header + data)
  File "C:\Users\AMD\AppData\Local\Programs\Python\Python311\Lib\site-packages\wandb\sdk\lib\sock_client.py", line 126, in _sendall_with_error_handle
    sent = self._sock.send(data)
           ^^^^^^^^^^^^^^^^^^^^^
ConnectionAbortedError: [WinError 10053] An established connection was aborted by the software in your host machine
2025-07-31 17:37:50,231 ERROR   sentry-sdk.BackgroundWorker:12572 [redirect.py:_on_write():664] [all runs] error in stdout callback
Traceback (most recent call last):
  File "C:\Users\AMD\AppData\Local\Programs\Python\Python311\Lib\site-packages\wandb\sdk\lib\redirect.py", line 662, in _on_write
    cb(written_data)
  File "C:\Users\AMD\AppData\Local\Programs\Python\Python311\Lib\site-packages\wandb\sdk\wandb_run.py", line 2379, in <lambda>
    lambda data: self._console_raw_callback("stdout", data),
                 ^^^^^^^^^^^^^^^^^^^^^^^^^^^^^^^^^^^^^^^^^^
  File "C:\Users\AMD\AppData\Local\Programs\Python\Python311\Lib\site-packages\wandb\sdk\wandb_run.py", line 398, in wrapper
    return func(self, *args, **kwargs)
           ^^^^^^^^^^^^^^^^^^^^^^^^^^^
  File "C:\Users\AMD\AppData\Local\Programs\Python\Python311\Lib\site-packages\wandb\sdk\wandb_run.py", line 456, in wrapper_fn
    return func(self, *args, **kwargs)
           ^^^^^^^^^^^^^^^^^^^^^^^^^^^
  File "C:\Users\AMD\AppData\Local\Programs\Python\Python311\Lib\site-packages\wandb\sdk\wandb_run.py", line 1566, in _console_raw_callback
    self._backend.interface.publish_output_raw(name, data)
  File "C:\Users\AMD\AppData\Local\Programs\Python\Python311\Lib\site-packages\wandb\sdk\interface\interface.py", line 771, in publish_output_raw
    self._publish_output_raw(o)
  File "C:\Users\AMD\AppData\Local\Programs\Python\Python311\Lib\site-packages\wandb\sdk\interface\interface_shared.py", line 38, in _publish_output_raw
    self._publish(rec)
  File "C:\Users\AMD\AppData\Local\Programs\Python\Python311\Lib\site-packages\wandb\sdk\interface\interface_sock.py", line 39, in _publish
    self._sock_client.send_record_publish(record)
  File "C:\Users\AMD\AppData\Local\Programs\Python\Python311\Lib\site-packages\wandb\sdk\lib\sock_client.py", line 170, in send_record_publish
    self.send_server_request(server_req)
  File "C:\Users\AMD\AppData\Local\Programs\Python\Python311\Lib\site-packages\wandb\sdk\lib\sock_client.py", line 150, in send_server_request
    self._send_message(msg)
  File "C:\Users\AMD\AppData\Local\Programs\Python\Python311\Lib\site-packages\wandb\sdk\lib\sock_client.py", line 147, in _send_message
    self._sendall_with_error_handle(header + data)
  File "C:\Users\AMD\AppData\Local\Programs\Python\Python311\Lib\site-packages\wandb\sdk\lib\sock_client.py", line 126, in _sendall_with_error_handle
    sent = self._sock.send(data)
           ^^^^^^^^^^^^^^^^^^^^^
ConnectionAbortedError: [WinError 10053] An established connection was aborted by the software in your host machine
2025-07-31 17:37:50,332 ERROR   sentry-sdk.BackgroundWorker:12572 [redirect.py:_on_write():664] [all runs] error in stdout callback
Traceback (most recent call last):
  File "C:\Users\AMD\AppData\Local\Programs\Python\Python311\Lib\site-packages\wandb\sdk\lib\redirect.py", line 662, in _on_write
    cb(written_data)
  File "C:\Users\AMD\AppData\Local\Programs\Python\Python311\Lib\site-packages\wandb\sdk\wandb_run.py", line 2379, in <lambda>
    lambda data: self._console_raw_callback("stdout", data),
                 ^^^^^^^^^^^^^^^^^^^^^^^^^^^^^^^^^^^^^^^^^^
  File "C:\Users\AMD\AppData\Local\Programs\Python\Python311\Lib\site-packages\wandb\sdk\wandb_run.py", line 398, in wrapper
    return func(self, *args, **kwargs)
           ^^^^^^^^^^^^^^^^^^^^^^^^^^^
  File "C:\Users\AMD\AppData\Local\Programs\Python\Python311\Lib\site-packages\wandb\sdk\wandb_run.py", line 456, in wrapper_fn
    return func(self, *args, **kwargs)
           ^^^^^^^^^^^^^^^^^^^^^^^^^^^
  File "C:\Users\AMD\AppData\Local\Programs\Python\Python311\Lib\site-packages\wandb\sdk\wandb_run.py", line 1566, in _console_raw_callback
    self._backend.interface.publish_output_raw(name, data)
  File "C:\Users\AMD\AppData\Local\Programs\Python\Python311\Lib\site-packages\wandb\sdk\interface\interface.py", line 771, in publish_output_raw
    self._publish_output_raw(o)
  File "C:\Users\AMD\AppData\Local\Programs\Python\Python311\Lib\site-packages\wandb\sdk\interface\interface_shared.py", line 38, in _publish_output_raw
    self._publish(rec)
  File "C:\Users\AMD\AppData\Local\Programs\Python\Python311\Lib\site-packages\wandb\sdk\interface\interface_sock.py", line 39, in _publish
    self._sock_client.send_record_publish(record)
  File "C:\Users\AMD\AppData\Local\Programs\Python\Python311\Lib\site-packages\wandb\sdk\lib\sock_client.py", line 170, in send_record_publish
    self.send_server_request(server_req)
  File "C:\Users\AMD\AppData\Local\Programs\Python\Python311\Lib\site-packages\wandb\sdk\lib\sock_client.py", line 150, in send_server_request
    self._send_message(msg)
  File "C:\Users\AMD\AppData\Local\Programs\Python\Python311\Lib\site-packages\wandb\sdk\lib\sock_client.py", line 147, in _send_message
    self._sendall_with_error_handle(header + data)
  File "C:\Users\AMD\AppData\Local\Programs\Python\Python311\Lib\site-packages\wandb\sdk\lib\sock_client.py", line 126, in _sendall_with_error_handle
    sent = self._sock.send(data)
           ^^^^^^^^^^^^^^^^^^^^^
ConnectionAbortedError: [WinError 10053] An established connection was aborted by the software in your host machine
2025-07-31 17:37:50,425 ERROR   sentry-sdk.BackgroundWorker:12572 [redirect.py:_on_write():664] [all runs] error in stdout callback
Traceback (most recent call last):
  File "C:\Users\AMD\AppData\Local\Programs\Python\Python311\Lib\site-packages\wandb\sdk\lib\redirect.py", line 662, in _on_write
    cb(written_data)
  File "C:\Users\AMD\AppData\Local\Programs\Python\Python311\Lib\site-packages\wandb\sdk\wandb_run.py", line 2379, in <lambda>
    lambda data: self._console_raw_callback("stdout", data),
                 ^^^^^^^^^^^^^^^^^^^^^^^^^^^^^^^^^^^^^^^^^^
  File "C:\Users\AMD\AppData\Local\Programs\Python\Python311\Lib\site-packages\wandb\sdk\wandb_run.py", line 398, in wrapper
    return func(self, *args, **kwargs)
           ^^^^^^^^^^^^^^^^^^^^^^^^^^^
  File "C:\Users\AMD\AppData\Local\Programs\Python\Python311\Lib\site-packages\wandb\sdk\wandb_run.py", line 456, in wrapper_fn
    return func(self, *args, **kwargs)
           ^^^^^^^^^^^^^^^^^^^^^^^^^^^
  File "C:\Users\AMD\AppData\Local\Programs\Python\Python311\Lib\site-packages\wandb\sdk\wandb_run.py", line 1566, in _console_raw_callback
    self._backend.interface.publish_output_raw(name, data)
  File "C:\Users\AMD\AppData\Local\Programs\Python\Python311\Lib\site-packages\wandb\sdk\interface\interface.py", line 771, in publish_output_raw
    self._publish_output_raw(o)
  File "C:\Users\AMD\AppData\Local\Programs\Python\Python311\Lib\site-packages\wandb\sdk\interface\interface_shared.py", line 38, in _publish_output_raw
    self._publish(rec)
  File "C:\Users\AMD\AppData\Local\Programs\Python\Python311\Lib\site-packages\wandb\sdk\interface\interface_sock.py", line 39, in _publish
    self._sock_client.send_record_publish(record)
  File "C:\Users\AMD\AppData\Local\Programs\Python\Python311\Lib\site-packages\wandb\sdk\lib\sock_client.py", line 170, in send_record_publish
    self.send_server_request(server_req)
  File "C:\Users\AMD\AppData\Local\Programs\Python\Python311\Lib\site-packages\wandb\sdk\lib\sock_client.py", line 150, in send_server_request
    self._send_message(msg)
  File "C:\Users\AMD\AppData\Local\Programs\Python\Python311\Lib\site-packages\wandb\sdk\lib\sock_client.py", line 147, in _send_message
    self._sendall_with_error_handle(header + data)
  File "C:\Users\AMD\AppData\Local\Programs\Python\Python311\Lib\site-packages\wandb\sdk\lib\sock_client.py", line 126, in _sendall_with_error_handle
    sent = self._sock.send(data)
           ^^^^^^^^^^^^^^^^^^^^^
ConnectionAbortedError: [WinError 10053] An established connection was aborted by the software in your host machine
2025-07-31 17:37:50,524 ERROR   sentry-sdk.BackgroundWorker:12572 [redirect.py:_on_write():664] [all runs] error in stdout callback
Traceback (most recent call last):
  File "C:\Users\AMD\AppData\Local\Programs\Python\Python311\Lib\site-packages\wandb\sdk\lib\redirect.py", line 662, in _on_write
    cb(written_data)
  File "C:\Users\AMD\AppData\Local\Programs\Python\Python311\Lib\site-packages\wandb\sdk\wandb_run.py", line 2379, in <lambda>
    lambda data: self._console_raw_callback("stdout", data),
                 ^^^^^^^^^^^^^^^^^^^^^^^^^^^^^^^^^^^^^^^^^^
  File "C:\Users\AMD\AppData\Local\Programs\Python\Python311\Lib\site-packages\wandb\sdk\wandb_run.py", line 398, in wrapper
    return func(self, *args, **kwargs)
           ^^^^^^^^^^^^^^^^^^^^^^^^^^^
  File "C:\Users\AMD\AppData\Local\Programs\Python\Python311\Lib\site-packages\wandb\sdk\wandb_run.py", line 456, in wrapper_fn
    return func(self, *args, **kwargs)
           ^^^^^^^^^^^^^^^^^^^^^^^^^^^
  File "C:\Users\AMD\AppData\Local\Programs\Python\Python311\Lib\site-packages\wandb\sdk\wandb_run.py", line 1566, in _console_raw_callback
    self._backend.interface.publish_output_raw(name, data)
  File "C:\Users\AMD\AppData\Local\Programs\Python\Python311\Lib\site-packages\wandb\sdk\interface\interface.py", line 771, in publish_output_raw
    self._publish_output_raw(o)
  File "C:\Users\AMD\AppData\Local\Programs\Python\Python311\Lib\site-packages\wandb\sdk\interface\interface_shared.py", line 38, in _publish_output_raw
    self._publish(rec)
  File "C:\Users\AMD\AppData\Local\Programs\Python\Python311\Lib\site-packages\wandb\sdk\interface\interface_sock.py", line 39, in _publish
    self._sock_client.send_record_publish(record)
  File "C:\Users\AMD\AppData\Local\Programs\Python\Python311\Lib\site-packages\wandb\sdk\lib\sock_client.py", line 170, in send_record_publish
    self.send_server_request(server_req)
  File "C:\Users\AMD\AppData\Local\Programs\Python\Python311\Lib\site-packages\wandb\sdk\lib\sock_client.py", line 150, in send_server_request
    self._send_message(msg)
  File "C:\Users\AMD\AppData\Local\Programs\Python\Python311\Lib\site-packages\wandb\sdk\lib\sock_client.py", line 147, in _send_message
    self._sendall_with_error_handle(header + data)
  File "C:\Users\AMD\AppData\Local\Programs\Python\Python311\Lib\site-packages\wandb\sdk\lib\sock_client.py", line 126, in _sendall_with_error_handle
    sent = self._sock.send(data)
           ^^^^^^^^^^^^^^^^^^^^^
ConnectionAbortedError: [WinError 10053] An established connection was aborted by the software in your host machine
2025-07-31 17:37:50,630 ERROR   sentry-sdk.BackgroundWorker:12572 [redirect.py:_on_write():664] [all runs] error in stdout callback
Traceback (most recent call last):
  File "C:\Users\AMD\AppData\Local\Programs\Python\Python311\Lib\site-packages\wandb\sdk\lib\redirect.py", line 662, in _on_write
    cb(written_data)
  File "C:\Users\AMD\AppData\Local\Programs\Python\Python311\Lib\site-packages\wandb\sdk\wandb_run.py", line 2379, in <lambda>
    lambda data: self._console_raw_callback("stdout", data),
                 ^^^^^^^^^^^^^^^^^^^^^^^^^^^^^^^^^^^^^^^^^^
  File "C:\Users\AMD\AppData\Local\Programs\Python\Python311\Lib\site-packages\wandb\sdk\wandb_run.py", line 398, in wrapper
    return func(self, *args, **kwargs)
           ^^^^^^^^^^^^^^^^^^^^^^^^^^^
  File "C:\Users\AMD\AppData\Local\Programs\Python\Python311\Lib\site-packages\wandb\sdk\wandb_run.py", line 456, in wrapper_fn
    return func(self, *args, **kwargs)
           ^^^^^^^^^^^^^^^^^^^^^^^^^^^
  File "C:\Users\AMD\AppData\Local\Programs\Python\Python311\Lib\site-packages\wandb\sdk\wandb_run.py", line 1566, in _console_raw_callback
    self._backend.interface.publish_output_raw(name, data)
  File "C:\Users\AMD\AppData\Local\Programs\Python\Python311\Lib\site-packages\wandb\sdk\interface\interface.py", line 771, in publish_output_raw
    self._publish_output_raw(o)
  File "C:\Users\AMD\AppData\Local\Programs\Python\Python311\Lib\site-packages\wandb\sdk\interface\interface_shared.py", line 38, in _publish_output_raw
    self._publish(rec)
  File "C:\Users\AMD\AppData\Local\Programs\Python\Python311\Lib\site-packages\wandb\sdk\interface\interface_sock.py", line 39, in _publish
    self._sock_client.send_record_publish(record)
  File "C:\Users\AMD\AppData\Local\Programs\Python\Python311\Lib\site-packages\wandb\sdk\lib\sock_client.py", line 170, in send_record_publish
    self.send_server_request(server_req)
  File "C:\Users\AMD\AppData\Local\Programs\Python\Python311\Lib\site-packages\wandb\sdk\lib\sock_client.py", line 150, in send_server_request
    self._send_message(msg)
  File "C:\Users\AMD\AppData\Local\Programs\Python\Python311\Lib\site-packages\wandb\sdk\lib\sock_client.py", line 147, in _send_message
    self._sendall_with_error_handle(header + data)
  File "C:\Users\AMD\AppData\Local\Programs\Python\Python311\Lib\site-packages\wandb\sdk\lib\sock_client.py", line 126, in _sendall_with_error_handle
    sent = self._sock.send(data)
           ^^^^^^^^^^^^^^^^^^^^^
ConnectionAbortedError: [WinError 10053] An established connection was aborted by the software in your host machine
2025-07-31 17:37:50,726 ERROR   sentry-sdk.BackgroundWorker:12572 [redirect.py:_on_write():664] [all runs] error in stdout callback
Traceback (most recent call last):
  File "C:\Users\AMD\AppData\Local\Programs\Python\Python311\Lib\site-packages\wandb\sdk\lib\redirect.py", line 662, in _on_write
    cb(written_data)
  File "C:\Users\AMD\AppData\Local\Programs\Python\Python311\Lib\site-packages\wandb\sdk\wandb_run.py", line 2379, in <lambda>
    lambda data: self._console_raw_callback("stdout", data),
                 ^^^^^^^^^^^^^^^^^^^^^^^^^^^^^^^^^^^^^^^^^^
  File "C:\Users\AMD\AppData\Local\Programs\Python\Python311\Lib\site-packages\wandb\sdk\wandb_run.py", line 398, in wrapper
    return func(self, *args, **kwargs)
           ^^^^^^^^^^^^^^^^^^^^^^^^^^^
  File "C:\Users\AMD\AppData\Local\Programs\Python\Python311\Lib\site-packages\wandb\sdk\wandb_run.py", line 456, in wrapper_fn
    return func(self, *args, **kwargs)
           ^^^^^^^^^^^^^^^^^^^^^^^^^^^
  File "C:\Users\AMD\AppData\Local\Programs\Python\Python311\Lib\site-packages\wandb\sdk\wandb_run.py", line 1566, in _console_raw_callback
    self._backend.interface.publish_output_raw(name, data)
  File "C:\Users\AMD\AppData\Local\Programs\Python\Python311\Lib\site-packages\wandb\sdk\interface\interface.py", line 771, in publish_output_raw
    self._publish_output_raw(o)
  File "C:\Users\AMD\AppData\Local\Programs\Python\Python311\Lib\site-packages\wandb\sdk\interface\interface_shared.py", line 38, in _publish_output_raw
    self._publish(rec)
  File "C:\Users\AMD\AppData\Local\Programs\Python\Python311\Lib\site-packages\wandb\sdk\interface\interface_sock.py", line 39, in _publish
    self._sock_client.send_record_publish(record)
  File "C:\Users\AMD\AppData\Local\Programs\Python\Python311\Lib\site-packages\wandb\sdk\lib\sock_client.py", line 170, in send_record_publish
    self.send_server_request(server_req)
  File "C:\Users\AMD\AppData\Local\Programs\Python\Python311\Lib\site-packages\wandb\sdk\lib\sock_client.py", line 150, in send_server_request
    self._send_message(msg)
  File "C:\Users\AMD\AppData\Local\Programs\Python\Python311\Lib\site-packages\wandb\sdk\lib\sock_client.py", line 147, in _send_message
    self._sendall_with_error_handle(header + data)
  File "C:\Users\AMD\AppData\Local\Programs\Python\Python311\Lib\site-packages\wandb\sdk\lib\sock_client.py", line 126, in _sendall_with_error_handle
    sent = self._sock.send(data)
           ^^^^^^^^^^^^^^^^^^^^^
ConnectionAbortedError: [WinError 10053] An established connection was aborted by the software in your host machine
2025-07-31 17:37:50,817 ERROR   sentry-sdk.BackgroundWorker:12572 [redirect.py:_on_write():664] [all runs] error in stdout callback
Traceback (most recent call last):
  File "C:\Users\AMD\AppData\Local\Programs\Python\Python311\Lib\site-packages\wandb\sdk\lib\redirect.py", line 662, in _on_write
    cb(written_data)
  File "C:\Users\AMD\AppData\Local\Programs\Python\Python311\Lib\site-packages\wandb\sdk\wandb_run.py", line 2379, in <lambda>
    lambda data: self._console_raw_callback("stdout", data),
                 ^^^^^^^^^^^^^^^^^^^^^^^^^^^^^^^^^^^^^^^^^^
  File "C:\Users\AMD\AppData\Local\Programs\Python\Python311\Lib\site-packages\wandb\sdk\wandb_run.py", line 398, in wrapper
    return func(self, *args, **kwargs)
           ^^^^^^^^^^^^^^^^^^^^^^^^^^^
  File "C:\Users\AMD\AppData\Local\Programs\Python\Python311\Lib\site-packages\wandb\sdk\wandb_run.py", line 456, in wrapper_fn
    return func(self, *args, **kwargs)
           ^^^^^^^^^^^^^^^^^^^^^^^^^^^
  File "C:\Users\AMD\AppData\Local\Programs\Python\Python311\Lib\site-packages\wandb\sdk\wandb_run.py", line 1566, in _console_raw_callback
    self._backend.interface.publish_output_raw(name, data)
  File "C:\Users\AMD\AppData\Local\Programs\Python\Python311\Lib\site-packages\wandb\sdk\interface\interface.py", line 771, in publish_output_raw
    self._publish_output_raw(o)
  File "C:\Users\AMD\AppData\Local\Programs\Python\Python311\Lib\site-packages\wandb\sdk\interface\interface_shared.py", line 38, in _publish_output_raw
    self._publish(rec)
  File "C:\Users\AMD\AppData\Local\Programs\Python\Python311\Lib\site-packages\wandb\sdk\interface\interface_sock.py", line 39, in _publish
    self._sock_client.send_record_publish(record)
  File "C:\Users\AMD\AppData\Local\Programs\Python\Python311\Lib\site-packages\wandb\sdk\lib\sock_client.py", line 170, in send_record_publish
    self.send_server_request(server_req)
  File "C:\Users\AMD\AppData\Local\Programs\Python\Python311\Lib\site-packages\wandb\sdk\lib\sock_client.py", line 150, in send_server_request
    self._send_message(msg)
  File "C:\Users\AMD\AppData\Local\Programs\Python\Python311\Lib\site-packages\wandb\sdk\lib\sock_client.py", line 147, in _send_message
    self._sendall_with_error_handle(header + data)
  File "C:\Users\AMD\AppData\Local\Programs\Python\Python311\Lib\site-packages\wandb\sdk\lib\sock_client.py", line 126, in _sendall_with_error_handle
    sent = self._sock.send(data)
           ^^^^^^^^^^^^^^^^^^^^^
ConnectionAbortedError: [WinError 10053] An established connection was aborted by the software in your host machine
2025-07-31 17:37:50,907 ERROR   sentry-sdk.BackgroundWorker:12572 [redirect.py:_on_write():664] [all runs] error in stdout callback
Traceback (most recent call last):
  File "C:\Users\AMD\AppData\Local\Programs\Python\Python311\Lib\site-packages\wandb\sdk\lib\redirect.py", line 662, in _on_write
    cb(written_data)
  File "C:\Users\AMD\AppData\Local\Programs\Python\Python311\Lib\site-packages\wandb\sdk\wandb_run.py", line 2379, in <lambda>
    lambda data: self._console_raw_callback("stdout", data),
                 ^^^^^^^^^^^^^^^^^^^^^^^^^^^^^^^^^^^^^^^^^^
  File "C:\Users\AMD\AppData\Local\Programs\Python\Python311\Lib\site-packages\wandb\sdk\wandb_run.py", line 398, in wrapper
    return func(self, *args, **kwargs)
           ^^^^^^^^^^^^^^^^^^^^^^^^^^^
  File "C:\Users\AMD\AppData\Local\Programs\Python\Python311\Lib\site-packages\wandb\sdk\wandb_run.py", line 456, in wrapper_fn
    return func(self, *args, **kwargs)
           ^^^^^^^^^^^^^^^^^^^^^^^^^^^
  File "C:\Users\AMD\AppData\Local\Programs\Python\Python311\Lib\site-packages\wandb\sdk\wandb_run.py", line 1566, in _console_raw_callback
    self._backend.interface.publish_output_raw(name, data)
  File "C:\Users\AMD\AppData\Local\Programs\Python\Python311\Lib\site-packages\wandb\sdk\interface\interface.py", line 771, in publish_output_raw
    self._publish_output_raw(o)
  File "C:\Users\AMD\AppData\Local\Programs\Python\Python311\Lib\site-packages\wandb\sdk\interface\interface_shared.py", line 38, in _publish_output_raw
    self._publish(rec)
  File "C:\Users\AMD\AppData\Local\Programs\Python\Python311\Lib\site-packages\wandb\sdk\interface\interface_sock.py", line 39, in _publish
    self._sock_client.send_record_publish(record)
  File "C:\Users\AMD\AppData\Local\Programs\Python\Python311\Lib\site-packages\wandb\sdk\lib\sock_client.py", line 170, in send_record_publish
    self.send_server_request(server_req)
  File "C:\Users\AMD\AppData\Local\Programs\Python\Python311\Lib\site-packages\wandb\sdk\lib\sock_client.py", line 150, in send_server_request
    self._send_message(msg)
  File "C:\Users\AMD\AppData\Local\Programs\Python\Python311\Lib\site-packages\wandb\sdk\lib\sock_client.py", line 147, in _send_message
    self._sendall_with_error_handle(header + data)
  File "C:\Users\AMD\AppData\Local\Programs\Python\Python311\Lib\site-packages\wandb\sdk\lib\sock_client.py", line 126, in _sendall_with_error_handle
    sent = self._sock.send(data)
           ^^^^^^^^^^^^^^^^^^^^^
ConnectionAbortedError: [WinError 10053] An established connection was aborted by the software in your host machine
2025-07-31 17:37:51,000 ERROR   sentry-sdk.BackgroundWorker:12572 [redirect.py:_on_write():664] [all runs] error in stdout callback
Traceback (most recent call last):
  File "C:\Users\AMD\AppData\Local\Programs\Python\Python311\Lib\site-packages\wandb\sdk\lib\redirect.py", line 662, in _on_write
    cb(written_data)
  File "C:\Users\AMD\AppData\Local\Programs\Python\Python311\Lib\site-packages\wandb\sdk\wandb_run.py", line 2379, in <lambda>
    lambda data: self._console_raw_callback("stdout", data),
                 ^^^^^^^^^^^^^^^^^^^^^^^^^^^^^^^^^^^^^^^^^^
  File "C:\Users\AMD\AppData\Local\Programs\Python\Python311\Lib\site-packages\wandb\sdk\wandb_run.py", line 398, in wrapper
    return func(self, *args, **kwargs)
           ^^^^^^^^^^^^^^^^^^^^^^^^^^^
  File "C:\Users\AMD\AppData\Local\Programs\Python\Python311\Lib\site-packages\wandb\sdk\wandb_run.py", line 456, in wrapper_fn
    return func(self, *args, **kwargs)
           ^^^^^^^^^^^^^^^^^^^^^^^^^^^
  File "C:\Users\AMD\AppData\Local\Programs\Python\Python311\Lib\site-packages\wandb\sdk\wandb_run.py", line 1566, in _console_raw_callback
    self._backend.interface.publish_output_raw(name, data)
  File "C:\Users\AMD\AppData\Local\Programs\Python\Python311\Lib\site-packages\wandb\sdk\interface\interface.py", line 771, in publish_output_raw
    self._publish_output_raw(o)
  File "C:\Users\AMD\AppData\Local\Programs\Python\Python311\Lib\site-packages\wandb\sdk\interface\interface_shared.py", line 38, in _publish_output_raw
    self._publish(rec)
  File "C:\Users\AMD\AppData\Local\Programs\Python\Python311\Lib\site-packages\wandb\sdk\interface\interface_sock.py", line 39, in _publish
    self._sock_client.send_record_publish(record)
  File "C:\Users\AMD\AppData\Local\Programs\Python\Python311\Lib\site-packages\wandb\sdk\lib\sock_client.py", line 170, in send_record_publish
    self.send_server_request(server_req)
  File "C:\Users\AMD\AppData\Local\Programs\Python\Python311\Lib\site-packages\wandb\sdk\lib\sock_client.py", line 150, in send_server_request
    self._send_message(msg)
  File "C:\Users\AMD\AppData\Local\Programs\Python\Python311\Lib\site-packages\wandb\sdk\lib\sock_client.py", line 147, in _send_message
    self._sendall_with_error_handle(header + data)
  File "C:\Users\AMD\AppData\Local\Programs\Python\Python311\Lib\site-packages\wandb\sdk\lib\sock_client.py", line 126, in _sendall_with_error_handle
    sent = self._sock.send(data)
           ^^^^^^^^^^^^^^^^^^^^^
ConnectionAbortedError: [WinError 10053] An established connection was aborted by the software in your host machine
2025-07-31 17:37:51,092 ERROR   sentry-sdk.BackgroundWorker:12572 [redirect.py:_on_write():664] [all runs] error in stdout callback
Traceback (most recent call last):
  File "C:\Users\AMD\AppData\Local\Programs\Python\Python311\Lib\site-packages\wandb\sdk\lib\redirect.py", line 662, in _on_write
    cb(written_data)
  File "C:\Users\AMD\AppData\Local\Programs\Python\Python311\Lib\site-packages\wandb\sdk\wandb_run.py", line 2379, in <lambda>
    lambda data: self._console_raw_callback("stdout", data),
                 ^^^^^^^^^^^^^^^^^^^^^^^^^^^^^^^^^^^^^^^^^^
  File "C:\Users\AMD\AppData\Local\Programs\Python\Python311\Lib\site-packages\wandb\sdk\wandb_run.py", line 398, in wrapper
    return func(self, *args, **kwargs)
           ^^^^^^^^^^^^^^^^^^^^^^^^^^^
  File "C:\Users\AMD\AppData\Local\Programs\Python\Python311\Lib\site-packages\wandb\sdk\wandb_run.py", line 456, in wrapper_fn
    return func(self, *args, **kwargs)
           ^^^^^^^^^^^^^^^^^^^^^^^^^^^
  File "C:\Users\AMD\AppData\Local\Programs\Python\Python311\Lib\site-packages\wandb\sdk\wandb_run.py", line 1566, in _console_raw_callback
    self._backend.interface.publish_output_raw(name, data)
  File "C:\Users\AMD\AppData\Local\Programs\Python\Python311\Lib\site-packages\wandb\sdk\interface\interface.py", line 771, in publish_output_raw
    self._publish_output_raw(o)
  File "C:\Users\AMD\AppData\Local\Programs\Python\Python311\Lib\site-packages\wandb\sdk\interface\interface_shared.py", line 38, in _publish_output_raw
    self._publish(rec)
  File "C:\Users\AMD\AppData\Local\Programs\Python\Python311\Lib\site-packages\wandb\sdk\interface\interface_sock.py", line 39, in _publish
    self._sock_client.send_record_publish(record)
  File "C:\Users\AMD\AppData\Local\Programs\Python\Python311\Lib\site-packages\wandb\sdk\lib\sock_client.py", line 170, in send_record_publish
    self.send_server_request(server_req)
  File "C:\Users\AMD\AppData\Local\Programs\Python\Python311\Lib\site-packages\wandb\sdk\lib\sock_client.py", line 150, in send_server_request
    self._send_message(msg)
  File "C:\Users\AMD\AppData\Local\Programs\Python\Python311\Lib\site-packages\wandb\sdk\lib\sock_client.py", line 147, in _send_message
    self._sendall_with_error_handle(header + data)
  File "C:\Users\AMD\AppData\Local\Programs\Python\Python311\Lib\site-packages\wandb\sdk\lib\sock_client.py", line 126, in _sendall_with_error_handle
    sent = self._sock.send(data)
           ^^^^^^^^^^^^^^^^^^^^^
ConnectionAbortedError: [WinError 10053] An established connection was aborted by the software in your host machine
2025-07-31 17:37:51,186 ERROR   sentry-sdk.BackgroundWorker:12572 [redirect.py:_on_write():664] [all runs] error in stdout callback
Traceback (most recent call last):
  File "C:\Users\AMD\AppData\Local\Programs\Python\Python311\Lib\site-packages\wandb\sdk\lib\redirect.py", line 662, in _on_write
    cb(written_data)
  File "C:\Users\AMD\AppData\Local\Programs\Python\Python311\Lib\site-packages\wandb\sdk\wandb_run.py", line 2379, in <lambda>
    lambda data: self._console_raw_callback("stdout", data),
                 ^^^^^^^^^^^^^^^^^^^^^^^^^^^^^^^^^^^^^^^^^^
  File "C:\Users\AMD\AppData\Local\Programs\Python\Python311\Lib\site-packages\wandb\sdk\wandb_run.py", line 398, in wrapper
    return func(self, *args, **kwargs)
           ^^^^^^^^^^^^^^^^^^^^^^^^^^^
  File "C:\Users\AMD\AppData\Local\Programs\Python\Python311\Lib\site-packages\wandb\sdk\wandb_run.py", line 456, in wrapper_fn
    return func(self, *args, **kwargs)
           ^^^^^^^^^^^^^^^^^^^^^^^^^^^
  File "C:\Users\AMD\AppData\Local\Programs\Python\Python311\Lib\site-packages\wandb\sdk\wandb_run.py", line 1566, in _console_raw_callback
    self._backend.interface.publish_output_raw(name, data)
  File "C:\Users\AMD\AppData\Local\Programs\Python\Python311\Lib\site-packages\wandb\sdk\interface\interface.py", line 771, in publish_output_raw
    self._publish_output_raw(o)
  File "C:\Users\AMD\AppData\Local\Programs\Python\Python311\Lib\site-packages\wandb\sdk\interface\interface_shared.py", line 38, in _publish_output_raw
    self._publish(rec)
  File "C:\Users\AMD\AppData\Local\Programs\Python\Python311\Lib\site-packages\wandb\sdk\interface\interface_sock.py", line 39, in _publish
    self._sock_client.send_record_publish(record)
  File "C:\Users\AMD\AppData\Local\Programs\Python\Python311\Lib\site-packages\wandb\sdk\lib\sock_client.py", line 170, in send_record_publish
    self.send_server_request(server_req)
  File "C:\Users\AMD\AppData\Local\Programs\Python\Python311\Lib\site-packages\wandb\sdk\lib\sock_client.py", line 150, in send_server_request
    self._send_message(msg)
  File "C:\Users\AMD\AppData\Local\Programs\Python\Python311\Lib\site-packages\wandb\sdk\lib\sock_client.py", line 147, in _send_message
    self._sendall_with_error_handle(header + data)
  File "C:\Users\AMD\AppData\Local\Programs\Python\Python311\Lib\site-packages\wandb\sdk\lib\sock_client.py", line 126, in _sendall_with_error_handle
    sent = self._sock.send(data)
           ^^^^^^^^^^^^^^^^^^^^^
ConnectionAbortedError: [WinError 10053] An established connection was aborted by the software in your host machine
2025-07-31 17:37:51,275 ERROR   sentry-sdk.BackgroundWorker:12572 [redirect.py:_on_write():664] [all runs] error in stdout callback
Traceback (most recent call last):
  File "C:\Users\AMD\AppData\Local\Programs\Python\Python311\Lib\site-packages\wandb\sdk\lib\redirect.py", line 662, in _on_write
    cb(written_data)
  File "C:\Users\AMD\AppData\Local\Programs\Python\Python311\Lib\site-packages\wandb\sdk\wandb_run.py", line 2379, in <lambda>
    lambda data: self._console_raw_callback("stdout", data),
                 ^^^^^^^^^^^^^^^^^^^^^^^^^^^^^^^^^^^^^^^^^^
  File "C:\Users\AMD\AppData\Local\Programs\Python\Python311\Lib\site-packages\wandb\sdk\wandb_run.py", line 398, in wrapper
    return func(self, *args, **kwargs)
           ^^^^^^^^^^^^^^^^^^^^^^^^^^^
  File "C:\Users\AMD\AppData\Local\Programs\Python\Python311\Lib\site-packages\wandb\sdk\wandb_run.py", line 456, in wrapper_fn
    return func(self, *args, **kwargs)
           ^^^^^^^^^^^^^^^^^^^^^^^^^^^
  File "C:\Users\AMD\AppData\Local\Programs\Python\Python311\Lib\site-packages\wandb\sdk\wandb_run.py", line 1566, in _console_raw_callback
    self._backend.interface.publish_output_raw(name, data)
  File "C:\Users\AMD\AppData\Local\Programs\Python\Python311\Lib\site-packages\wandb\sdk\interface\interface.py", line 771, in publish_output_raw
    self._publish_output_raw(o)
  File "C:\Users\AMD\AppData\Local\Programs\Python\Python311\Lib\site-packages\wandb\sdk\interface\interface_shared.py", line 38, in _publish_output_raw
    self._publish(rec)
  File "C:\Users\AMD\AppData\Local\Programs\Python\Python311\Lib\site-packages\wandb\sdk\interface\interface_sock.py", line 39, in _publish
    self._sock_client.send_record_publish(record)
  File "C:\Users\AMD\AppData\Local\Programs\Python\Python311\Lib\site-packages\wandb\sdk\lib\sock_client.py", line 170, in send_record_publish
    self.send_server_request(server_req)
  File "C:\Users\AMD\AppData\Local\Programs\Python\Python311\Lib\site-packages\wandb\sdk\lib\sock_client.py", line 150, in send_server_request
    self._send_message(msg)
  File "C:\Users\AMD\AppData\Local\Programs\Python\Python311\Lib\site-packages\wandb\sdk\lib\sock_client.py", line 147, in _send_message
    self._sendall_with_error_handle(header + data)
  File "C:\Users\AMD\AppData\Local\Programs\Python\Python311\Lib\site-packages\wandb\sdk\lib\sock_client.py", line 126, in _sendall_with_error_handle
    sent = self._sock.send(data)
           ^^^^^^^^^^^^^^^^^^^^^
ConnectionAbortedError: [WinError 10053] An established connection was aborted by the software in your host machine
2025-07-31 17:37:51,375 ERROR   sentry-sdk.BackgroundWorker:12572 [redirect.py:_on_write():664] [all runs] error in stdout callback
Traceback (most recent call last):
  File "C:\Users\AMD\AppData\Local\Programs\Python\Python311\Lib\site-packages\wandb\sdk\lib\redirect.py", line 662, in _on_write
    cb(written_data)
  File "C:\Users\AMD\AppData\Local\Programs\Python\Python311\Lib\site-packages\wandb\sdk\wandb_run.py", line 2379, in <lambda>
    lambda data: self._console_raw_callback("stdout", data),
                 ^^^^^^^^^^^^^^^^^^^^^^^^^^^^^^^^^^^^^^^^^^
  File "C:\Users\AMD\AppData\Local\Programs\Python\Python311\Lib\site-packages\wandb\sdk\wandb_run.py", line 398, in wrapper
    return func(self, *args, **kwargs)
           ^^^^^^^^^^^^^^^^^^^^^^^^^^^
  File "C:\Users\AMD\AppData\Local\Programs\Python\Python311\Lib\site-packages\wandb\sdk\wandb_run.py", line 456, in wrapper_fn
    return func(self, *args, **kwargs)
           ^^^^^^^^^^^^^^^^^^^^^^^^^^^
  File "C:\Users\AMD\AppData\Local\Programs\Python\Python311\Lib\site-packages\wandb\sdk\wandb_run.py", line 1566, in _console_raw_callback
    self._backend.interface.publish_output_raw(name, data)
  File "C:\Users\AMD\AppData\Local\Programs\Python\Python311\Lib\site-packages\wandb\sdk\interface\interface.py", line 771, in publish_output_raw
    self._publish_output_raw(o)
  File "C:\Users\AMD\AppData\Local\Programs\Python\Python311\Lib\site-packages\wandb\sdk\interface\interface_shared.py", line 38, in _publish_output_raw
    self._publish(rec)
  File "C:\Users\AMD\AppData\Local\Programs\Python\Python311\Lib\site-packages\wandb\sdk\interface\interface_sock.py", line 39, in _publish
    self._sock_client.send_record_publish(record)
  File "C:\Users\AMD\AppData\Local\Programs\Python\Python311\Lib\site-packages\wandb\sdk\lib\sock_client.py", line 170, in send_record_publish
    self.send_server_request(server_req)
  File "C:\Users\AMD\AppData\Local\Programs\Python\Python311\Lib\site-packages\wandb\sdk\lib\sock_client.py", line 150, in send_server_request
    self._send_message(msg)
  File "C:\Users\AMD\AppData\Local\Programs\Python\Python311\Lib\site-packages\wandb\sdk\lib\sock_client.py", line 147, in _send_message
    self._sendall_with_error_handle(header + data)
  File "C:\Users\AMD\AppData\Local\Programs\Python\Python311\Lib\site-packages\wandb\sdk\lib\sock_client.py", line 126, in _sendall_with_error_handle
    sent = self._sock.send(data)
           ^^^^^^^^^^^^^^^^^^^^^
ConnectionAbortedError: [WinError 10053] An established connection was aborted by the software in your host machine
2025-07-31 17:37:51,468 ERROR   sentry-sdk.BackgroundWorker:12572 [redirect.py:_on_write():664] [all runs] error in stdout callback
Traceback (most recent call last):
  File "C:\Users\AMD\AppData\Local\Programs\Python\Python311\Lib\site-packages\wandb\sdk\lib\redirect.py", line 662, in _on_write
    cb(written_data)
  File "C:\Users\AMD\AppData\Local\Programs\Python\Python311\Lib\site-packages\wandb\sdk\wandb_run.py", line 2379, in <lambda>
    lambda data: self._console_raw_callback("stdout", data),
                 ^^^^^^^^^^^^^^^^^^^^^^^^^^^^^^^^^^^^^^^^^^
  File "C:\Users\AMD\AppData\Local\Programs\Python\Python311\Lib\site-packages\wandb\sdk\wandb_run.py", line 398, in wrapper
    return func(self, *args, **kwargs)
           ^^^^^^^^^^^^^^^^^^^^^^^^^^^
  File "C:\Users\AMD\AppData\Local\Programs\Python\Python311\Lib\site-packages\wandb\sdk\wandb_run.py", line 456, in wrapper_fn
    return func(self, *args, **kwargs)
           ^^^^^^^^^^^^^^^^^^^^^^^^^^^
  File "C:\Users\AMD\AppData\Local\Programs\Python\Python311\Lib\site-packages\wandb\sdk\wandb_run.py", line 1566, in _console_raw_callback
    self._backend.interface.publish_output_raw(name, data)
  File "C:\Users\AMD\AppData\Local\Programs\Python\Python311\Lib\site-packages\wandb\sdk\interface\interface.py", line 771, in publish_output_raw
    self._publish_output_raw(o)
  File "C:\Users\AMD\AppData\Local\Programs\Python\Python311\Lib\site-packages\wandb\sdk\interface\interface_shared.py", line 38, in _publish_output_raw
    self._publish(rec)
  File "C:\Users\AMD\AppData\Local\Programs\Python\Python311\Lib\site-packages\wandb\sdk\interface\interface_sock.py", line 39, in _publish
    self._sock_client.send_record_publish(record)
  File "C:\Users\AMD\AppData\Local\Programs\Python\Python311\Lib\site-packages\wandb\sdk\lib\sock_client.py", line 170, in send_record_publish
    self.send_server_request(server_req)
  File "C:\Users\AMD\AppData\Local\Programs\Python\Python311\Lib\site-packages\wandb\sdk\lib\sock_client.py", line 150, in send_server_request
    self._send_message(msg)
  File "C:\Users\AMD\AppData\Local\Programs\Python\Python311\Lib\site-packages\wandb\sdk\lib\sock_client.py", line 147, in _send_message
    self._sendall_with_error_handle(header + data)
  File "C:\Users\AMD\AppData\Local\Programs\Python\Python311\Lib\site-packages\wandb\sdk\lib\sock_client.py", line 126, in _sendall_with_error_handle
    sent = self._sock.send(data)
           ^^^^^^^^^^^^^^^^^^^^^
ConnectionAbortedError: [WinError 10053] An established connection was aborted by the software in your host machine
2025-07-31 17:37:51,558 ERROR   sentry-sdk.BackgroundWorker:12572 [redirect.py:_on_write():664] [all runs] error in stdout callback
Traceback (most recent call last):
  File "C:\Users\AMD\AppData\Local\Programs\Python\Python311\Lib\site-packages\wandb\sdk\lib\redirect.py", line 662, in _on_write
    cb(written_data)
  File "C:\Users\AMD\AppData\Local\Programs\Python\Python311\Lib\site-packages\wandb\sdk\wandb_run.py", line 2379, in <lambda>
    lambda data: self._console_raw_callback("stdout", data),
                 ^^^^^^^^^^^^^^^^^^^^^^^^^^^^^^^^^^^^^^^^^^
  File "C:\Users\AMD\AppData\Local\Programs\Python\Python311\Lib\site-packages\wandb\sdk\wandb_run.py", line 398, in wrapper
    return func(self, *args, **kwargs)
           ^^^^^^^^^^^^^^^^^^^^^^^^^^^
  File "C:\Users\AMD\AppData\Local\Programs\Python\Python311\Lib\site-packages\wandb\sdk\wandb_run.py", line 456, in wrapper_fn
    return func(self, *args, **kwargs)
           ^^^^^^^^^^^^^^^^^^^^^^^^^^^
  File "C:\Users\AMD\AppData\Local\Programs\Python\Python311\Lib\site-packages\wandb\sdk\wandb_run.py", line 1566, in _console_raw_callback
    self._backend.interface.publish_output_raw(name, data)
  File "C:\Users\AMD\AppData\Local\Programs\Python\Python311\Lib\site-packages\wandb\sdk\interface\interface.py", line 771, in publish_output_raw
    self._publish_output_raw(o)
  File "C:\Users\AMD\AppData\Local\Programs\Python\Python311\Lib\site-packages\wandb\sdk\interface\interface_shared.py", line 38, in _publish_output_raw
    self._publish(rec)
  File "C:\Users\AMD\AppData\Local\Programs\Python\Python311\Lib\site-packages\wandb\sdk\interface\interface_sock.py", line 39, in _publish
    self._sock_client.send_record_publish(record)
  File "C:\Users\AMD\AppData\Local\Programs\Python\Python311\Lib\site-packages\wandb\sdk\lib\sock_client.py", line 170, in send_record_publish
    self.send_server_request(server_req)
  File "C:\Users\AMD\AppData\Local\Programs\Python\Python311\Lib\site-packages\wandb\sdk\lib\sock_client.py", line 150, in send_server_request
    self._send_message(msg)
  File "C:\Users\AMD\AppData\Local\Programs\Python\Python311\Lib\site-packages\wandb\sdk\lib\sock_client.py", line 147, in _send_message
    self._sendall_with_error_handle(header + data)
  File "C:\Users\AMD\AppData\Local\Programs\Python\Python311\Lib\site-packages\wandb\sdk\lib\sock_client.py", line 126, in _sendall_with_error_handle
    sent = self._sock.send(data)
           ^^^^^^^^^^^^^^^^^^^^^
ConnectionAbortedError: [WinError 10053] An established connection was aborted by the software in your host machine
2025-07-31 17:37:51,598 ERROR   MainThread:12572 [redirect.py:_on_write():664] [all runs] error in stdout callback
Traceback (most recent call last):
  File "C:\Users\AMD\AppData\Local\Programs\Python\Python311\Lib\site-packages\wandb\sdk\lib\redirect.py", line 662, in _on_write
    cb(written_data)
  File "C:\Users\AMD\AppData\Local\Programs\Python\Python311\Lib\site-packages\wandb\sdk\wandb_run.py", line 2379, in <lambda>
    lambda data: self._console_raw_callback("stdout", data),
                 ^^^^^^^^^^^^^^^^^^^^^^^^^^^^^^^^^^^^^^^^^^
  File "C:\Users\AMD\AppData\Local\Programs\Python\Python311\Lib\site-packages\wandb\sdk\wandb_run.py", line 398, in wrapper
    return func(self, *args, **kwargs)
           ^^^^^^^^^^^^^^^^^^^^^^^^^^^
  File "C:\Users\AMD\AppData\Local\Programs\Python\Python311\Lib\site-packages\wandb\sdk\wandb_run.py", line 456, in wrapper_fn
    return func(self, *args, **kwargs)
           ^^^^^^^^^^^^^^^^^^^^^^^^^^^
  File "C:\Users\AMD\AppData\Local\Programs\Python\Python311\Lib\site-packages\wandb\sdk\wandb_run.py", line 1566, in _console_raw_callback
    self._backend.interface.publish_output_raw(name, data)
  File "C:\Users\AMD\AppData\Local\Programs\Python\Python311\Lib\site-packages\wandb\sdk\interface\interface.py", line 771, in publish_output_raw
    self._publish_output_raw(o)
  File "C:\Users\AMD\AppData\Local\Programs\Python\Python311\Lib\site-packages\wandb\sdk\interface\interface_shared.py", line 38, in _publish_output_raw
    self._publish(rec)
  File "C:\Users\AMD\AppData\Local\Programs\Python\Python311\Lib\site-packages\wandb\sdk\interface\interface_sock.py", line 39, in _publish
    self._sock_client.send_record_publish(record)
  File "C:\Users\AMD\AppData\Local\Programs\Python\Python311\Lib\site-packages\wandb\sdk\lib\sock_client.py", line 170, in send_record_publish
    self.send_server_request(server_req)
  File "C:\Users\AMD\AppData\Local\Programs\Python\Python311\Lib\site-packages\wandb\sdk\lib\sock_client.py", line 150, in send_server_request
    self._send_message(msg)
  File "C:\Users\AMD\AppData\Local\Programs\Python\Python311\Lib\site-packages\wandb\sdk\lib\sock_client.py", line 147, in _send_message
    self._sendall_with_error_handle(header + data)
  File "C:\Users\AMD\AppData\Local\Programs\Python\Python311\Lib\site-packages\wandb\sdk\lib\sock_client.py", line 126, in _sendall_with_error_handle
    sent = self._sock.send(data)
           ^^^^^^^^^^^^^^^^^^^^^
ConnectionAbortedError: [WinError 10053] An established connection was aborted by the software in your host machine
2025-07-31 17:37:51,617 ERROR   MainThread:12572 [redirect.py:_on_write():664] [all runs] error in stdout callback
Traceback (most recent call last):
  File "C:\Users\AMD\AppData\Local\Programs\Python\Python311\Lib\site-packages\litellm\llms\custom_httpx\async_client_cleanup.py", line 66, in cleanup_wrapper
    loop = asyncio.get_event_loop()
           ^^^^^^^^^^^^^^^^^^^^^^^^
  File "C:\Users\AMD\AppData\Local\Programs\Python\Python311\Lib\asyncio\events.py", line 681, in get_event_loop
    raise RuntimeError('There is no current event loop in thread %r.'
RuntimeError: There is no current event loop in thread 'MainThread'.

During handling of the above exception, another exception occurred:

Traceback (most recent call last):
  File "C:\Users\AMD\AppData\Local\Programs\Python\Python311\Lib\site-packages\wandb\sdk\lib\redirect.py", line 662, in _on_write
    cb(written_data)
  File "C:\Users\AMD\AppData\Local\Programs\Python\Python311\Lib\site-packages\wandb\sdk\wandb_run.py", line 2379, in <lambda>
    lambda data: self._console_raw_callback("stdout", data),
                 ^^^^^^^^^^^^^^^^^^^^^^^^^^^^^^^^^^^^^^^^^^
  File "C:\Users\AMD\AppData\Local\Programs\Python\Python311\Lib\site-packages\wandb\sdk\wandb_run.py", line 398, in wrapper
    return func(self, *args, **kwargs)
           ^^^^^^^^^^^^^^^^^^^^^^^^^^^
  File "C:\Users\AMD\AppData\Local\Programs\Python\Python311\Lib\site-packages\wandb\sdk\wandb_run.py", line 456, in wrapper_fn
    return func(self, *args, **kwargs)
           ^^^^^^^^^^^^^^^^^^^^^^^^^^^
  File "C:\Users\AMD\AppData\Local\Programs\Python\Python311\Lib\site-packages\wandb\sdk\wandb_run.py", line 1566, in _console_raw_callback
    self._backend.interface.publish_output_raw(name, data)
  File "C:\Users\AMD\AppData\Local\Programs\Python\Python311\Lib\site-packages\wandb\sdk\interface\interface.py", line 771, in publish_output_raw
    self._publish_output_raw(o)
  File "C:\Users\AMD\AppData\Local\Programs\Python\Python311\Lib\site-packages\wandb\sdk\interface\interface_shared.py", line 38, in _publish_output_raw
    self._publish(rec)
  File "C:\Users\AMD\AppData\Local\Programs\Python\Python311\Lib\site-packages\wandb\sdk\interface\interface_sock.py", line 39, in _publish
    self._sock_client.send_record_publish(record)
  File "C:\Users\AMD\AppData\Local\Programs\Python\Python311\Lib\site-packages\wandb\sdk\lib\sock_client.py", line 170, in send_record_publish
    self.send_server_request(server_req)
  File "C:\Users\AMD\AppData\Local\Programs\Python\Python311\Lib\site-packages\wandb\sdk\lib\sock_client.py", line 150, in send_server_request
    self._send_message(msg)
  File "C:\Users\AMD\AppData\Local\Programs\Python\Python311\Lib\site-packages\wandb\sdk\lib\sock_client.py", line 147, in _send_message
    self._sendall_with_error_handle(header + data)
  File "C:\Users\AMD\AppData\Local\Programs\Python\Python311\Lib\site-packages\wandb\sdk\lib\sock_client.py", line 126, in _sendall_with_error_handle
    sent = self._sock.send(data)
           ^^^^^^^^^^^^^^^^^^^^^
ConnectionAbortedError: [WinError 10053] An established connection was aborted by the software in your host machine
