{
  "summary": {
    "total_issues_identified": 25,
    "issues_attempted": 25,
    "issues_fixed": 0,
    "issues_failed": 25,
    "remaining_issues_after_fix": 0,
    "sentry_errors_processed": 25
  },
  "details": [
    {
      "file_path": "unknown",
      "line": 0,
      "type": "SentryError",
      "message": "default: Cognitive Forge Engine initialized successfully",
      "frequency": "322",
      "suggested_fix": "Review the error context and apply appropriate fix",
      "source": "sentry",
      "proposed_action": "Fix the SentryError.",
      "status": "FAILED",
      "final_error": "Validation after fix failed: [Errno 2] No such file or directory: 'unknown'"
    },
    {
      "file_path": "unknown",
      "line": 0,
      "type": "SentryError",
      "message": "default: LLM initialized successfully",
      "frequency": "343",
      "suggested_fix": "Review the error context and apply appropriate fix",
      "source": "sentry",
      "proposed_action": "Fix the SentryError.",
      "status": "FAILED",
      "final_error": "Validation after fix failed: [Errno 2] No such file or directory: 'unknown'"
    },
    {
      "file_path": "unknown",
      "line": 0,
      "type": "SentryError",
      "message": "default: Traceback (most recent call last):",
      "frequency": "141",
      "suggested_fix": "Review the error context and apply appropriate fix",
      "source": "sentry",
      "proposed_action": "Fix the SentryError.",
      "status": "FAILED",
      "final_error": "Validation after fix failed: [Errno 2] No such file or directory: 'unknown'"
    },
    {
      "file_path": "unknown",
      "line": 0,
      "type": "SentryError",
      "message": "default: 2025-07-31 18:08:03.403 | ERROR    | Fix_AI:run_execution_phase:372 - Could not fix default: 2025-07-31 16:09:07.287 | ERROR    | src.core.cognitive_forge_engine:run_mission:266 - Mission test_mission_20250731_160907 failed: 'DirectAIAgent' object has n...",
      "frequency": "1",
      "suggested_fix": "Review the error context and apply appropriate fix",
      "source": "sentry",
      "proposed_action": "Fix the SentryError.",
      "status": "FAILED",
      "final_error": "Validation after fix failed: [Errno 2] No such file or directory: 'unknown'"
    },
    {
      "file_path": "unknown",
      "line": 0,
      "type": "SentryError",
      "message": "default: 2025-07-31 18:08:03.387 | ERROR    | Fix_AI:run_execution_phase:372 - Could not fix default: Mission started: test_mission_20250731_161157 after 3 attempts.",
      "frequency": "1",
      "suggested_fix": "Review the error context and apply appropriate fix",
      "source": "sentry",
      "proposed_action": "Fix the SentryError.",
      "status": "FAILED",
      "final_error": "Validation after fix failed: [Errno 2] No such file or directory: 'unknown'"
    },
    {
      "file_path": "unknown",
      "line": 0,
      "type": "SentryError",
      "message": "default: 2025-07-31 18:08:03.369 | ERROR    | Fix_AI:run_execution_phase:372 - Could not fix default: 2025-07-31 16:11:57.907 | ERROR    | src.core.cognitive_forge_engine:run_mission:266 - Mission test_mission_20250731_161157 failed: Invalid JSON format: Expecti...",
      "frequency": "1",
      "suggested_fix": "Review the error context and apply appropriate fix",
      "source": "sentry",
      "proposed_action": "Fix the SentryError.",
      "status": "FAILED",
      "final_error": "Validation after fix failed: [Errno 2] No such file or directory: 'unknown'"
    },
    {
      "file_path": "unknown",
      "line": 0,
      "type": "SentryError",
      "message": "default: 2025-07-31 18:08:03.348 | ERROR    | Fix_AI:run_execution_phase:372 - Could not fix default: Mission started: test_mission_20250731_161458 after 3 attempts.",
      "frequency": "1",
      "suggested_fix": "Review the error context and apply appropriate fix",
      "source": "sentry",
      "proposed_action": "Fix the SentryError.",
      "status": "FAILED",
      "final_error": "Validation after fix failed: [Errno 2] No such file or directory: 'unknown'"
    },
    {
      "file_path": "unknown",
      "line": 0,
      "type": "SentryError",
      "message": "default: 2025-07-31 18:08:03.333 | ERROR    | Fix_AI:run_execution_phase:372 - Could not fix default: 2025-07-31 16:14:58.030 | ERROR    | src.utils.google_ai_wrapper:_generate:161 - Error during Google AI generation: 'ModelPrivateAttr' object has no attribute '...",
      "frequency": "1",
      "suggested_fix": "Review the error context and apply appropriate fix",
      "source": "sentry",
      "proposed_action": "Fix the SentryError.",
      "status": "FAILED",
      "final_error": "Validation after fix failed: [Errno 2] No such file or directory: 'unknown'"
    },
    {
      "file_path": "unknown",
      "line": 0,
      "type": "SentryError",
      "message": "default: 2025-07-31 18:08:03.313 | ERROR    | Fix_AI:run_execution_phase:372 - Could not fix default: 2025-07-31 16:14:58.044 | ERROR    | src.core.cognitive_forge_engine:_parse_agent_json_response:1238 - Original response: An error occurred: 'ModelPrivateAttr' ...",
      "frequency": "1",
      "suggested_fix": "Review the error context and apply appropriate fix",
      "source": "sentry",
      "proposed_action": "Fix the SentryError.",
      "status": "FAILED",
      "final_error": "Validation after fix failed: [Errno 2] No such file or directory: 'unknown'"
    },
    {
      "file_path": "unknown",
      "line": 0,
      "type": "SentryError",
      "message": "default: 2025-07-31 18:08:03.295 | ERROR    | Fix_AI:run_execution_phase:372 - Could not fix error: ValueError: Invalid JSON format: Expecting value: line 1 column 1 (char 0) after 3 attempts.",
      "frequency": "1",
      "suggested_fix": "Review the error context and apply appropriate fix",
      "source": "sentry",
      "proposed_action": "Fix the SentryError.",
      "status": "FAILED",
      "final_error": "Validation after fix failed: [Errno 2] No such file or directory: 'unknown'"
    },
    {
      "file_path": "unknown",
      "line": 0,
      "type": "SentryError",
      "message": "default: 2025-07-31 18:08:03.277 | ERROR    | Fix_AI:run_execution_phase:372 - Could not fix default: 2025-07-31 16:14:58.073 | ERROR    | src.core.cognitive_forge_engine:run_mission:266 - Mission test_mission_20250731_161458 failed: Invalid JSON format: Expecti...",
      "frequency": "1",
      "suggested_fix": "Review the error context and apply appropriate fix",
      "source": "sentry",
      "proposed_action": "Fix the SentryError.",
      "status": "FAILED",
      "final_error": "Validation after fix failed: [Errno 2] No such file or directory: 'unknown'"
    },
    {
      "file_path": "unknown",
      "line": 0,
      "type": "SentryError",
      "message": "default: 2025-07-31 18:08:03.259 | ERROR    | Fix_AI:run_execution_phase:372 - Could not fix default: 2025-07-31 17:26:05.474 | ERROR    | src.utils.performance_optimizer:parallelize_tasks:492 - Parallel task execution failed: 'str' object has no attribute 'get'...",
      "frequency": "1",
      "suggested_fix": "Review the error context and apply appropriate fix",
      "source": "sentry",
      "proposed_action": "Fix the SentryError.",
      "status": "FAILED",
      "final_error": "Validation after fix failed: [Errno 2] No such file or directory: 'unknown'"
    },
    {
      "file_path": "unknown",
      "line": 0,
      "type": "SentryError",
      "message": "default: 2025-07-31 18:08:03.239 | ERROR    | Fix_AI:run_execution_phase:372 - Could not fix default: 2025-07-31 17:26:05.503 | ERROR    | src.core.advanced_intelligence:_create_execution_plan:166 - Execution plan creation failed: 'str' object has no attribute '...",
      "frequency": "1",
      "suggested_fix": "Review the error context and apply appropriate fix",
      "source": "sentry",
      "proposed_action": "Fix the SentryError.",
      "status": "FAILED",
      "final_error": "Validation after fix failed: [Errno 2] No such file or directory: 'unknown'"
    },
    {
      "file_path": "unknown",
      "line": 0,
      "type": "SentryError",
      "message": "default: 2025-07-31 18:08:03.221 | ERROR    | Fix_AI:run_execution_phase:372 - Could not fix default: 2025-07-31 17:31:38.570 | ERROR    | src.core.advanced_intelligence:_execute_phase:301 - Task execution failed: 'str' object has no attribute 'get' after 3 atte...",
      "frequency": "1",
      "suggested_fix": "Review the error context and apply appropriate fix",
      "source": "sentry",
      "proposed_action": "Fix the SentryError.",
      "status": "FAILED",
      "final_error": "Validation after fix failed: [Errno 2] No such file or directory: 'unknown'"
    },
    {
      "file_path": "unknown",
      "line": 0,
      "type": "SentryError",
      "message": "default: 2025-07-31 18:08:03.203 | ERROR    | Fix_AI:run_execution_phase:372 - Could not fix default: 2025-07-31 17:45:54.695 | ERROR    | src.utils.google_ai_wrapper:_generate:169 - Error during Google AI generation: 'GoogleGenerativeAIWrapper' object has no at...",
      "frequency": "1",
      "suggested_fix": "Review the error context and apply appropriate fix",
      "source": "sentry",
      "proposed_action": "Fix the SentryError.",
      "status": "FAILED",
      "final_error": "Validation after fix failed: [Errno 2] No such file or directory: 'unknown'"
    },
    {
      "file_path": "unknown",
      "line": 0,
      "type": "SentryError",
      "message": "default: 2025-07-31 18:08:03.184 | ERROR    | Fix_AI:run_execution_phase:372 - Could not fix default: 2025-07-31 17:45:54.716 | ERROR    | src.core.cognitive_forge_engine:_parse_agent_json_response:1256 - Original response: An error occurred: 'GoogleGenerativeAI...",
      "frequency": "1",
      "suggested_fix": "Review the error context and apply appropriate fix",
      "source": "sentry",
      "proposed_action": "Fix the SentryError.",
      "status": "FAILED",
      "final_error": "Validation after fix failed: [Errno 2] No such file or directory: 'unknown'"
    },
    {
      "file_path": "unknown",
      "line": 0,
      "type": "SentryError",
      "message": "default: 2025-07-31 18:08:03.170 | ERROR    | Fix_AI:run_execution_phase:372 - Could not fix default: 2025-07-31 17:54:46.493 | ERROR    | src.core.cognitive_forge_engine:_parse_agent_json_response:1255 - Failed to parse JSON: after 3 attempts.",
      "frequency": "1",
      "suggested_fix": "Review the error context and apply appropriate fix",
      "source": "sentry",
      "proposed_action": "Fix the SentryError.",
      "status": "FAILED",
      "final_error": "Validation after fix failed: [Errno 2] No such file or directory: 'unknown'"
    },
    {
      "file_path": "unknown",
      "line": 0,
      "type": "SentryError",
      "message": "default: 2025-07-31 18:08:03.151 | ERROR    | Fix_AI:run_execution_phase:372 - Could not fix default: 2025-07-31 17:54:46.505 | ERROR    | src.core.cognitive_forge_engine:_parse_agent_json_response:1256 - Original response: Fallback response: Analyze and optimiz...",
      "frequency": "1",
      "suggested_fix": "Review the error context and apply appropriate fix",
      "source": "sentry",
      "proposed_action": "Fix the SentryError.",
      "status": "FAILED",
      "final_error": "Validation after fix failed: [Errno 2] No such file or directory: 'unknown'"
    },
    {
      "file_path": "unknown",
      "line": 0,
      "type": "SentryError",
      "message": "default: 2025-07-31 18:08:03.135 | ERROR    | Fix_AI:run_execution_phase:372 - Could not fix default: 2025-07-31 17:54:47.987 | ERROR    | src.utils.google_ai_wrapper:model:109 - Error creating Google Generative AI model: float() argument must be a string or a r...",
      "frequency": "1",
      "suggested_fix": "Review the error context and apply appropriate fix",
      "source": "sentry",
      "proposed_action": "Fix the SentryError.",
      "status": "FAILED",
      "final_error": "Validation after fix failed: [Errno 2] No such file or directory: 'unknown'"
    },
    {
      "file_path": "unknown",
      "line": 0,
      "type": "SentryError",
      "message": "default: 2025-07-31 18:08:03.112 | ERROR    | Fix_AI:run_execution_phase:372 - Could not fix default: 2025-07-31 17:54:47.999 | ERROR    | src.utils.crewai_bypass:execute_task:48 - Direct AI execution failed: float() argument must be a string or a real number, n...",
      "frequency": "1",
      "suggested_fix": "Review the error context and apply appropriate fix",
      "source": "sentry",
      "proposed_action": "Fix the SentryError.",
      "status": "FAILED",
      "final_error": "Validation after fix failed: [Errno 2] No such file or directory: 'unknown'"
    },
    {
      "file_path": "unknown",
      "line": 0,
      "type": "SentryError",
      "message": "default: 2025-07-31 18:08:03.103 | ERROR    | Fix_AI:run_execution_phase:372 - Could not fix default: 2025-07-31 17:54:48.039 | ERROR    | src.core.cognitive_forge_engine:_parse_agent_json_response:1256 - Original response: Fallback response: Analyze and optimiz...",
      "frequency": "1",
      "suggested_fix": "Review the error context and apply appropriate fix",
      "source": "sentry",
      "proposed_action": "Fix the SentryError.",
      "status": "FAILED",
      "final_error": "Validation after fix failed: [Errno 2] No such file or directory: 'unknown'"
    },
    {
      "file_path": "unknown",
      "line": 0,
      "type": "SentryError",
      "message": "default: 2025-07-31 18:08:03.084 | ERROR    | Fix_AI:run_execution_phase:372 - Could not fix default: 2025-07-31 17:54:48.052 | ERROR    | src.core.cognitive_forge_engine:_execute_prompt_alchemy:384 - Prompt optimization failed: Invalid JSON format: Expecting va...",
      "frequency": "1",
      "suggested_fix": "Review the error context and apply appropriate fix",
      "source": "sentry",
      "proposed_action": "Fix the SentryError.",
      "status": "FAILED",
      "final_error": "Validation after fix failed: [Errno 2] No such file or directory: 'unknown'"
    },
    {
      "file_path": "unknown",
      "line": 0,
      "type": "SentryError",
      "message": "default: 2025-07-31 18:08:03.070 | ERROR    | Fix_AI:run_execution_phase:372 - Could not fix default: 2025-07-31 17:54:48.191 | ERROR    | src.utils.crewai_bypass:execute_task:48 - Direct AI execution failed: 'NoneType' object has no attribute 'invoke' after 3 a...",
      "frequency": "1",
      "suggested_fix": "Review the error context and apply appropriate fix",
      "source": "sentry",
      "proposed_action": "Fix the SentryError.",
      "status": "FAILED",
      "final_error": "Validation after fix failed: [Errno 2] No such file or directory: 'unknown'"
    },
    {
      "file_path": "unknown",
      "line": 0,
      "type": "SentryError",
      "message": "default: 2025-07-31 18:08:03.054 | ERROR    | Fix_AI:run_execution_phase:372 - Could not fix error: ConnectionAbortedError: [WinError 10053] An established connection was aborted by the software in your host machine after 3 attempts.",
      "frequency": "1",
      "suggested_fix": "Review the error context and apply appropriate fix",
      "source": "sentry",
      "proposed_action": "Fix the SentryError.",
      "status": "FAILED",
      "final_error": "Validation after fix failed: [Errno 2] No such file or directory: 'unknown'"
    },
    {
      "file_path": "unknown",
      "line": 0,
      "type": "SentryError",
      "message": "default: 2025-07-31 18:08:03.039 | ERROR    | Fix_AI:run_execution_phase:372 - Could not fix default: Traceback (most recent call last): after 3 attempts.",
      "frequency": "1",
      "suggested_fix": "Review the error context and apply appropriate fix",
      "source": "sentry",
      "proposed_action": "Fix the SentryError.",
      "status": "FAILED",
      "final_error": "Validation after fix failed: [Errno 2] No such file or directory: 'unknown'"
    }
  ],
  "start_time": "2025-07-31T18:10:10.049759",
  "final_validation": {
    "initial_issues": 25,
    "remaining_issues": 0
  },
  "end_time": "2025-07-31T18:11:34.116997"
}