[32m2025-08-02 19:51:31.330[0m | [32m[1mSUCCESS [0m | [36mutils.agent_observability[0m:[36m_initialize_integrations[0m:[36m109[0m - [32m[1mâœ… W&B initialized for agent analytics.[0m
[32m2025-08-02 19:51:33.173[0m | [1mINFO    [0m | [36mmodels.advanced_database[0m:[36m__init__[0m:[36m125[0m - [1mâœ… ChromaDB memory system initialized successfully[0m
[32m2025-08-02 19:51:33.175[0m | [1mINFO    [0m | [36mmodels.advanced_database[0m:[36m__init__[0m:[36m130[0m - [1mâœ… Database system initialized successfully[0m
C:\Users\AMD\sentinel\desktop-app\src\core\cognitive_forge_engine.py:31: LangChainDeprecationWarning: As of langchain-core 0.3.0, LangChain uses pydantic v2 internally. The langchain_core.pydantic_v1 module was a compatibility shim for pydantic v1, and should no longer be used. Please update the code to import from Pydantic directly.

For example, replace imports like: `from langchain_core.pydantic_v1 import BaseModel`
with: `from pydantic import BaseModel`
or the v1 compatibility namespace if you are working in a code base that has not been fully upgraded to pydantic 2 yet. 	from pydantic.v1 import BaseModel

  from utils.google_ai_wrapper import create_google_ai_llm, direct_inference, google_ai_wrapper
[32m2025-08-02 19:51:38.370[0m | [32m[1mSUCCESS [0m | [36mutils.sentry_integration[0m:[36m_initialize_sentry[0m:[36m78[0m - [32m[1mSentry integration initialized successfully[0m
[32m2025-08-02 19:51:38.395[0m | [1mINFO    [0m | [36mcore.cognitive_forge_engine[0m:[36m__init__[0m:[36m86[0m - [1mGoogle Generative AI initialized with model: gemini-1.5-pro[0m
[32mINFO[0m:     Started server process [[36m16820[0m]
[32mINFO[0m:     Waiting for application startup.
[32m2025-08-02 19:51:38.425[0m | [1mINFO    [0m | [36msrc.main[0m:[36mstartup_event[0m:[36m142[0m - [1mðŸš€ Sentinel Cognitive Forge v5.3 (Live Mode) starting up...[0m
[32mINFO[0m:     Application startup complete.
[31mERROR[0m:    Traceback (most recent call last):
  File "C:\Users\AMD\AppData\Local\Programs\Python\Python311\Lib\asyncio\runners.py", line 118, in run
    return self._loop.run_until_complete(task)
           ^^^^^^^^^^^^^^^^^^^^^^^^^^^^^^^^^^^
  File "C:\Users\AMD\AppData\Local\Programs\Python\Python311\Lib\asyncio\base_events.py", line 654, in run_until_complete
    return future.result()
           ^^^^^^^^^^^^^^^
asyncio.exceptions.CancelledError

During handling of the above exception, another exception occurred:

Traceback (most recent call last):
  File "C:\Users\AMD\AppData\Local\Programs\Python\Python311\Lib\asyncio\runners.py", line 190, in run
    return runner.run(main)
           ^^^^^^^^^^^^^^^^
  File "C:\Users\AMD\AppData\Local\Programs\Python\Python311\Lib\asyncio\runners.py", line 123, in run
    raise KeyboardInterrupt()
KeyboardInterrupt

During handling of the above exception, another exception occurred:

Traceback (most recent call last):
  File "C:\Users\AMD\AppData\Local\Programs\Python\Python311\Lib\site-packages\starlette\routing.py", line 686, in lifespan
    await receive()
  File "C:\Users\AMD\AppData\Local\Programs\Python\Python311\Lib\site-packages\sentry_sdk\integrations\starlette.py", line 179, in _sentry_receive
    return await receive(*args, **kwargs)
           ^^^^^^^^^^^^^^^^^^^^^^^^^^^^^^
  File "C:\Users\AMD\AppData\Local\Programs\Python\Python311\Lib\site-packages\uvicorn\lifespan\on.py", line 137, in receive
    return await self.receive_queue.get()
           ^^^^^^^^^^^^^^^^^^^^^^^^^^^^^^
  File "C:\Users\AMD\AppData\Local\Programs\Python\Python311\Lib\asyncio\queues.py", line 158, in get
    await getter
asyncio.exceptions.CancelledError

Sentry is attempting to send 3 pending events
Waiting up to 2 seconds
Press Ctrl-Break to quit
[0m
